<sdf version='1.7'>
  <world name='default'>
    <gravity>0 0 -9.8</gravity>
    <physics name='default_physics' default='0' type='ode'>
      <max_step_size>0.001</max_step_size>
      <real_time_factor>1</real_time_factor>
      <real_time_update_rate>1000</real_time_update_rate>
    </physics>
    <plugin name='ground_truth' filename='libgazebo_ros_p3d.so'>
      <ros>
        <namespace>/world_ground_truth</namespace>
        <remapping>odom:=pose</remapping>
      </ros>
      <body_name>mir_robot::base_link</body_name>
      <frame_name>world</frame_name>
      <update_rate>100.0</update_rate>
    </plugin>
    <model name='aws_robomaker_warehouse_ShelfF_01_001'>
      <frame name='aws_robomaker_warehouse_ShelfF_01::__model__' attached_to='aws_robomaker_warehouse_ShelfF_01::link'>
        <pose relative_to='__model__'>0 0 0 0 -0 0</pose>
      </frame>
      <link name='aws_robomaker_warehouse_ShelfF_01::link'>
        <inertial>
          <mass>30</mass>
          <inertia>
            <ixx>907.144</ixx>
            <ixy>0</ixy>
            <ixz>0</ixz>
            <iyy>104.95</iyy>
            <iyz>0</iyz>
            <izz>824.248</izz>
          </inertia>
        </inertial>
        <collision name='collision'>
          <geometry>
            <mesh>
              <uri>file://models/aws_robomaker_warehouse_ShelfF_01/meshes/aws_robomaker_warehouse_ShelfF_01_collision.DAE</uri>
              <scale>1 1 1</scale>
            </mesh>
          </geometry>
          <surface>
            <friction>
              <ode>
                <mu>0.2</mu>
                <mu2>0.2</mu2>
                <fdir1>0 0 0</fdir1>
                <slip1>0</slip1>
                <slip2>0</slip2>
              </ode>
              <torsional>
                <ode/>
              </torsional>
            </friction>
            <contact>
              <ode/>
            </contact>
            <bounce/>
          </surface>
          <max_contacts>10</max_contacts>
        </collision>
        <visual name='visual'>
          <geometry>
            <mesh>
              <uri>file://models/aws_robomaker_warehouse_ShelfF_01/meshes/aws_robomaker_warehouse_ShelfF_01_visual.DAE</uri>
            </mesh>
          </geometry>
          <meta>
            <layer>1</layer>
          </meta>
        </visual>
        <pose relative_to='aws_robomaker_warehouse_ShelfF_01::__model__'>0 0 0 0 -0 0</pose>
        <self_collide>0</self_collide>
        <enable_wind>0</enable_wind>
        <kinematic>0</kinematic>
      </link>
      <static>1</static>
      <pose>-5.79514 -0.956635 0 0 -0 0</pose>
    </model>
    <model name='aws_robomaker_warehouse_WallB_01_001'>
      <frame name='aws_robomaker_warehouse_WallB_01::__model__' attached_to='aws_robomaker_warehouse_WallB_01::link'>
        <pose relative_to='__model__'>0 0 0 0 -0 0</pose>
      </frame>
      <link name='aws_robomaker_warehouse_WallB_01::link'>
        <inertial>
          <mass>1000</mass>
          <inertia>
            <ixx>840083</ixx>
            <ixy>0</ixy>
            <ixz>0</ixz>
            <iyy>475500</iyy>
            <iyz>0</iyz>
            <izz>1.30208e+06</izz>
          </inertia>
        </inertial>
        <collision name='collision'>
          <geometry>
            <mesh>
              <uri>file://models/aws_robomaker_warehouse_WallB_01/meshes/aws_robomaker_warehouse_WallB_01_collision.DAE</uri>
              <scale>1 1 1</scale>
            </mesh>
          </geometry>
          <surface>
            <friction>
              <ode>
                <mu>0.5</mu>
                <mu2>0.5</mu2>
                <fdir1>0 0 0</fdir1>
                <slip1>0</slip1>
                <slip2>0</slip2>
              </ode>
              <torsional>
                <ode/>
              </torsional>
            </friction>
            <contact>
              <ode/>
            </contact>
            <bounce/>
          </surface>
          <max_contacts>10</max_contacts>
        </collision>
        <visual name='visual'>
          <geometry>
            <mesh>
              <uri>file://models/aws_robomaker_warehouse_WallB_01/meshes/aws_robomaker_warehouse_WallB_01_visual.DAE</uri>
            </mesh>
          </geometry>
          <meta>
            <layer>2</layer>
          </meta>
        </visual>
        <pose relative_to='aws_robomaker_warehouse_WallB_01::__model__'>0 0 0 0 -0 0</pose>
        <self_collide>0</self_collide>
        <enable_wind>0</enable_wind>
        <kinematic>0</kinematic>
      </link>
      <static>1</static>
      <pose>0 0 0 0 -0 0</pose>
    </model>
    <model name='aws_robomaker_warehouse_ShelfE_01_001'>
      <frame name='aws_robomaker_warehouse_ShelfE_01::__model__' attached_to='aws_robomaker_warehouse_ShelfE_01::link'>
        <pose relative_to='__model__'>0 0 0 0 -0 0</pose>
      </frame>
      <link name='aws_robomaker_warehouse_ShelfE_01::link'>
        <inertial>
          <mass>30</mass>
          <inertia>
            <ixx>907.144</ixx>
            <ixy>0</ixy>
            <ixz>0</ixz>
            <iyy>104.95</iyy>
            <iyz>0</iyz>
            <izz>824.248</izz>
          </inertia>
        </inertial>
        <collision name='collision'>
          <geometry>
            <mesh>
              <uri>file://models/aws_robomaker_warehouse_ShelfE_01/meshes/aws_robomaker_warehouse_ShelfE_01_collision.DAE</uri>
              <scale>1 1 1</scale>
            </mesh>
          </geometry>
          <surface>
            <friction>
              <ode>
                <mu>0.2</mu>
                <mu2>0.2</mu2>
                <fdir1>0 0 0</fdir1>
                <slip1>0</slip1>
                <slip2>0</slip2>
              </ode>
              <torsional>
                <ode/>
              </torsional>
            </friction>
            <contact>
              <ode/>
            </contact>
            <bounce/>
          </surface>
          <max_contacts>10</max_contacts>
        </collision>
        <visual name='visual'>
          <geometry>
            <mesh>
              <uri>file://models/aws_robomaker_warehouse_ShelfE_01/meshes/aws_robomaker_warehouse_ShelfE_01_visual.DAE</uri>
            </mesh>
          </geometry>
          <meta>
            <layer>1</layer>
          </meta>
        </visual>
        <pose relative_to='aws_robomaker_warehouse_ShelfE_01::__model__'>0 0 0 0 -0 0</pose>
        <self_collide>0</self_collide>
        <enable_wind>0</enable_wind>
        <kinematic>0</kinematic>
      </link>
      <static>1</static>
      <pose>4.73156 0.57943 0 0 -0 0</pose>
    </model>
    <model name='aws_robomaker_warehouse_ShelfE_01_002'>
      <frame name='aws_robomaker_warehouse_ShelfE_01::__model__' attached_to='aws_robomaker_warehouse_ShelfE_01::link'>
        <pose relative_to='__model__'>0 0 0 0 -0 0</pose>
      </frame>
      <link name='aws_robomaker_warehouse_ShelfE_01::link'>
        <inertial>
          <mass>30</mass>
          <inertia>
            <ixx>907.144</ixx>
            <ixy>0</ixy>
            <ixz>0</ixz>
            <iyy>104.95</iyy>
            <iyz>0</iyz>
            <izz>824.248</izz>
          </inertia>
        </inertial>
        <collision name='collision'>
          <geometry>
            <mesh>
              <uri>file://models/aws_robomaker_warehouse_ShelfE_01/meshes/aws_robomaker_warehouse_ShelfE_01_collision.DAE</uri>
              <scale>1 1 1</scale>
            </mesh>
          </geometry>
          <surface>
            <friction>
              <ode>
                <mu>0.2</mu>
                <mu2>0.2</mu2>
                <fdir1>0 0 0</fdir1>
                <slip1>0</slip1>
                <slip2>0</slip2>
              </ode>
              <torsional>
                <ode/>
              </torsional>
            </friction>
            <contact>
              <ode/>
            </contact>
            <bounce/>
          </surface>
          <max_contacts>10</max_contacts>
        </collision>
        <visual name='visual'>
          <geometry>
            <mesh>
              <uri>file://models/aws_robomaker_warehouse_ShelfE_01/meshes/aws_robomaker_warehouse_ShelfE_01_visual.DAE</uri>
            </mesh>
          </geometry>
          <meta>
            <layer>1</layer>
          </meta>
        </visual>
        <pose relative_to='aws_robomaker_warehouse_ShelfE_01::__model__'>0 0 0 0 -0 0</pose>
        <self_collide>0</self_collide>
        <enable_wind>0</enable_wind>
        <kinematic>0</kinematic>
      </link>
      <static>1</static>
      <pose>4.73156 -4.82705 0 0 -0 0</pose>
    </model>
    <model name='aws_robomaker_warehouse_ShelfD_01_002'>
      <frame name='aws_robomaker_warehouse_ShelfD_01::__model__' attached_to='aws_robomaker_warehouse_ShelfD_01::link'>
        <pose relative_to='__model__'>0 0 0 0 -0 0</pose>
      </frame>
      <link name='aws_robomaker_warehouse_ShelfD_01::link'>
        <inertial>
          <mass>30</mass>
          <inertia>
            <ixx>907.144</ixx>
            <ixy>0</ixy>
            <ixz>0</ixz>
            <iyy>104.95</iyy>
            <iyz>0</iyz>
            <izz>824.248</izz>
          </inertia>
        </inertial>
        <collision name='collision'>
          <geometry>
            <mesh>
              <uri>file://models/aws_robomaker_warehouse_ShelfD_01/meshes/aws_robomaker_warehouse_ShelfD_01_collision.DAE</uri>
              <scale>1 1 1</scale>
            </mesh>
          </geometry>
          <surface>
            <friction>
              <ode>
                <mu>0.2</mu>
                <mu2>0.2</mu2>
                <fdir1>0 0 0</fdir1>
                <slip1>0</slip1>
                <slip2>0</slip2>
              </ode>
              <torsional>
                <ode/>
              </torsional>
            </friction>
            <contact>
              <ode/>
            </contact>
            <bounce/>
          </surface>
          <max_contacts>10</max_contacts>
        </collision>
        <visual name='visual'>
          <geometry>
            <mesh>
              <uri>file://models/aws_robomaker_warehouse_ShelfD_01/meshes/aws_robomaker_warehouse_ShelfD_01_visual.DAE</uri>
            </mesh>
          </geometry>
          <meta>
            <layer>1</layer>
          </meta>
        </visual>
        <pose relative_to='aws_robomaker_warehouse_ShelfD_01::__model__'>0 0 0 0 -0 0</pose>
        <self_collide>0</self_collide>
        <enable_wind>0</enable_wind>
        <kinematic>0</kinematic>
      </link>
      <static>1</static>
      <pose>4.73156 -3.03855 0 0 -0 0</pose>
    </model>
    <model name='aws_robomaker_warehouse_GroundB_01_001'>
      <frame name='aws_robomaker_warehouse_GroundB_01::__model__' attached_to='aws_robomaker_warehouse_GroundB_01::link'>
        <pose relative_to='__model__'>0 0 0 0 -0 0</pose>
      </frame>
      <link name='aws_robomaker_warehouse_GroundB_01::link'>
        <inertial>
          <mass>1000</mass>
          <inertia>
            <ixx>1.20008e+06</ixx>
            <ixy>0</ixy>
            <ixz>0</ixz>
            <iyy>8.33342e+06</iyy>
            <iyz>0</iyz>
            <izz>2.03333e+06</izz>
          </inertia>
        </inertial>
        <collision name='collision'>
          <geometry>
            <mesh>
              <uri>file://models/aws_robomaker_warehouse_GroundB_01/meshes/aws_robomaker_warehouse_GroundB_01_collision.DAE</uri>
              <scale>1 1 1</scale>
            </mesh>
          </geometry>
          <surface>
            <friction>
              <ode>
                <mu>100</mu>
                <mu2>50</mu2>
                <fdir1>0 0 0</fdir1>
                <slip1>0</slip1>
                <slip2>0</slip2>
              </ode>
              <torsional>
                <ode/>
              </torsional>
            </friction>
            <contact>
              <ode/>
            </contact>
            <bounce/>
          </surface>
          <max_contacts>10</max_contacts>
        </collision>
        <visual name='visual'>
          <geometry>
            <mesh>
              <uri>file://models/aws_robomaker_warehouse_GroundB_01/meshes/aws_robomaker_warehouse_GroundB_01_visual.DAE</uri>
            </mesh>
          </geometry>
          <meta>
            <layer>1</layer>
          </meta>
        </visual>
        <pose relative_to='aws_robomaker_warehouse_GroundB_01::__model__'>0 0 0 0 -0 0</pose>
        <self_collide>0</self_collide>
        <enable_wind>0</enable_wind>
        <kinematic>0</kinematic>
      </link>
      <static>1</static>
      <pose>0 0 -0.090092 0 -0 0</pose>
    </model>
    <model name='aws_robomaker_warehouse_Lamp_01_005'>
      <frame name='aws_robomaker_warehouse_Lamp_01::__model__' attached_to='aws_robomaker_warehouse_Lamp_01::link'>
        <pose relative_to='__model__'>0 0 0 0 -0 0</pose>
      </frame>
      <link name='aws_robomaker_warehouse_Lamp_01::link'>
        <inertial>
          <mass>30</mass>
          <inertia>
            <ixx>907.144</ixx>
            <ixy>0</ixy>
            <ixz>0</ixz>
            <iyy>104.95</iyy>
            <iyz>0</iyz>
            <izz>824.248</izz>
          </inertia>
        </inertial>
        <collision name='collision'>
          <geometry>
            <mesh>
              <uri>file://models/aws_robomaker_warehouse_Lamp_01/meshes/aws_robomaker_warehouse_Lamp_01_collision.DAE</uri>
              <scale>1 1 1</scale>
            </mesh>
          </geometry>
          <surface>
            <friction>
              <ode>
                <mu>0.2</mu>
                <mu2>0.2</mu2>
                <fdir1>0 0 0</fdir1>
                <slip1>0</slip1>
                <slip2>0</slip2>
              </ode>
              <torsional>
                <ode/>
              </torsional>
            </friction>
            <contact>
              <ode/>
            </contact>
            <bounce/>
          </surface>
          <max_contacts>10</max_contacts>
        </collision>
        <visual name='visual'>
          <geometry>
            <mesh>
              <uri>file://models/aws_robomaker_warehouse_Lamp_01/meshes/aws_robomaker_warehouse_Lamp_01_visual.DAE</uri>
            </mesh>
          </geometry>
          <meta>
            <layer>1</layer>
          </meta>
        </visual>
        <pose relative_to='aws_robomaker_warehouse_Lamp_01::__model__'>0 0 0 0 -0 0</pose>
        <self_collide>0</self_collide>
        <enable_wind>0</enable_wind>
        <kinematic>0</kinematic>
      </link>
      <static>1</static>
      <pose>0 0 -4 0 -0 0</pose>
    </model>
    <model name='aws_robomaker_warehouse_Bucket_01_020'>
      <frame name='aws_robomaker_warehouse_Bucket_01::__model__' attached_to='aws_robomaker_warehouse_Bucket_01::body'>
        <pose relative_to='__model__'>0 0 0 0 -0 0</pose>
      </frame>
      <link name='aws_robomaker_warehouse_Bucket_01::body'>
        <inertial>
          <mass>2</mass>
          <pose>0 0 0 0 -0 0</pose>
          <inertia>
            <ixx>0.57</ixx>
            <ixy>0</ixy>
            <ixz>0</ixz>
            <iyy>0.474</iyy>
            <iyz>0</iyz>
            <izz>0.391</izz>
          </inertia>
        </inertial>
        <pose relative_to='aws_robomaker_warehouse_Bucket_01::__model__'>0 0 0 0 -0 0</pose>
        <self_collide>0</self_collide>
        <kinematic>0</kinematic>
        <gravity>1</gravity>
        <visual name='visual'>
          <geometry>
            <mesh>
              <uri>file://models/aws_robomaker_warehouse_Bucket_01/meshes/aws_robomaker_warehouse_Bucket_01_visual.DAE</uri>
            </mesh>
          </geometry>
          <meta>
            <layer>1</layer>
          </meta>
        </visual>
        <collision name='collision_0'>
          <laser_retro>0</laser_retro>
          <max_contacts>10</max_contacts>
          <pose>0 0 0 0 -0 0</pose>
          <geometry>
            <mesh>
              <uri>file://models/aws_robomaker_warehouse_Bucket_01/meshes/aws_robomaker_warehouse_Bucket_01_collision.DAE</uri>
              <scale>1 1 1</scale>
            </mesh>
          </geometry>
          <surface>
            <friction>
              <ode>
                <mu>0.4</mu>
                <mu2>0.4</mu2>
                <fdir1>0 0 0</fdir1>
                <slip1>0</slip1>
                <slip2>0</slip2>
              </ode>
              <torsional>
                <coefficient>1</coefficient>
                <patch_radius>0</patch_radius>
                <surface_radius>0</surface_radius>
                <use_patch_radius>1</use_patch_radius>
                <ode>
                  <slip>0</slip>
                </ode>
              </torsional>
            </friction>
            <contact>
              <ode/>
            </contact>
            <bounce/>
          </surface>
        </collision>
        <enable_wind>0</enable_wind>
      </link>
      <static>1</static>
      <pose>0.433449 9.63171 0 0 0 -1.56316</pose>
    </model>
    <model name='aws_robomaker_warehouse_Bucket_01_021'>
      <frame name='aws_robomaker_warehouse_Bucket_01::__model__' attached_to='aws_robomaker_warehouse_Bucket_01::body'>
        <pose relative_to='__model__'>0 0 0 0 -0 0</pose>
      </frame>
      <link name='aws_robomaker_warehouse_Bucket_01::body'>
        <inertial>
          <mass>2</mass>
          <pose>0 0 0 0 -0 0</pose>
          <inertia>
            <ixx>0.57</ixx>
            <ixy>0</ixy>
            <ixz>0</ixz>
            <iyy>0.474</iyy>
            <iyz>0</iyz>
            <izz>0.391</izz>
          </inertia>
        </inertial>
        <pose relative_to='aws_robomaker_warehouse_Bucket_01::__model__'>0 0 0 0 -0 0</pose>
        <self_collide>0</self_collide>
        <kinematic>0</kinematic>
        <gravity>1</gravity>
        <visual name='visual'>
          <geometry>
            <mesh>
              <uri>file://models/aws_robomaker_warehouse_Bucket_01/meshes/aws_robomaker_warehouse_Bucket_01_visual.DAE</uri>
            </mesh>
          </geometry>
          <meta>
            <layer>1</layer>
          </meta>
        </visual>
        <collision name='collision_0'>
          <laser_retro>0</laser_retro>
          <max_contacts>10</max_contacts>
          <pose>0 0 0 0 -0 0</pose>
          <geometry>
            <mesh>
              <uri>file://models/aws_robomaker_warehouse_Bucket_01/meshes/aws_robomaker_warehouse_Bucket_01_collision.DAE</uri>
              <scale>1 1 1</scale>
            </mesh>
          </geometry>
          <surface>
            <friction>
              <ode>
                <mu>0.4</mu>
                <mu2>0.4</mu2>
                <fdir1>0 0 0</fdir1>
                <slip1>0</slip1>
                <slip2>0</slip2>
              </ode>
              <torsional>
                <coefficient>1</coefficient>
                <patch_radius>0</patch_radius>
                <surface_radius>0</surface_radius>
                <use_patch_radius>1</use_patch_radius>
                <ode>
                  <slip>0</slip>
                </ode>
              </torsional>
            </friction>
            <contact>
              <ode/>
            </contact>
            <bounce/>
          </surface>
        </collision>
        <enable_wind>0</enable_wind>
      </link>
      <static>1</static>
      <pose>-1.8321 -6.3752 0 0 0 -1.56316</pose>
    </model>
    <model name='aws_robomaker_warehouse_ClutteringA_01_016'>
      <frame name='aws_robomaker_warehouse_ClutteringA_01::__model__' attached_to='aws_robomaker_warehouse_ClutteringA_01::link'>
        <pose relative_to='__model__'>0 0 0 0 -0 0</pose>
      </frame>
      <link name='aws_robomaker_warehouse_ClutteringA_01::link'>
        <inertial>
          <mass>2</mass>
          <inertia>
            <ixx>0.841</ixx>
            <ixy>0</ixy>
            <ixz>0</ixz>
            <iyy>0.954</iyy>
            <iyz>0</iyz>
            <izz>1.422</izz>
          </inertia>
        </inertial>
        <collision name='collision'>
          <geometry>
            <mesh>
              <uri>file://models/aws_robomaker_warehouse_ClutteringA_01/meshes/aws_robomaker_warehouse_ClutteringA_01_collision.DAE</uri>
              <scale>1 1 1</scale>
            </mesh>
          </geometry>
          <surface>
            <friction>
              <ode>
                <mu>0.6</mu>
                <mu2>0.6</mu2>
                <fdir1>0 0 0</fdir1>
                <slip1>0</slip1>
                <slip2>0</slip2>
              </ode>
              <torsional>
                <coefficient>1</coefficient>
                <patch_radius>0</patch_radius>
                <surface_radius>0</surface_radius>
                <use_patch_radius>1</use_patch_radius>
                <ode>
                  <slip>0</slip>
                </ode>
              </torsional>
            </friction>
            <contact>
              <ode/>
            </contact>
            <bounce/>
          </surface>
          <max_contacts>10</max_contacts>
        </collision>
        <visual name='visual'>
          <geometry>
            <mesh>
              <uri>file://models/aws_robomaker_warehouse_ClutteringA_01/meshes/aws_robomaker_warehouse_ClutteringA_01_visual.DAE</uri>
            </mesh>
          </geometry>
          <meta>
            <layer>1</layer>
          </meta>
        </visual>
        <pose relative_to='aws_robomaker_warehouse_ClutteringA_01::__model__'>0 0 0 0 -0 0</pose>
        <self_collide>0</self_collide>
        <enable_wind>0</enable_wind>
        <kinematic>0</kinematic>
      </link>
      <static>1</static>
      <pose>5.70814 8.61684 -0.017477 0 -0 0</pose>
    </model>
    <model name='aws_robomaker_warehouse_ClutteringA_01_017'>
      <frame name='aws_robomaker_warehouse_ClutteringA_01::__model__' attached_to='aws_robomaker_warehouse_ClutteringA_01::link'>
        <pose relative_to='__model__'>0 0 0 0 -0 0</pose>
      </frame>
      <link name='aws_robomaker_warehouse_ClutteringA_01::link'>
        <inertial>
          <mass>2</mass>
          <inertia>
            <ixx>0.841</ixx>
            <ixy>0</ixy>
            <ixz>0</ixz>
            <iyy>0.954</iyy>
            <iyz>0</iyz>
            <izz>1.422</izz>
          </inertia>
        </inertial>
        <collision name='collision'>
          <geometry>
            <mesh>
              <uri>file://models/aws_robomaker_warehouse_ClutteringA_01/meshes/aws_robomaker_warehouse_ClutteringA_01_collision.DAE</uri>
              <scale>1 1 1</scale>
            </mesh>
          </geometry>
          <surface>
            <friction>
              <ode>
                <mu>0.6</mu>
                <mu2>0.6</mu2>
                <fdir1>0 0 0</fdir1>
                <slip1>0</slip1>
                <slip2>0</slip2>
              </ode>
              <torsional>
                <coefficient>1</coefficient>
                <patch_radius>0</patch_radius>
                <surface_radius>0</surface_radius>
                <use_patch_radius>1</use_patch_radius>
                <ode>
                  <slip>0</slip>
                </ode>
              </torsional>
            </friction>
            <contact>
              <ode/>
            </contact>
            <bounce/>
          </surface>
          <max_contacts>10</max_contacts>
        </collision>
        <visual name='visual'>
          <geometry>
            <mesh>
              <uri>file://models/aws_robomaker_warehouse_ClutteringA_01/meshes/aws_robomaker_warehouse_ClutteringA_01_visual.DAE</uri>
            </mesh>
          </geometry>
          <meta>
            <layer>1</layer>
          </meta>
        </visual>
        <pose relative_to='aws_robomaker_warehouse_ClutteringA_01::__model__'>0 0 0 0 -0 0</pose>
        <self_collide>0</self_collide>
        <enable_wind>0</enable_wind>
        <kinematic>0</kinematic>
      </link>
      <static>1</static>
      <pose>3.40864 8.61684 -0.017477 0 -0 0</pose>
    </model>
    <model name='aws_robomaker_warehouse_ClutteringC_01_027'>
      <frame name='aws_robomaker_warehouse_ClutteringC_01::__model__' attached_to='aws_robomaker_warehouse_ClutteringC_01::link'>
        <pose relative_to='__model__'>0 0 0 0 -0 0</pose>
      </frame>
      <link name='aws_robomaker_warehouse_ClutteringC_01::link'>
        <inertial>
          <mass>1</mass>
          <inertia>
            <ixx>1.558</ixx>
            <ixy>0</ixy>
            <ixz>0</ixz>
            <iyy>1.821</iyy>
            <iyz>0</iyz>
            <izz>1.892</izz>
          </inertia>
        </inertial>
        <collision name='collision'>
          <geometry>
            <mesh>
              <uri>file://models/aws_robomaker_warehouse_ClutteringC_01/meshes/aws_robomaker_warehouse_ClutteringC_01_collision.DAE</uri>
              <scale>1 1 1</scale>
            </mesh>
          </geometry>
          <surface>
            <friction>
              <ode>
                <mu>0.6</mu>
                <mu2>0.6</mu2>
                <fdir1>0 0 0</fdir1>
                <slip1>0</slip1>
                <slip2>0</slip2>
              </ode>
              <torsional>
                <coefficient>1</coefficient>
                <patch_radius>0</patch_radius>
                <surface_radius>0</surface_radius>
                <use_patch_radius>1</use_patch_radius>
                <ode>
                  <slip>0</slip>
                </ode>
              </torsional>
            </friction>
            <contact>
              <ode/>
            </contact>
            <bounce/>
          </surface>
          <max_contacts>10</max_contacts>
        </collision>
        <visual name='visual'>
          <geometry>
            <mesh>
              <uri>file://models/aws_robomaker_warehouse_ClutteringC_01/meshes/aws_robomaker_warehouse_ClutteringC_01_visual.DAE</uri>
            </mesh>
          </geometry>
          <meta>
            <layer>1</layer>
          </meta>
        </visual>
        <pose relative_to='aws_robomaker_warehouse_ClutteringC_01::__model__'>0 0 0 0 -0 0</pose>
        <self_collide>0</self_collide>
        <enable_wind>0</enable_wind>
        <kinematic>0</kinematic>
      </link>
      <static>1</static>
      <pose>3.32496 3.82245 -0.012064 0 -0 1.56387</pose>
    </model>
    <model name='aws_robomaker_warehouse_ClutteringC_01_028'>
      <frame name='aws_robomaker_warehouse_ClutteringC_01::__model__' attached_to='aws_robomaker_warehouse_ClutteringC_01::link'>
        <pose relative_to='__model__'>0 0 0 0 -0 0</pose>
      </frame>
      <link name='aws_robomaker_warehouse_ClutteringC_01::link'>
        <inertial>
          <mass>1</mass>
          <inertia>
            <ixx>1.558</ixx>
            <ixy>0</ixy>
            <ixz>0</ixz>
            <iyy>1.821</iyy>
            <iyz>0</iyz>
            <izz>1.892</izz>
          </inertia>
        </inertial>
        <collision name='collision'>
          <geometry>
            <mesh>
              <uri>file://models/aws_robomaker_warehouse_ClutteringC_01/meshes/aws_robomaker_warehouse_ClutteringC_01_collision.DAE</uri>
              <scale>1 1 1</scale>
            </mesh>
          </geometry>
          <surface>
            <friction>
              <ode>
                <mu>0.6</mu>
                <mu2>0.6</mu2>
                <fdir1>0 0 0</fdir1>
                <slip1>0</slip1>
                <slip2>0</slip2>
              </ode>
              <torsional>
                <coefficient>1</coefficient>
                <patch_radius>0</patch_radius>
                <surface_radius>0</surface_radius>
                <use_patch_radius>1</use_patch_radius>
                <ode>
                  <slip>0</slip>
                </ode>
              </torsional>
            </friction>
            <contact>
              <ode/>
            </contact>
            <bounce/>
          </surface>
          <max_contacts>10</max_contacts>
        </collision>
        <visual name='visual'>
          <geometry>
            <mesh>
              <uri>file://models/aws_robomaker_warehouse_ClutteringC_01/meshes/aws_robomaker_warehouse_ClutteringC_01_visual.DAE</uri>
            </mesh>
          </geometry>
          <meta>
            <layer>1</layer>
          </meta>
        </visual>
        <pose relative_to='aws_robomaker_warehouse_ClutteringC_01::__model__'>0 0 0 0 -0 0</pose>
        <self_collide>0</self_collide>
        <enable_wind>0</enable_wind>
        <kinematic>0</kinematic>
      </link>
      <static>1</static>
      <pose>5.54171 3.81648 -0.015663 0 0 -1.58319</pose>
    </model>
    <model name='aws_robomaker_warehouse_ClutteringC_01_032'>
      <frame name='aws_robomaker_warehouse_ClutteringC_01::__model__' attached_to='aws_robomaker_warehouse_ClutteringC_01::link'>
        <pose relative_to='__model__'>0 0 0 0 -0 0</pose>
      </frame>
      <link name='aws_robomaker_warehouse_ClutteringC_01::link'>
        <inertial>
          <mass>1</mass>
          <inertia>
            <ixx>1.558</ixx>
            <ixy>0</ixy>
            <ixz>0</ixz>
            <iyy>1.821</iyy>
            <iyz>0</iyz>
            <izz>1.892</izz>
          </inertia>
        </inertial>
        <collision name='collision'>
          <geometry>
            <mesh>
              <uri>file://models/aws_robomaker_warehouse_ClutteringC_01/meshes/aws_robomaker_warehouse_ClutteringC_01_collision.DAE</uri>
              <scale>1 1 1</scale>
            </mesh>
          </geometry>
          <surface>
            <friction>
              <ode>
                <mu>0.6</mu>
                <mu2>0.6</mu2>
                <fdir1>0 0 0</fdir1>
                <slip1>0</slip1>
                <slip2>0</slip2>
              </ode>
              <torsional>
                <coefficient>1</coefficient>
                <patch_radius>0</patch_radius>
                <surface_radius>0</surface_radius>
                <use_patch_radius>1</use_patch_radius>
                <ode>
                  <slip>0</slip>
                </ode>
              </torsional>
            </friction>
            <contact>
              <ode/>
            </contact>
            <bounce/>
          </surface>
          <max_contacts>10</max_contacts>
        </collision>
        <visual name='visual'>
          <geometry>
            <mesh>
              <uri>file://models/aws_robomaker_warehouse_ClutteringC_01/meshes/aws_robomaker_warehouse_ClutteringC_01_visual.DAE</uri>
            </mesh>
          </geometry>
          <meta>
            <layer>1</layer>
          </meta>
        </visual>
        <pose relative_to='aws_robomaker_warehouse_ClutteringC_01::__model__'>0 0 0 0 -0 0</pose>
        <self_collide>0</self_collide>
        <enable_wind>0</enable_wind>
        <kinematic>0</kinematic>
      </link>
      <static>1</static>
      <pose>-1.2196 9.407 -0.015663 0 -0 1.56387</pose>
    </model>
    <model name='aws_robomaker_warehouse_ClutteringD_01_005'>
      <frame name='aws_robomaker_warehouse_ClutteringD_01::__model__' attached_to='aws_robomaker_warehouse_ClutteringD_01::link'>
        <pose relative_to='__model__'>0 0 0 0 -0 0</pose>
      </frame>
      <link name='aws_robomaker_warehouse_ClutteringD_01::link'>
        <inertial>
          <mass>1</mass>
          <inertia>
            <ixx>1.558</ixx>
            <ixy>0</ixy>
            <ixz>0</ixz>
            <iyy>1.821</iyy>
            <iyz>0</iyz>
            <izz>1.892</izz>
          </inertia>
        </inertial>
        <collision name='collision'>
          <geometry>
            <mesh>
              <uri>file://models/aws_robomaker_warehouse_ClutteringD_01/meshes/aws_robomaker_warehouse_ClutteringD_01_collision.DAE</uri>
              <scale>1 1 1</scale>
            </mesh>
          </geometry>
          <surface>
            <friction>
              <ode>
                <mu>0.6</mu>
                <mu2>0.6</mu2>
                <fdir1>0 0 0</fdir1>
                <slip1>0</slip1>
                <slip2>0</slip2>
              </ode>
              <torsional>
                <coefficient>1</coefficient>
                <patch_radius>0</patch_radius>
                <surface_radius>0</surface_radius>
                <use_patch_radius>1</use_patch_radius>
                <ode>
                  <slip>0</slip>
                </ode>
              </torsional>
            </friction>
            <contact>
              <ode/>
            </contact>
            <bounce/>
          </surface>
          <max_contacts>10</max_contacts>
        </collision>
        <visual name='visual'>
          <geometry>
            <mesh>
              <uri>file://models/aws_robomaker_warehouse_ClutteringD_01/meshes/aws_robomaker_warehouse_ClutteringD_01_visual.DAE</uri>
            </mesh>
          </geometry>
          <meta>
            <layer>1</layer>
          </meta>
        </visual>
        <pose relative_to='aws_robomaker_warehouse_ClutteringD_01::__model__'>0 0 0 0 -0 0</pose>
        <self_collide>0</self_collide>
        <enable_wind>0</enable_wind>
        <kinematic>0</kinematic>
      </link>
      <static>1</static>
      <pose>-1.63468 -7.81181 -0.319559 0 -0 0</pose>
    </model>
    <light name='Warehouse_CeilingLight_003' type='point'>
      <pose>0 0 9 0 -0 0</pose>
      <diffuse>0.5 0.5 0.5 1</diffuse>
      <specular>0.2 0.2 0.2 1</specular>
      <attenuation>
        <range>80</range>
        <constant>0.3</constant>
        <linear>0.01</linear>
        <quadratic>0.001</quadratic>
      </attenuation>
      <cast_shadows>1</cast_shadows>
      <direction>0.1 0.1 -1</direction>
      <spot>
        <inner_angle>0</inner_angle>
        <outer_angle>0</outer_angle>
        <falloff>0</falloff>
      </spot>
    </light>
    <gui fullscreen='0'>
      <camera name='user_camera'>
        <pose>-2.8671 -1.63808 14.5368 0 1.1698 0.261152</pose>
        <view_controller>orbit</view_controller>
        <projection_type>perspective</projection_type>
      </camera>
    </gui>
    <magnetic_field>6e-06 2.3e-05 -4.2e-05</magnetic_field>
    <atmosphere type='adiabatic'/>
    <scene>
      <ambient>0.4 0.4 0.4 1</ambient>
      <background>0.7 0.7 0.7 1</background>
      <shadows>1</shadows>
    </scene>
    <audio>
      <device>default</device>
    </audio>
    <wind/>
    <spherical_coordinates>
      <surface_model>EARTH_WGS84</surface_model>
      <latitude_deg>0</latitude_deg>
      <longitude_deg>0</longitude_deg>
      <elevation>0</elevation>
      <heading_deg>0</heading_deg>
    </spherical_coordinates>
    <model name='mir_robot'>
      <link name='base_footprint'>
        <inertial>
          <pose>-0.009572 1.7e-05 0.152334 0 -0 0</pose>
          <mass>70.96</mass>
          <inertia>
            <ixx>0.973179</ixx>
            <ixy>-0.369183</ixy>
            <ixz>-0.00771231</ixz>
            <iyy>2.26736</iyy>
            <iyz>-4.68795e-05</iyz>
            <izz>2.75838</izz>
          </inertia>
        </inertial>
        <collision name='base_footprint_fixed_joint_lump__base_link_collision'>
          <pose>0.037646 0 0 0 -0 0</pose>
          <geometry>
            <mesh>
              <scale>1 1 1</scale>
              <uri>model://mir_description/meshes/collision/mir_100_base.stl</uri>
            </mesh>
          </geometry>
          <surface>
            <contact>
              <ode/>
            </contact>
            <friction>
              <ode/>
              <torsional>
                <ode/>
              </torsional>
            </friction>
            <bounce/>
          </surface>
          <max_contacts>10</max_contacts>
        </collision>
        <collision name='base_footprint_fixed_joint_lump__back_laser_link_collision_1'>
          <pose>-0.3548 -0.2352 0.1914 3.14159 -0 -2.35619</pose>
          <geometry>
            <mesh>
              <scale>1 1 1</scale>
              <uri>model://mir_description/meshes/visual/sick_lms-100.stl</uri>
            </mesh>
          </geometry>
          <surface>
            <contact>
              <ode/>
            </contact>
            <friction>
              <ode/>
              <torsional>
                <ode/>
              </torsional>
            </friction>
            <bounce/>
          </surface>
          <max_contacts>10</max_contacts>
        </collision>
        <collision name='base_footprint_fixed_joint_lump__front_laser_link_collision_2'>
          <pose>0.4288 0.2358 0.1914 3.14159 -0 0.785398</pose>
          <geometry>
            <mesh>
              <scale>1 1 1</scale>
              <uri>model://mir_description/meshes/visual/sick_lms-100.stl</uri>
            </mesh>
          </geometry>
          <surface>
            <contact>
              <ode/>
            </contact>
            <friction>
              <ode/>
              <torsional>
                <ode/>
              </torsional>
            </friction>
            <bounce/>
          </surface>
          <max_contacts>10</max_contacts>
        </collision>
        <visual name='base_footprint_fixed_joint_lump__base_link_visual'>
          <pose>0.037646 0 0 0 -0 0</pose>
          <geometry>
            <mesh>
              <scale>1 1 1</scale>
              <uri>model://mir_description/meshes/visual/mir_100_base.stl</uri>
            </mesh>
          </geometry>
          <material>
            <script>
              <name>Gazebo/White</name>
              <uri>file://media/materials/scripts/gazebo.material</uri>
            </script>
          </material>
        </visual>
        <visual name='base_footprint_fixed_joint_lump__back_laser_link_visual_1'>
          <pose>-0.3548 -0.2352 0.1914 3.14159 -0 -2.35619</pose>
          <geometry>
            <mesh>
              <scale>1 1 1</scale>
              <uri>model://mir_description/meshes/visual/sick_lms-100.stl</uri>
            </mesh>
          </geometry>
          <material>
            <script>
              <name>Gazebo/FlatBlack</name>
              <uri>file://media/materials/scripts/gazebo.material</uri>
            </script>
          </material>
        </visual>
        <visual name='base_footprint_fixed_joint_lump__camera_link_visual_2'>
          <pose>0.465 0 0.28 0 -0 0</pose>
          <geometry>
            <box>
              <size>0.01 0.13 0.03</size>
            </box>
          </geometry>
          <material>
            <script>
              <name>Gazebo/Red</name>
              <uri>file://media/materials/scripts/gazebo.material</uri>
            </script>
          </material>
        </visual>
        <visual name='base_footprint_fixed_joint_lump__front_laser_link_visual_3'>
          <pose>0.4288 0.2358 0.1914 3.14159 -0 0.785398</pose>
          <geometry>
            <mesh>
              <scale>1 1 1</scale>
              <uri>model://mir_description/meshes/visual/sick_lms-100.stl</uri>
            </mesh>
          </geometry>
          <material>
            <script>
              <name>Gazebo/FlatBlack</name>
              <uri>file://media/materials/scripts/gazebo.material</uri>
            </script>
          </material>
        </visual>
        <sensor name='back_laser_link' type='ray'>
          <visualize>0</visualize>
          <update_rate>12.5</update_rate>
          <ray>
            <scan>
              <horizontal>
                <samples>541</samples>
                <resolution>1</resolution>
                <min_angle>-2.35619</min_angle>
                <max_angle>2.35619</max_angle>
              </horizontal>
              <vertical>
                <samples>1</samples>
                <min_angle>0</min_angle>
                <max_angle>0</max_angle>
              </vertical>
            </scan>
            <range>
              <min>0.05</min>
              <max>29</max>
              <resolution>0.01</resolution>
            </range>
            <noise>
              <type>gaussian</type>
              <mean>0</mean>
              <stddev>0.01</stddev>
            </noise>
          </ray>
          <plugin name='gazebo_ros_back_laser_link_controller' filename='libgazebo_ros_ray_sensor.so'>
            <ros>
              <remapping>~/out:=b_scan</remapping>
            </ros>
            <output_type>sensor_msgs/LaserScan</output_type>
            <frame_name>back_laser_link</frame_name>
          </plugin>
          <pose>-0.3548 -0.2352 0.1914 0 0 -2.35619</pose>
        </sensor>
        <sensor name='depth_camera' type='depth'>
          <visualize>1</visualize>
          <update_rate>10</update_rate>
          <plugin name='depth_camera_controller' filename='libgazebo_ros_camera.so'>
            <always_on>1</always_on>
            <update_rate>10.0</update_rate>
            <camera_name>depth_camera</camera_name>
            <frame_name>camera_link_optical</frame_name>
            <topic_name>camera/depth/image_raw</topic_name>
          </plugin>
          <plugin name='point_cloud_plugin' filename='libgazebo_ros_point_cloud.so'>
            <always_on>1</always_on>
            <update_rate>10.0</update_rate>
            <frame_name>camera_link_optical</frame_name>
            <topic_name>camera/depth/points</topic_name>
          </plugin>
          <pose>0.465 0 0.28 0 -0 0</pose>
          <camera>
            <horizontal_fov>1.047</horizontal_fov>
            <image>
              <width>320</width>
              <height>240</height>
            </image>
            <clip>
              <near>0.1</near>
              <far>100</far>
            </clip>
          </camera>
          <depth_camera>
            <horizontal_fov>1.089</horizontal_fov>
            <image>
              <format>FLOAT32</format>
              <width>640</width>
              <height>480</height>
            </image>
            <clip>
              <near>0.05</near>
              <far>8.0</far>
            </clip>
          </depth_camera>
        </sensor>
        <sensor name='front_laser_link' type='ray'>
          <visualize>0</visualize>
          <update_rate>12.5</update_rate>
          <ray>
            <scan>
              <horizontal>
                <samples>541</samples>
                <resolution>1</resolution>
                <min_angle>-2.35619</min_angle>
                <max_angle>2.35619</max_angle>
              </horizontal>
              <vertical>
                <samples>1</samples>
                <min_angle>0</min_angle>
                <max_angle>0</max_angle>
              </vertical>
            </scan>
            <range>
              <min>0.05</min>
              <max>29</max>
              <resolution>0.01</resolution>
            </range>
            <noise>
              <type>gaussian</type>
              <mean>0</mean>
              <stddev>0.01</stddev>
            </noise>
          </ray>
          <plugin name='gazebo_ros_front_laser_link_controller' filename='libgazebo_ros_ray_sensor.so'>
            <ros>
              <remapping>~/out:=f_scan</remapping>
            </ros>
            <output_type>sensor_msgs/LaserScan</output_type>
            <frame_name>front_laser_link</frame_name>
          </plugin>
          <pose>0.4288 0.2358 0.1914 0 -0 0.785398</pose>
        </sensor>
        <gravity>1</gravity>
        <sensor name='imu_sensor' type='imu'>
          <always_on>1</always_on>
          <update_rate>50</update_rate>
          <visualize>1</visualize>
          <imu>
            <angular_velocity>
              <x>
                <noise type='gaussian'>
                  <mean>0</mean>
                  <stddev>0.00017</stddev>
                  <bias_mean>7.5e-06</bias_mean>
                  <bias_stddev>8e-07</bias_stddev>
                </noise>
              </x>
              <y>
                <noise type='gaussian'>
                  <mean>0</mean>
                  <stddev>0.00017</stddev>
                  <bias_mean>7.5e-06</bias_mean>
                  <bias_stddev>8e-07</bias_stddev>
                </noise>
              </y>
              <z>
                <noise type='gaussian'>
                  <mean>0</mean>
                  <stddev>0.00017</stddev>
                  <bias_mean>7.5e-06</bias_mean>
                  <bias_stddev>8e-07</bias_stddev>
                </noise>
              </z>
            </angular_velocity>
            <linear_acceleration>
              <x>
                <noise type='gaussian'>
                  <mean>0</mean>
                  <stddev>0.00017</stddev>
                  <bias_mean>0.1</bias_mean>
                  <bias_stddev>0.001</bias_stddev>
                </noise>
              </x>
              <y>
                <noise type='gaussian'>
                  <mean>0</mean>
                  <stddev>0.00017</stddev>
                  <bias_mean>0.1</bias_mean>
                  <bias_stddev>0.001</bias_stddev>
                </noise>
              </y>
              <z>
                <noise type='gaussian'>
                  <mean>0</mean>
                  <stddev>0.00017</stddev>
                  <bias_mean>0.1</bias_mean>
                  <bias_stddev>0.001</bias_stddev>
                </noise>
              </z>
            </linear_acceleration>
          </imu>
          <plugin name='imu_plugin' filename='libgazebo_ros_imu_sensor.so'>
            <initial_orientation_as_reference>0</initial_orientation_as_reference>
            <ros>
              <namespace>imu_data</namespace>
              <remapping>~/out:=data</remapping>
              <frame_name>imu_frame</frame_name>
            </ros>
          </plugin>
          <pose>0 0 0.25 0 -0 0</pose>
        </sensor>
        <self_collide>0</self_collide>
        <enable_wind>0</enable_wind>
        <kinematic>0</kinematic>
      </link>
      <joint name='bl_caster_rotation_joint' type='revolute'>
        <pose relative_to='base_footprint'>-0.270154 0.203 0.1565 0 -0 0</pose>
        <parent>base_footprint</parent>
        <child>bl_caster_rotation_link</child>
        <axis>
          <xyz>0 0 1</xyz>
          <limit>
            <lower>-1e+16</lower>
            <upper>1e+16</upper>
          </limit>
          <dynamics>
            <damping>0</damping>
            <friction>0.5</friction>
            <spring_reference>0</spring_reference>
            <spring_stiffness>0</spring_stiffness>
          </dynamics>
        </axis>
      </joint>
      <link name='bl_caster_rotation_link'>
        <pose relative_to='bl_caster_rotation_joint'>0 0 0 0 -0 0</pose>
        <inertial>
          <pose>0 0 -0.0425 0.418879 0 1.5708</pose>
          <mass>0.309754</mass>
          <inertia>
            <ixx>0.000584452</ixx>
            <ixy>0</ixy>
            <ixz>0</ixz>
            <iyy>0.000528726</iyy>
            <iyz>0</iyz>
            <izz>0.000179236</izz>
          </inertia>
        </inertial>
        <collision name='bl_caster_rotation_link_collision'>
          <pose>0 0 0 0 -0 0</pose>
          <geometry>
            <mesh>
              <scale>1 1 1</scale>
              <uri>model://mir_description/meshes/collision/caster_wheel_base.stl</uri>
            </mesh>
          </geometry>
          <surface>
            <contact>
              <ode/>
            </contact>
            <friction>
              <ode/>
              <torsional>
                <ode/>
              </torsional>
            </friction>
            <bounce/>
          </surface>
          <max_contacts>10</max_contacts>
        </collision>
        <visual name='bl_caster_rotation_link_visual'>
          <pose>0 0 0 0 -0 0</pose>
          <geometry>
            <mesh>
              <scale>1 1 1</scale>
              <uri>model://mir_description/meshes/visual/caster_wheel_base.stl</uri>
            </mesh>
          </geometry>
          <material>
            <script>
              <name>Gazebo/Grey</name>
              <uri>file://media/materials/scripts/gazebo.material</uri>
            </script>
          </material>
        </visual>
        <self_collide>0</self_collide>
        <enable_wind>0</enable_wind>
        <kinematic>0</kinematic>
      </link>
      <joint name='bl_caster_wheel_joint' type='revolute'>
        <pose relative_to='bl_caster_rotation_link'>-0.0382 0 -0.094 0 -0 0</pose>
        <parent>bl_caster_rotation_link</parent>
        <child>bl_caster_wheel_link</child>
        <axis>
          <xyz>0 1 0</xyz>
          <limit>
            <lower>-1e+16</lower>
            <upper>1e+16</upper>
          </limit>
          <dynamics>
            <spring_reference>0</spring_reference>
            <spring_stiffness>0</spring_stiffness>
          </dynamics>
        </axis>
      </joint>
      <link name='bl_caster_wheel_link'>
        <pose relative_to='bl_caster_wheel_joint'>0 0 0 0 -0 0</pose>
        <inertial>
          <pose>0 0 0 1.5708 -0 0</pose>
          <mass>1</mass>
          <inertia>
            <ixx>0.0010619</ixx>
            <ixy>0</ixy>
            <ixz>0</ixz>
            <iyy>0.0010619</iyy>
            <iyz>0</iyz>
            <izz>0.00195312</izz>
          </inertia>
        </inertial>
        <collision name='bl_caster_wheel_link_collision'>
          <pose>0 0 0 1.5708 -0 0</pose>
          <geometry>
            <cylinder>
              <length>0.032</length>
              <radius>0.0625</radius>
            </cylinder>
          </geometry>
          <surface>
            <friction>
              <ode>
                <mu>1</mu>
                <mu2>1</mu2>
                <fdir1>0 0 1</fdir1>
                <slip1>0</slip1>
                <slip2>0.5</slip2>
              </ode>
              <torsional>
                <ode/>
              </torsional>
            </friction>
            <contact>
              <ode>
                <kp>1e+08</kp>
                <min_depth>0</min_depth>
              </ode>
            </contact>
            <bounce/>
          </surface>
          <max_contacts>10</max_contacts>
        </collision>
        <visual name='bl_caster_wheel_link_visual'>
          <pose>0 0 0 0 -0 0</pose>
          <geometry>
            <mesh>
              <scale>1 1 1</scale>
              <uri>model://mir_description/meshes/visual/wheel.stl</uri>
            </mesh>
          </geometry>
          <material>
            <script>
              <name>Gazebo/DarkGrey</name>
              <uri>file://media/materials/scripts/gazebo.material</uri>
            </script>
          </material>
        </visual>
        <self_collide>0</self_collide>
        <enable_wind>0</enable_wind>
        <kinematic>0</kinematic>
      </link>
      <joint name='br_caster_rotation_joint' type='revolute'>
        <pose relative_to='base_footprint'>-0.270154 -0.203 0.1565 0 -0 0</pose>
        <parent>base_footprint</parent>
        <child>br_caster_rotation_link</child>
        <axis>
          <xyz>0 0 1</xyz>
          <limit>
            <lower>-1e+16</lower>
            <upper>1e+16</upper>
          </limit>
          <dynamics>
            <damping>0</damping>
            <friction>0.5</friction>
            <spring_reference>0</spring_reference>
            <spring_stiffness>0</spring_stiffness>
          </dynamics>
        </axis>
      </joint>
      <link name='br_caster_rotation_link'>
        <pose relative_to='br_caster_rotation_joint'>0 0 0 0 -0 0</pose>
        <inertial>
          <pose>0 0 -0.0425 0.418879 0 1.5708</pose>
          <mass>0.309754</mass>
          <inertia>
            <ixx>0.000584452</ixx>
            <ixy>0</ixy>
            <ixz>0</ixz>
            <iyy>0.000528726</iyy>
            <iyz>0</iyz>
            <izz>0.000179236</izz>
          </inertia>
        </inertial>
        <collision name='br_caster_rotation_link_collision'>
          <pose>0 0 0 0 -0 0</pose>
          <geometry>
            <mesh>
              <scale>1 1 1</scale>
              <uri>model://mir_description/meshes/collision/caster_wheel_base.stl</uri>
            </mesh>
          </geometry>
          <surface>
            <contact>
              <ode/>
            </contact>
            <friction>
              <ode/>
              <torsional>
                <ode/>
              </torsional>
            </friction>
            <bounce/>
          </surface>
          <max_contacts>10</max_contacts>
        </collision>
        <visual name='br_caster_rotation_link_visual'>
          <pose>0 0 0 0 -0 0</pose>
          <geometry>
            <mesh>
              <scale>1 1 1</scale>
              <uri>model://mir_description/meshes/visual/caster_wheel_base.stl</uri>
            </mesh>
          </geometry>
          <material>
            <script>
              <name>Gazebo/Grey</name>
              <uri>file://media/materials/scripts/gazebo.material</uri>
            </script>
          </material>
        </visual>
        <self_collide>0</self_collide>
        <enable_wind>0</enable_wind>
        <kinematic>0</kinematic>
      </link>
      <joint name='br_caster_wheel_joint' type='revolute'>
        <pose relative_to='br_caster_rotation_link'>-0.0382 0 -0.094 0 -0 0</pose>
        <parent>br_caster_rotation_link</parent>
        <child>br_caster_wheel_link</child>
        <axis>
          <xyz>0 1 0</xyz>
          <limit>
            <lower>-1e+16</lower>
            <upper>1e+16</upper>
          </limit>
          <dynamics>
            <spring_reference>0</spring_reference>
            <spring_stiffness>0</spring_stiffness>
          </dynamics>
        </axis>
      </joint>
      <link name='br_caster_wheel_link'>
        <pose relative_to='br_caster_wheel_joint'>0 0 0 0 -0 0</pose>
        <inertial>
          <pose>0 0 0 1.5708 -0 0</pose>
          <mass>1</mass>
          <inertia>
            <ixx>0.0010619</ixx>
            <ixy>0</ixy>
            <ixz>0</ixz>
            <iyy>0.0010619</iyy>
            <iyz>0</iyz>
            <izz>0.00195312</izz>
          </inertia>
        </inertial>
        <collision name='br_caster_wheel_link_collision'>
          <pose>0 0 0 1.5708 -0 0</pose>
          <geometry>
            <cylinder>
              <length>0.032</length>
              <radius>0.0625</radius>
            </cylinder>
          </geometry>
          <surface>
            <friction>
              <ode>
                <mu>1</mu>
                <mu2>1</mu2>
                <fdir1>0 0 1</fdir1>
                <slip1>0</slip1>
                <slip2>0.5</slip2>
              </ode>
              <torsional>
                <ode/>
              </torsional>
            </friction>
            <contact>
              <ode>
                <kp>1e+08</kp>
                <min_depth>0</min_depth>
              </ode>
            </contact>
            <bounce/>
          </surface>
          <max_contacts>10</max_contacts>
        </collision>
        <visual name='br_caster_wheel_link_visual'>
          <pose>0 0 0 0 -0 0</pose>
          <geometry>
            <mesh>
              <scale>1 1 1</scale>
              <uri>model://mir_description/meshes/visual/wheel.stl</uri>
            </mesh>
          </geometry>
          <material>
            <script>
              <name>Gazebo/DarkGrey</name>
              <uri>file://media/materials/scripts/gazebo.material</uri>
            </script>
          </material>
        </visual>
        <self_collide>0</self_collide>
        <enable_wind>0</enable_wind>
        <kinematic>0</kinematic>
      </link>
      <joint name='fl_caster_rotation_joint' type='revolute'>
        <pose relative_to='base_footprint'>0.341346 0.203 0.1565 0 -0 0</pose>
        <parent>base_footprint</parent>
        <child>fl_caster_rotation_link</child>
        <axis>
          <xyz>0 0 1</xyz>
          <limit>
            <lower>-1e+16</lower>
            <upper>1e+16</upper>
          </limit>
          <dynamics>
            <damping>0</damping>
            <friction>0.5</friction>
            <spring_reference>0</spring_reference>
            <spring_stiffness>0</spring_stiffness>
          </dynamics>
        </axis>
      </joint>
      <link name='fl_caster_rotation_link'>
        <pose relative_to='fl_caster_rotation_joint'>0 0 0 0 -0 0</pose>
        <inertial>
          <pose>0 0 -0.0425 0.418879 0 1.5708</pose>
          <mass>0.309754</mass>
          <inertia>
            <ixx>0.000584452</ixx>
            <ixy>0</ixy>
            <ixz>0</ixz>
            <iyy>0.000528726</iyy>
            <iyz>0</iyz>
            <izz>0.000179236</izz>
          </inertia>
        </inertial>
        <collision name='fl_caster_rotation_link_collision'>
          <pose>0 0 0 0 -0 0</pose>
          <geometry>
            <mesh>
              <scale>1 1 1</scale>
              <uri>model://mir_description/meshes/collision/caster_wheel_base.stl</uri>
            </mesh>
          </geometry>
          <surface>
            <contact>
              <ode/>
            </contact>
            <friction>
              <ode/>
              <torsional>
                <ode/>
              </torsional>
            </friction>
            <bounce/>
          </surface>
          <max_contacts>10</max_contacts>
        </collision>
        <visual name='fl_caster_rotation_link_visual'>
          <pose>0 0 0 0 -0 0</pose>
          <geometry>
            <mesh>
              <scale>1 1 1</scale>
              <uri>model://mir_description/meshes/visual/caster_wheel_base.stl</uri>
            </mesh>
          </geometry>
          <material>
            <script>
              <name>Gazebo/Grey</name>
              <uri>file://media/materials/scripts/gazebo.material</uri>
            </script>
          </material>
        </visual>
        <self_collide>0</self_collide>
        <enable_wind>0</enable_wind>
        <kinematic>0</kinematic>
      </link>
      <joint name='fl_caster_wheel_joint' type='revolute'>
        <pose relative_to='fl_caster_rotation_link'>-0.0382 0 -0.094 0 -0 0</pose>
        <parent>fl_caster_rotation_link</parent>
        <child>fl_caster_wheel_link</child>
        <axis>
          <xyz>0 1 0</xyz>
          <limit>
            <lower>-1e+16</lower>
            <upper>1e+16</upper>
          </limit>
          <dynamics>
            <spring_reference>0</spring_reference>
            <spring_stiffness>0</spring_stiffness>
          </dynamics>
        </axis>
      </joint>
      <link name='fl_caster_wheel_link'>
        <pose relative_to='fl_caster_wheel_joint'>0 0 0 0 -0 0</pose>
        <inertial>
          <pose>0 0 0 1.5708 -0 0</pose>
          <mass>1</mass>
          <inertia>
            <ixx>0.0010619</ixx>
            <ixy>0</ixy>
            <ixz>0</ixz>
            <iyy>0.0010619</iyy>
            <iyz>0</iyz>
            <izz>0.00195312</izz>
          </inertia>
        </inertial>
        <collision name='fl_caster_wheel_link_collision'>
          <pose>0 0 0 1.5708 -0 0</pose>
          <geometry>
            <cylinder>
              <length>0.032</length>
              <radius>0.0625</radius>
            </cylinder>
          </geometry>
          <surface>
            <friction>
              <ode>
                <mu>1</mu>
                <mu2>1</mu2>
                <fdir1>0 0 1</fdir1>
                <slip1>0</slip1>
                <slip2>0.5</slip2>
              </ode>
              <torsional>
                <ode/>
              </torsional>
            </friction>
            <contact>
              <ode>
                <kp>1e+08</kp>
                <min_depth>0</min_depth>
              </ode>
            </contact>
            <bounce/>
          </surface>
          <max_contacts>10</max_contacts>
        </collision>
        <visual name='fl_caster_wheel_link_visual'>
          <pose>0 0 0 0 -0 0</pose>
          <geometry>
            <mesh>
              <scale>1 1 1</scale>
              <uri>model://mir_description/meshes/visual/wheel.stl</uri>
            </mesh>
          </geometry>
          <material>
            <script>
              <name>Gazebo/DarkGrey</name>
              <uri>file://media/materials/scripts/gazebo.material</uri>
            </script>
          </material>
        </visual>
        <self_collide>0</self_collide>
        <enable_wind>0</enable_wind>
        <kinematic>0</kinematic>
      </link>
      <joint name='fr_caster_rotation_joint' type='revolute'>
        <pose relative_to='base_footprint'>0.341346 -0.203 0.1565 0 -0 0</pose>
        <parent>base_footprint</parent>
        <child>fr_caster_rotation_link</child>
        <axis>
          <xyz>0 0 1</xyz>
          <limit>
            <lower>-1e+16</lower>
            <upper>1e+16</upper>
          </limit>
          <dynamics>
            <damping>0</damping>
            <friction>0.5</friction>
            <spring_reference>0</spring_reference>
            <spring_stiffness>0</spring_stiffness>
          </dynamics>
        </axis>
      </joint>
      <link name='fr_caster_rotation_link'>
        <pose relative_to='fr_caster_rotation_joint'>0 0 0 0 -0 0</pose>
        <inertial>
          <pose>0 0 -0.0425 0.418879 0 1.5708</pose>
          <mass>0.309754</mass>
          <inertia>
            <ixx>0.000584452</ixx>
            <ixy>0</ixy>
            <ixz>0</ixz>
            <iyy>0.000528726</iyy>
            <iyz>0</iyz>
            <izz>0.000179236</izz>
          </inertia>
        </inertial>
        <collision name='fr_caster_rotation_link_collision'>
          <pose>0 0 0 0 -0 0</pose>
          <geometry>
            <mesh>
              <scale>1 1 1</scale>
              <uri>model://mir_description/meshes/collision/caster_wheel_base.stl</uri>
            </mesh>
          </geometry>
          <surface>
            <contact>
              <ode/>
            </contact>
            <friction>
              <ode/>
              <torsional>
                <ode/>
              </torsional>
            </friction>
            <bounce/>
          </surface>
          <max_contacts>10</max_contacts>
        </collision>
        <visual name='fr_caster_rotation_link_visual'>
          <pose>0 0 0 0 -0 0</pose>
          <geometry>
            <mesh>
              <scale>1 1 1</scale>
              <uri>model://mir_description/meshes/visual/caster_wheel_base.stl</uri>
            </mesh>
          </geometry>
          <material>
            <script>
              <name>Gazebo/Grey</name>
              <uri>file://media/materials/scripts/gazebo.material</uri>
            </script>
          </material>
        </visual>
        <self_collide>0</self_collide>
        <enable_wind>0</enable_wind>
        <kinematic>0</kinematic>
      </link>
      <joint name='fr_caster_wheel_joint' type='revolute'>
        <pose relative_to='fr_caster_rotation_link'>-0.0382 0 -0.094 0 -0 0</pose>
        <parent>fr_caster_rotation_link</parent>
        <child>fr_caster_wheel_link</child>
        <axis>
          <xyz>0 1 0</xyz>
          <limit>
            <lower>-1e+16</lower>
            <upper>1e+16</upper>
          </limit>
          <dynamics>
            <spring_reference>0</spring_reference>
            <spring_stiffness>0</spring_stiffness>
          </dynamics>
        </axis>
      </joint>
      <link name='fr_caster_wheel_link'>
        <pose relative_to='fr_caster_wheel_joint'>0 0 0 0 -0 0</pose>
        <inertial>
          <pose>0 0 0 1.5708 -0 0</pose>
          <mass>1</mass>
          <inertia>
            <ixx>0.0010619</ixx>
            <ixy>0</ixy>
            <ixz>0</ixz>
            <iyy>0.0010619</iyy>
            <iyz>0</iyz>
            <izz>0.00195312</izz>
          </inertia>
        </inertial>
        <collision name='fr_caster_wheel_link_collision'>
          <pose>0 0 0 1.5708 -0 0</pose>
          <geometry>
            <cylinder>
              <length>0.032</length>
              <radius>0.0625</radius>
            </cylinder>
          </geometry>
          <surface>
            <friction>
              <ode>
                <mu>1</mu>
                <mu2>1</mu2>
                <fdir1>0 0 1</fdir1>
                <slip1>0</slip1>
                <slip2>0.5</slip2>
              </ode>
              <torsional>
                <ode/>
              </torsional>
            </friction>
            <contact>
              <ode>
                <kp>1e+08</kp>
                <min_depth>0</min_depth>
              </ode>
            </contact>
            <bounce/>
          </surface>
          <max_contacts>10</max_contacts>
        </collision>
        <visual name='fr_caster_wheel_link_visual'>
          <pose>0 0 0 0 -0 0</pose>
          <geometry>
            <mesh>
              <scale>1 1 1</scale>
              <uri>model://mir_description/meshes/visual/wheel.stl</uri>
            </mesh>
          </geometry>
          <material>
            <script>
              <name>Gazebo/DarkGrey</name>
              <uri>file://media/materials/scripts/gazebo.material</uri>
            </script>
          </material>
        </visual>
        <self_collide>0</self_collide>
        <enable_wind>0</enable_wind>
        <kinematic>0</kinematic>
      </link>
      <joint name='left_wheel_joint' type='revolute'>
        <pose relative_to='base_footprint'>0 0.222604 0.0625 0 -0 0</pose>
        <parent>base_footprint</parent>
        <child>left_wheel_link</child>
        <axis>
          <xyz>0 1 0</xyz>
          <limit>
            <effort>100</effort>
            <velocity>20</velocity>
            <lower>-1e+16</lower>
            <upper>1e+16</upper>
          </limit>
          <dynamics>
            <spring_reference>0</spring_reference>
            <spring_stiffness>0</spring_stiffness>
          </dynamics>
        </axis>
      </joint>
      <link name='left_wheel_link'>
        <pose relative_to='left_wheel_joint'>0 0 0 0 -0 0</pose>
        <inertial>
          <pose>0 0 0 1.5708 -0 0</pose>
          <mass>1</mass>
          <inertia>
            <ixx>0.0010619</ixx>
            <ixy>0</ixy>
            <ixz>0</ixz>
            <iyy>0.0010619</iyy>
            <iyz>0</iyz>
            <izz>0.00195312</izz>
          </inertia>
        </inertial>
        <collision name='left_wheel_link_collision'>
          <pose>0 0 0 1.5708 -0 0</pose>
          <geometry>
            <cylinder>
              <length>0.032</length>
              <radius>0.0625</radius>
            </cylinder>
          </geometry>
          <surface>
            <friction>
              <ode>
                <mu>300</mu>
                <mu2>300</mu2>
                <fdir1>0 0 1</fdir1>
              </ode>
              <torsional>
                <coefficient>300</coefficient>
                <use_patch_radius>0</use_patch_radius>
                <surface_radius>0.0625</surface_radius>
                <ode/>
              </torsional>
            </friction>
            <contact>
              <ode>
                <min_depth>0.001</min_depth>
              </ode>
            </contact>
            <bounce/>
          </surface>
          <max_contacts>10</max_contacts>
        </collision>
        <visual name='left_wheel_link_visual'>
          <pose>0 0 0 0 -0 0</pose>
          <geometry>
            <mesh>
              <scale>1 1 1</scale>
              <uri>model://mir_description/meshes/visual/wheel.stl</uri>
            </mesh>
          </geometry>
          <material>
            <script>
              <name>Gazebo/DarkGrey</name>
              <uri>file://media/materials/scripts/gazebo.material</uri>
            </script>
          </material>
        </visual>
        <self_collide>0</self_collide>
        <enable_wind>0</enable_wind>
        <kinematic>0</kinematic>
      </link>
      <joint name='right_wheel_joint' type='revolute'>
        <pose relative_to='base_footprint'>0 -0.222604 0.0625 0 -0 0</pose>
        <parent>base_footprint</parent>
        <child>right_wheel_link</child>
        <axis>
          <xyz>0 1 0</xyz>
          <limit>
            <effort>100</effort>
            <velocity>20</velocity>
            <lower>-1e+16</lower>
            <upper>1e+16</upper>
          </limit>
          <dynamics>
            <spring_reference>0</spring_reference>
            <spring_stiffness>0</spring_stiffness>
          </dynamics>
        </axis>
      </joint>
      <link name='right_wheel_link'>
        <pose relative_to='right_wheel_joint'>0 0 0 0 -0 0</pose>
        <inertial>
          <pose>0 0 0 1.5708 -0 0</pose>
          <mass>1</mass>
          <inertia>
            <ixx>0.0010619</ixx>
            <ixy>0</ixy>
            <ixz>0</ixz>
            <iyy>0.0010619</iyy>
            <iyz>0</iyz>
            <izz>0.00195312</izz>
          </inertia>
        </inertial>
        <collision name='right_wheel_link_collision'>
          <pose>0 0 0 1.5708 -0 0</pose>
          <geometry>
            <cylinder>
              <length>0.032</length>
              <radius>0.0625</radius>
            </cylinder>
          </geometry>
          <surface>
            <friction>
              <ode>
                <mu>300</mu>
                <mu2>300</mu2>
                <fdir1>0 0 1</fdir1>
              </ode>
              <torsional>
                <coefficient>300</coefficient>
                <use_patch_radius>0</use_patch_radius>
                <surface_radius>0.0625</surface_radius>
                <ode/>
              </torsional>
            </friction>
            <contact>
              <ode>
                <min_depth>0.001</min_depth>
              </ode>
            </contact>
            <bounce/>
          </surface>
          <max_contacts>10</max_contacts>
        </collision>
        <visual name='right_wheel_link_visual'>
          <pose>0 0 0 0 -0 0</pose>
          <geometry>
            <mesh>
              <scale>1 1 1</scale>
              <uri>model://mir_description/meshes/visual/wheel.stl</uri>
            </mesh>
          </geometry>
          <material>
            <script>
              <name>Gazebo/DarkGrey</name>
              <uri>file://media/materials/scripts/gazebo.material</uri>
            </script>
          </material>
        </visual>
        <self_collide>0</self_collide>
        <enable_wind>0</enable_wind>
        <kinematic>0</kinematic>
      </link>
      <plugin name='fl_caster_rotation_joint_states' filename='libgazebo_ros_joint_state_publisher.so'>
        <ros>
          <namespace/>
        </ros>
        <update_rate>200.0</update_rate>
        <joint_name>fl_caster_rotation_joint</joint_name>
      </plugin>
      <plugin name='fl_caster_wheel_joint_states' filename='libgazebo_ros_joint_state_publisher.so'>
        <ros>
          <namespace/>
        </ros>
        <update_rate>200.0</update_rate>
        <joint_name>fl_caster_wheel_joint</joint_name>
      </plugin>
      <plugin name='fr_caster_rotation_joint_states' filename='libgazebo_ros_joint_state_publisher.so'>
        <ros>
          <namespace/>
        </ros>
        <update_rate>200.0</update_rate>
        <joint_name>fr_caster_rotation_joint</joint_name>
      </plugin>
      <plugin name='fr_caster_wheel_joint_states' filename='libgazebo_ros_joint_state_publisher.so'>
        <ros>
          <namespace/>
        </ros>
        <update_rate>200.0</update_rate>
        <joint_name>fr_caster_wheel_joint</joint_name>
      </plugin>
      <plugin name='bl_caster_rotation_joint_states' filename='libgazebo_ros_joint_state_publisher.so'>
        <ros>
          <namespace/>
        </ros>
        <update_rate>200.0</update_rate>
        <joint_name>bl_caster_rotation_joint</joint_name>
      </plugin>
      <plugin name='bl_caster_wheel_joint_states' filename='libgazebo_ros_joint_state_publisher.so'>
        <ros>
          <namespace/>
        </ros>
        <update_rate>200.0</update_rate>
        <joint_name>bl_caster_wheel_joint</joint_name>
      </plugin>
      <plugin name='br_caster_rotation_joint_states' filename='libgazebo_ros_joint_state_publisher.so'>
        <ros>
          <namespace/>
        </ros>
        <update_rate>200.0</update_rate>
        <joint_name>br_caster_rotation_joint</joint_name>
      </plugin>
      <plugin name='br_caster_wheel_joint_states' filename='libgazebo_ros_joint_state_publisher.so'>
        <ros>
          <namespace/>
        </ros>
        <update_rate>200.0</update_rate>
        <joint_name>br_caster_wheel_joint</joint_name>
      </plugin>
      <plugin name='p3d_base_controller' filename='libgazebo_ros_p3d.so'>
        <ros>
          <remapping>odom:=base_pose_ground_truth</remapping>
        </ros>
        <always_on>1</always_on>
        <update_rate>50.0</update_rate>
        <body_name>base_footprint</body_name>
        <gaussian_noise>0.01</gaussian_noise>
        <frame_name>map</frame_name>
        <xyz_offset>0 0 0</xyz_offset>
        <rpy_offset>0 0 0</rpy_offset>
      </plugin>
      <static>0</static>
      <plugin name='joint_states' filename='libgazebo_ros_joint_state_publisher.so'>
        <ros>
          <namespace/>
        </ros>
        <update_rate>1000.0</update_rate>
        <joint_name>right_wheel_joint</joint_name>
        <joint_name>left_wheel_joint</joint_name>
      </plugin>
      <plugin name='diff_drive_controller' filename='libgazebo_ros_diff_drive.so'>
        <ros>
          <remapping>cmd_vel:=cmd_vel</remapping>
          <remapping>odom:=odom</remapping>
        </ros>
        <legacy_mode>0</legacy_mode>
        <always_on>1</always_on>
        <update_rate>1000.0</update_rate>
        <left_joint>left_wheel_joint</left_joint>
        <right_joint>right_wheel_joint</right_joint>
        <wheel_separation>0.445208</wheel_separation>
        <wheel_diameter>0.125</wheel_diameter>
        <odometry_frame>odom</odometry_frame>
        <robot_base_frame>base_footprint</robot_base_frame>
        <publish_odom>1</publish_odom>
        <publish_wheel_tf>0</publish_wheel_tf>
        <publish_odom_tf>1</publish_odom_tf>
        <max_wheel_torque>10</max_wheel_torque>
        <max_wheel_acceleration>2.8</max_wheel_acceleration>
      </plugin>
      <pose>0 0 0 0 -0 0</pose>
    </model>
    <model name='aruco_marker_0'>
      <static>1</static>
      <link name='link'>
        <visual name='visual'>
          <geometry>
            <box>
              <size>0.15 0.15 0.01</size>
            </box>
          </geometry>
          <material>
            <script>
              <uri>model://aruco_marker_0/materials/scripts</uri>
              <name>AruCo/Marker0</name>
            </script>
          </material>
        </visual>
        <self_collide>0</self_collide>
        <enable_wind>0</enable_wind>
        <kinematic>0</kinematic>
      </link>
      <pose>1.84354 -9.70764 0 0 -0 0</pose>
    </model>
    <state world_name='default'>
      <sim_time>2367 286000000</sim_time>
      <real_time>70 57851942</real_time>
      <wall_time>1747137076 161326825</wall_time>
      <iterations>69381</iterations>
      <model name='aruco_marker_0'>
        <pose>1.82 -10.312 0.3124 1.57079 -1.57079 3.14159</pose>
        <scale>1 1 1</scale>
        <link name='link'>
          <pose>1.82 -10.312 0.3124 1.57079 -1.57079 3.14159</pose>
          <velocity>0 0 0 0 -0 0</velocity>
          <acceleration>0 0 0 0 -0 0</acceleration>
          <wrench>0 0 0 0 -0 0</wrench>
        </link>
      </model>
      <model name='aruco_marker_1'>
        <pose>6.83309 -9.51828 0.3124 3.14159 -1.57079 3.14159</pose>
        <scale>1 1 1</scale>
        <link name='link'>
          <pose>6.83309 -9.51828 0.3124 3.14159 -1.57079 3.14159</pose>
          <velocity>0 0 0 0 -0 0</velocity>
          <acceleration>0 0 0 0 -0 0</acceleration>
          <wrench>0 0 0 0 -0 0</wrench>
        </link>
      </model>
      <model name='aruco_marker_2'>
        <pose>6.83405 -6.37807 0.3124 3.14159 -1.57079 3.14159</pose>
        <scale>1 1 1</scale>
        <link name='link'>
          <pose>6.83405 -6.37807 0.3124 3.14159 -1.57079 3.14159</pose>
          <velocity>0 0 0 0 -0 0</velocity>
          <acceleration>0 0 0 0 -0 0</acceleration>
          <wrench>0 0 0 0 -0 0</wrench>
        </link>
      </model>
      <model name='aruco_marker_3'>
        <pose>6.83371 -1.22608 0.312442 -3.00391 -1.57079 3.00392</pose>
        <scale>1 1 1</scale>
        <link name='link'>
          <pose>6.83371 -1.22608 0.312442 -3.00391 -1.57079 3.00392</pose>
          <velocity>0 0 0 0 -0 0</velocity>
          <acceleration>0 0 0 0 -0 0</acceleration>
          <wrench>0 0 0 0 -0 0</wrench>
        </link>
      </model>
      <model name='aruco_marker_4'>
        <pose>6.83452 2.20087 0.312473 -3.00391 -1.57079 3.00392</pose>
        <scale>1 1 1</scale>
        <link name='link'>
          <pose>6.83452 2.20087 0.312473 -3.00391 -1.57079 3.00392</pose>
          <velocity>0 0 0 0 -0 0</velocity>
          <acceleration>0 0 0 0 -0 0</acceleration>
          <wrench>0 0 0 0 -0 0</wrench>
        </link>
      </model>
      <model name='aruco_marker_5'>
        <pose>6.83424 6.35949 0.312487 -3.14159 -1.57079 -3.14159</pose>
        <scale>1 1 1</scale>
        <link name='link'>
          <pose>6.83424 6.35949 0.312487 -3.14159 -1.57079 -3.14159</pose>
          <velocity>0 0 0 0 -0 0</velocity>
          <acceleration>0 0 0 0 -0 0</acceleration>
          <wrench>0 0 0 0 -0 0</wrench>
        </link>
      </model>
      <model name='aruco_marker_6'>
        <pose>1.77748 10.3205 0.400646 -1.57079 -1.57079 3.14159</pose>
        <scale>1 1 1</scale>
        <link name='link'>
          <pose>1.77748 10.3205 0.400646 -1.57079 -1.57079 3.14159</pose>
          <velocity>0 0 0 0 -0 0</velocity>
          <acceleration>0 0 0 0 -0 0</acceleration>
          <wrench>0 0 0 0 -0 0</wrench>
        </link>
      </model>
      <model name='aruco_marker_7'>
        <pose>-3.77672 10.3199 0.39689 -1.57079 -1.57079 3.14159</pose>
        <scale>1 1 1</scale>
        <link name='link'>
          <pose>-3.77672 10.3199 0.39689 -1.57079 -1.57079 3.14159</pose>
          <velocity>0 0 0 0 -0 0</velocity>
          <acceleration>0 0 0 0 -0 0</acceleration>
          <wrench>0 0 0 0 -0 0</wrench>
        </link>
      </model>
      <model name='aruco_marker_8'>
        <pose>-6.86915 9.29036 0.467248 -3e-06 -1.57079 3.14159</pose>
        <scale>1 1 1</scale>
        <link name='link'>
          <pose>-6.86915 9.29036 0.467248 -3e-06 -1.57079 3.14159</pose>
          <velocity>0 0 0 0 -0 0</velocity>
          <acceleration>0 0 0 0 -0 0</acceleration>
          <wrench>0 0 0 0 -0 0</wrench>
        </link>
      </model>
      <model name='aws_robomaker_warehouse_Bucket_01_020'>
        <pose>0.433449 9.63171 0 0 0 -1.56316</pose>
        <scale>1 1 1</scale>
        <link name='aws_robomaker_warehouse_Bucket_01::body'>
          <pose>0.433449 9.63171 0 0 0 -1.56316</pose>
          <velocity>0 0 0 0 -0 0</velocity>
          <acceleration>0 0 0 0 -0 0</acceleration>
          <wrench>0 0 0 0 -0 0</wrench>
        </link>
      </model>
      <model name='aws_robomaker_warehouse_Bucket_01_020_clone'>
        <pose>-1.87113 3.23127 0 0 0 -1.56316</pose>
        <scale>1 1 1</scale>
        <link name='aws_robomaker_warehouse_Bucket_01::body'>
          <pose>-1.87113 3.23127 0 0 0 -1.56316</pose>
          <velocity>0 0 0 0 -0 0</velocity>
          <acceleration>0 0 0 0 -0 0</acceleration>
          <wrench>0 0 0 0 -0 0</wrench>
        </link>
      </model>
      <model name='aws_robomaker_warehouse_Bucket_01_021'>
        <pose>-1.8321 -6.3752 0 0 0 -1.56316</pose>
        <scale>1 1 1</scale>
        <link name='aws_robomaker_warehouse_Bucket_01::body'>
          <pose>-1.8321 -6.3752 0 0 0 -1.56316</pose>
          <velocity>0 0 0 0 -0 0</velocity>
          <acceleration>0 0 0 0 -0 0</acceleration>
          <wrench>0 0 0 0 -0 0</wrench>
        </link>
      </model>
      <model name='aws_robomaker_warehouse_Bucket_01_021_clone'>
        <pose>4.94933 -8.16306 0 0 0 -1.56316</pose>
        <scale>1 1 1</scale>
        <link name='aws_robomaker_warehouse_Bucket_01::body'>
          <pose>4.94933 -8.16306 0 0 0 -1.56316</pose>
          <velocity>0 0 0 0 -0 0</velocity>
          <acceleration>0 0 0 0 -0 0</acceleration>
          <wrench>0 0 0 0 -0 0</wrench>
        </link>
      </model>
      <model name='aws_robomaker_warehouse_ClutteringA_01_016'>
        <pose>5.70814 8.61684 -0.017477 0 -0 0</pose>
        <scale>1 1 1</scale>
        <link name='aws_robomaker_warehouse_ClutteringA_01::link'>
          <pose>5.70814 8.61684 -0.017477 0 -0 0</pose>
          <velocity>0 0 0 0 -0 0</velocity>
          <acceleration>0 0 0 0 -0 0</acceleration>
          <wrench>0 0 0 0 -0 0</wrench>
        </link>
      </model>
      <model name='aws_robomaker_warehouse_ClutteringA_01_017'>
        <pose>3.40864 8.61684 -0.017477 0 -0 0</pose>
        <scale>1 1 1</scale>
        <link name='aws_robomaker_warehouse_ClutteringA_01::link'>
          <pose>3.40864 8.61684 -0.017477 0 -0 0</pose>
          <velocity>0 0 0 0 -0 0</velocity>
          <acceleration>0 0 0 0 -0 0</acceleration>
          <wrench>0 0 0 0 -0 0</wrench>
        </link>
      </model>
      <model name='aws_robomaker_warehouse_ClutteringC_01_027'>
        <pose>3.32496 3.82245 -0.012064 0 -0 1.56387</pose>
        <scale>1 1 1</scale>
        <link name='aws_robomaker_warehouse_ClutteringC_01::link'>
          <pose>3.32496 3.82245 -0.012064 0 -0 1.56387</pose>
          <velocity>0 0 0 0 -0 0</velocity>
          <acceleration>0 0 0 0 -0 0</acceleration>
          <wrench>0 0 0 0 -0 0</wrench>
        </link>
      </model>
      <model name='aws_robomaker_warehouse_ClutteringC_01_028'>
        <pose>5.54171 3.81648 -0.015663 0 0 -1.58319</pose>
        <scale>1 1 1</scale>
        <link name='aws_robomaker_warehouse_ClutteringC_01::link'>
          <pose>5.54171 3.81648 -0.015663 0 0 -1.58319</pose>
          <velocity>0 0 0 0 -0 0</velocity>
          <acceleration>0 0 0 0 -0 0</acceleration>
          <wrench>0 0 0 0 -0 0</wrench>
        </link>
      </model>
      <model name='aws_robomaker_warehouse_ClutteringC_01_032'>
        <pose>-1.2196 9.407 -0.015663 0 -0 1.56387</pose>
        <scale>1 1 1</scale>
        <link name='aws_robomaker_warehouse_ClutteringC_01::link'>
          <pose>-1.2196 9.407 -0.015663 0 -0 1.56387</pose>
          <velocity>0 0 0 0 -0 0</velocity>
          <acceleration>0 0 0 0 -0 0</acceleration>
          <wrench>0 0 0 0 -0 0</wrench>
        </link>
      </model>
      <model name='aws_robomaker_warehouse_ClutteringD_01_005'>
        <pose>-1.63468 -7.81181 -0.319559 0 -0 0</pose>
        <scale>1 1 1</scale>
        <link name='aws_robomaker_warehouse_ClutteringD_01::link'>
          <pose>-1.63468 -7.81181 -0.319559 0 -0 0</pose>
          <velocity>0 0 0 0 -0 0</velocity>
          <acceleration>0 0 0 0 -0 0</acceleration>
          <wrench>0 0 0 0 -0 0</wrench>
        </link>
      </model>
      <model name='aws_robomaker_warehouse_GroundB_01_001'>
        <pose>0 0 -0.090092 0 -0 0</pose>
        <scale>1 1 1</scale>
        <link name='aws_robomaker_warehouse_GroundB_01::link'>
          <pose>0 0 -0.090092 0 -0 0</pose>
          <velocity>0 0 0 0 -0 0</velocity>
          <acceleration>0 0 0 0 -0 0</acceleration>
          <wrench>0 0 0 0 -0 0</wrench>
        </link>
      </model>
      <model name='aws_robomaker_warehouse_Lamp_01_005'>
        <pose>0 0 -4 0 -0 0</pose>
        <scale>1 1 1</scale>
        <link name='aws_robomaker_warehouse_Lamp_01::link'>
          <pose>0 0 -4 0 -0 0</pose>
          <velocity>0 0 0 0 -0 0</velocity>
          <acceleration>0 0 0 0 -0 0</acceleration>
          <wrench>0 0 0 0 -0 0</wrench>
        </link>
      </model>
      <model name='aws_robomaker_warehouse_ShelfD_01_002'>
        <pose>4.73156 -3.03855 0 0 -0 0</pose>
        <scale>1 1 1</scale>
        <link name='aws_robomaker_warehouse_ShelfD_01::link'>
          <pose>4.73156 -3.03855 0 0 -0 0</pose>
          <velocity>0 0 0 0 -0 0</velocity>
          <acceleration>0 0 0 0 -0 0</acceleration>
          <wrench>0 0 0 0 -0 0</wrench>
        </link>
      </model>
      <model name='aws_robomaker_warehouse_ShelfE_01_001'>
        <pose>4.73156 0.57943 0 0 -0 0</pose>
        <scale>1 1 1</scale>
        <link name='aws_robomaker_warehouse_ShelfE_01::link'>
          <pose>4.73156 0.57943 0 0 -0 0</pose>
          <velocity>0 0 0 0 -0 0</velocity>
          <acceleration>0 0 0 0 -0 0</acceleration>
          <wrench>0 0 0 0 -0 0</wrench>
        </link>
      </model>
      <model name='aws_robomaker_warehouse_ShelfE_01_002'>
        <pose>4.73156 -4.82705 0 0 -0 0</pose>
        <scale>1 1 1</scale>
        <link name='aws_robomaker_warehouse_ShelfE_01::link'>
          <pose>4.73156 -4.82705 0 0 -0 0</pose>
          <velocity>0 0 0 0 -0 0</velocity>
          <acceleration>0 0 0 0 -0 0</acceleration>
          <wrench>0 0 0 0 -0 0</wrench>
        </link>
      </model>
      <model name='aws_robomaker_warehouse_ShelfF_01_001'>
        <pose>-5.79514 -0.956635 0 0 -0 0</pose>
        <scale>1 1 1</scale>
        <link name='aws_robomaker_warehouse_ShelfF_01::link'>
          <pose>-5.79514 -0.956635 0 0 -0 0</pose>
          <velocity>0 0 0 0 -0 0</velocity>
          <acceleration>0 0 0 0 -0 0</acceleration>
          <wrench>0 0 0 0 -0 0</wrench>
        </link>
      </model>
      <model name='aws_robomaker_warehouse_WallB_01_001'>
        <pose>-0.01238 0.004524 0 0 -0 0</pose>
        <scale>1 1 1</scale>
        <link name='aws_robomaker_warehouse_WallB_01::link'>
          <pose>-0.01238 0.004524 0 0 -0 0</pose>
          <velocity>0 0 0 0 -0 0</velocity>
          <acceleration>0 0 0 0 -0 0</acceleration>
          <wrench>0 0 0 0 -0 0</wrench>
        </link>
      </model>
      <model name='cart'>
        <pose>-2.72174 -2.75378 -9.56436e+06 0.680835 0.841947 0.352724</pose>
        <scale>1 1 1</scale>
        <link name='base_footprint'>
          <pose>-2.72174 -2.75378 -9.56436e+06 0.680835 0.841947 0.352724</pose>
          <velocity>-0.280721 -0.199035 -13691.4 -0.384251 0.686655 0.231194</velocity>
          <acceleration>0.46647 -0.002544 -10.4841 2.25551 -0.648391 1.82107</acceleration>
          <wrench>14.0701 -0.076722 -316.232 0 -0 0</wrench>
        </link>
        <link name='rev1_link'>
          <pose>-2.3019 -2.36587 -9.56436e+06 0.639114 -0.870005 1.89642</pose>
          <velocity>-0.46512 -0.15577 -13691.8 1.16791 -0.274577 -2.73323</velocity>
          <acceleration>1.49335 0.574136 -9.32948 -2.26246 -1.3913 -2.07652</acceleration>
          <wrench>2.08477 0.801517 -13.0243 0 -0 0</wrench>
        </link>
        <link name='rev2_link'>
          <pose>-2.87066 -2.57525 -9.56436e+06 0.984297 -0.362119 1.32822</pose>
          <velocity>0.048587 -0.027562 -13691.3 0.667178 -1.51166 2.20446</velocity>
          <acceleration>1.08038 4.93968 -10.9535 1.33544 1.18075 -0.947926</acceleration>
          <wrench>1.50825 6.89599 -15.2915 0 -0 0</wrench>
        </link>
        <link name='rev3_link'>
          <pose>-2.42587 -3.00768 -9.56436e+06 1.02172 -0.129688 1.1759</pose>
          <velocity>-0.524537 -0.299877 -13691.5 -1.37397 1.19467 -0.441585</velocity>
          <acceleration>2.45302 -1.09906 -10.084 -1.19343 -0.307502 0.924526</acceleration>
          <wrench>3.42451 -1.53434 -14.0777 0 -0 0</wrench>
        </link>
        <link name='rev4_link'>
          <pose>-2.99462 -3.21704 -9.56436e+06 -1.02632 -0.042701 -2.07048</pose>
          <velocity>-0.00841 -0.168174 -13691 1.62275 -1.51908 2.34761</velocity>
          <acceleration>-2.23362 -4.43407 -11.5666 -0.68251 -0.733307 -1.81622</acceleration>
          <wrench>-3.11822 -6.19014 -16.1474 0 -0 0</wrench>
        </link>
        <link name='wheel_link1'>
          <pose>-2.35457 -2.37258 -9.56436e+06 -0.097226 1.17403 -2.40475</pose>
          <velocity>-0.125885 -0.104091 -13692.3 1.10041 -0.347825 -2.69156</velocity>
          <acceleration>-0.379146 3.34523 -5.15714 1.49065 0.176928 0.028375</acceleration>
          <wrench>-1.20544 10.6357 -16.3964 0 -0 0</wrench>
        </link>
        <link name='wheel_link2'>
          <pose>-2.93398 -2.57816 -9.56436e+06 -0.656957 0.181452 2.04793</pose>
          <velocity>0.263883 -0.389624 -13691.9 0.778856 -1.5392 2.05904</velocity>
          <acceleration>1.44288 11.7573 -7.13465 3.08018 -0.607908 1.6856</acceleration>
          <wrench>4.58742 37.3805 -22.6836 0 -0 0</wrench>
        </link>
        <link name='wheel_link3'>
          <pose>-2.46933 -3.00961 -9.56436e+06 -0.505138 -0.259216 0.950245</pose>
          <velocity>-0.587255 -0.351339 -13691.4 1.09598 -0.440775 -1.98237</velocity>
          <acceleration>1.79088 -0.914741 -8.90122 1.06078 -0.367744 -2.17317</acceleration>
          <wrench>5.69383 -2.90828 -28.3001 0 -0 0</wrench>
        </link>
        <link name='wheel_link4'>
          <pose>-3.03674 -3.16616 -9.56436e+06 3.0305 0.535768 2.35628</pose>
          <velocity>0.524529 0.12122 -13691.6 -2.07539 -1.28367 0.281251</velocity>
          <acceleration>-8.50653 -14.1552 -10.3165 -1.63653 -0.467785 -0.737529</acceleration>
          <wrench>-27.0453 -45.0042 -32.7998 0 -0 0</wrench>
        </link>
      </model>
      <model name='mir_robot'>
        <pose>-0.006373 0.001759 0.034221 2e-06 -9e-06 -0.011974</pose>
        <scale>1 1 1</scale>
        <link name='base_footprint'>
          <pose>-0.006373 0.001759 0.034221 2e-06 -9e-06 -0.011974</pose>
          <velocity>-0.000211 -2.1e-05 -6e-06 -7e-06 -5e-06 -0.000281</velocity>
          <acceleration>-0.000163 -0.000415 -0.000125 -0.000196 2.1e-05 0.000354</acceleration>
          <wrench>-0.011532 -0.029476 -0.008892 0 -0 0</wrench>
        </link>
        <link name='bl_caster_rotation_link'>
          <pose>-0.274078 0.207978 0.190722 6e-06 7.1e-05 1.89293</pose>
          <velocity>-0.000157 5.2e-05 -1e-06 -0.000158 -9.2e-05 0.003366</velocity>
          <acceleration>7.7e-05 -0.000563 -6.4e-05 -0.001071 -0.001256 -0.001978</acceleration>
          <wrench>2.4e-05 -0.000174 -2e-05 0 -0 0</wrench>
        </link>
        <link name='bl_caster_wheel_link'>
          <pose>-0.261983 0.171741 0.096724 3.14158 -0.394612 -1.24866</pose>
          <velocity>-3e-05 8.8e-05 4e-06 -0.002081 -0.000705 0.00337</velocity>
          <acceleration>4.5e-05 -0.000533 6e-06 0.002318 -0.002159 -0.002888</acceleration>
          <wrench>4.5e-05 -0.000533 6e-06 0 -0 0</wrench>
        </link>
        <link name='br_caster_rotation_link'>
          <pose>-0.278938 -0.197993 0.190722 0 8.8e-05 2.18829</pose>
          <velocity>-0.00027 5.5e-05 0 -9.9e-05 -0.000116 0.004826</velocity>
          <acceleration>0.00016 -0.000411 -2.6e-05 -0.00081 -0.000267 -0.000323</acceleration>
          <wrench>5e-05 -0.000127 -8e-06 0 -0 0</wrench>
        </link>
        <link name='br_caster_wheel_link'>
          <pose>-0.256818 -0.229141 0.096724 -1e-06 -0.779985 2.18829</pose>
          <velocity>-0.000114 0.000158 4e-06 -0.003145 -0.002256 0.004829</velocity>
          <acceleration>0.000131 -0.000362 8e-06 0.002308 9.2e-05 -0.001335</acceleration>
          <wrench>0.000131 -0.000362 8e-06 0 -0 0</wrench>
        </link>
        <link name='fl_caster_rotation_link'>
          <pose>0.337379 0.200657 0.190724 1.2e-05 1e-06 -1.8701</pose>
          <velocity>-0.000154 -0.000117 -1e-06 0.000104 1.3e-05 -0.003041</velocity>
          <acceleration>-0.000239 -0.000177 -6e-05 0.003173 0.000764 -0.006655</acceleration>
          <wrench>-7.4e-05 -5.5e-05 -1.9e-05 0 -0 0</wrench>
        </link>
        <link name='fl_caster_wheel_link'>
          <pose>0.348643 0.237159 0.096724 3.14149 1.40882 1.27139</pose>
          <velocity>-4.4e-05 -0.000148 2e-06 0.00244 -0.000719 -0.003037</velocity>
          <acceleration>-7.9e-05 -0.000266 -2e-06 0.000309 -0.000144 -0.004623</acceleration>
          <wrench>-7.9e-05 -0.000266 -2e-06 0 -0 0</wrench>
        </link>
        <link name='fr_caster_rotation_link'>
          <pose>0.332517 -0.205314 0.190724 7e-06 1.6e-05 -2.66005</pose>
          <velocity>-0.000269 -0.000119 1e-06 7.4e-05 -3.6e-05 -0.000582</velocity>
          <acceleration>-0.000166 6.8e-05 -4.2e-05 0.005554 -3.7e-05 -0.011985</acceleration>
          <wrench>-5.1e-05 2.1e-05 -1.3e-05 0 -0 0</wrench>
        </link>
        <link name='fr_caster_wheel_link'>
          <pose>0.366375 -0.187622 0.096724 1.1e-05 0.794596 -2.66005</pose>
          <velocity>-0.000258 -0.000137 3e-06 0.002234 -0.004223 -0.000579</velocity>
          <acceleration>5e-05 -0.000151 1.1e-05 0.002421 0.0017 -0.009247</acceleration>
          <wrench>5e-05 -0.000151 1.1e-05 0 -0 0</wrench>
        </link>
        <link name='left_wheel_link'>
          <pose>-0.003708 0.224345 0.096725 -3.14156 0.372911 3.12963</pose>
          <velocity>-0.000149 -1.7e-05 -5e-06 0.000579 -0.002262 -0.000311</velocity>
          <acceleration>-0.000208 -0.000426 -0.000125 0.005828 -0.002671 -0.000569</acceleration>
          <wrench>-0.000208 -0.000426 -0.000125 0 -0 0</wrench>
        </link>
        <link name='right_wheel_link'>
          <pose>-0.009038 -0.220827 0.096725 3.14149 -0.362011 3.12966</pose>
          <velocity>-0.000273 -1.5e-05 1e-06 0.000227 -0.004403 -0.000269</velocity>
          <acceleration>-0.000245 -0.000324 1.3e-05 0.005203 -0.004105 -0.000918</acceleration>
          <wrench>-0.000245 -0.000324 1.3e-05 0 -0 0</wrench>
        </link>
      </model>
      <light name='Warehouse_CeilingLight_003'>
        <pose>0 0 9 0 -0 0</pose>
      </light>
    </state>
    <model name='aruco_marker_1'>
      <static>1</static>
      <link name='link'>
        <visual name='visual'>
          <geometry>
            <box>
              <size>0.15 0.15 0.01</size>
            </box>
          </geometry>
          <material>
            <script>
              <uri>model://aruco_marker_1/materials/scripts</uri>
              <name>AruCo/Marker1</name>
            </script>
          </material>
        </visual>
        <self_collide>0</self_collide>
        <enable_wind>0</enable_wind>
        <kinematic>0</kinematic>
      </link>
      <pose>6.68568 -9.99923 0 0 -0 0</pose>
    </model>
    <model name='aruco_marker_2'>
      <static>1</static>
      <link name='link'>
        <visual name='visual'>
          <geometry>
            <box>
              <size>0.15 0.15 0.01</size>
            </box>
          </geometry>
          <material>
            <script>
              <uri>model://aruco_marker_2/materials/scripts</uri>
              <name>AruCo/Marker2</name>
            </script>
          </material>
        </visual>
        <self_collide>0</self_collide>
        <enable_wind>0</enable_wind>
        <kinematic>0</kinematic>
      </link>
      <pose>7.83095 2.31895 0 0 -0 0</pose>
    </model>
    <model name='aruco_marker_3'>
      <static>1</static>
      <link name='link'>
        <visual name='visual'>
          <geometry>
            <box>
              <size>0.15 0.15 0.01</size>
            </box>
          </geometry>
          <material>
            <script>
              <uri>model://aruco_marker_3/materials/scripts</uri>
              <name>AruCo/Marker3</name>
            </script>
          </material>
        </visual>
        <self_collide>0</self_collide>
        <enable_wind>0</enable_wind>
        <kinematic>0</kinematic>
      </link>
      <pose>1.58684 10.8851 0 0 -0 0</pose>
    </model>
    <model name='aruco_marker_4'>
      <static>1</static>
      <link name='link'>
        <visual name='visual'>
          <geometry>
            <box>
              <size>0.15 0.15 0.01</size>
            </box>
          </geometry>
          <material>
            <script>
              <uri>model://aruco_marker_4/materials/scripts</uri>
              <name>AruCo/Marker4</name>
            </script>
          </material>
        </visual>
        <self_collide>0</self_collide>
        <enable_wind>0</enable_wind>
        <kinematic>0</kinematic>
      </link>
      <pose>-3.85436 10.7375 0 0 -0 0</pose>
    </model>
    <model name='aruco_marker_5'>
      <static>1</static>
      <link name='link'>
        <visual name='visual'>
          <geometry>
            <box>
              <size>0.15 0.15 0.01</size>
            </box>
          </geometry>
          <material>
            <script>
              <uri>model://aruco_marker_5/materials/scripts</uri>
              <name>AruCo/Marker5</name>
            </script>
          </material>
        </visual>
        <self_collide>0</self_collide>
        <enable_wind>0</enable_wind>
        <kinematic>0</kinematic>
      </link>
      <pose>-6.14092 9.19602 0 0 -0 0</pose>
    </model>
    <model name='aws_robomaker_warehouse_Bucket_01_020_clone'>
      <frame name='aws_robomaker_warehouse_Bucket_01::__model__' attached_to='aws_robomaker_warehouse_Bucket_01::body'>
        <pose relative_to='__model__'>0 0 0 0 -0 0</pose>
      </frame>
      <link name='aws_robomaker_warehouse_Bucket_01::body'>
        <inertial>
          <mass>2</mass>
          <pose>0 0 0 0 -0 0</pose>
          <inertia>
            <ixx>0.57</ixx>
            <ixy>0</ixy>
            <ixz>0</ixz>
            <iyy>0.474</iyy>
            <iyz>0</iyz>
            <izz>0.391</izz>
          </inertia>
        </inertial>
        <pose relative_to='aws_robomaker_warehouse_Bucket_01::__model__'>0 0 0 0 -0 0</pose>
        <self_collide>0</self_collide>
        <kinematic>0</kinematic>
        <gravity>1</gravity>
        <visual name='visual'>
          <geometry>
            <mesh>
              <uri>file://models/aws_robomaker_warehouse_Bucket_01/meshes/aws_robomaker_warehouse_Bucket_01_visual.DAE</uri>
            </mesh>
          </geometry>
          <meta>
            <layer>1</layer>
          </meta>
        </visual>
        <collision name='collision_0'>
          <laser_retro>0</laser_retro>
          <max_contacts>10</max_contacts>
          <pose>0 0 0 0 -0 0</pose>
          <geometry>
            <mesh>
              <uri>file://models/aws_robomaker_warehouse_Bucket_01/meshes/aws_robomaker_warehouse_Bucket_01_collision.DAE</uri>
              <scale>1 1 1</scale>
            </mesh>
          </geometry>
          <surface>
            <friction>
              <ode>
                <mu>0.4</mu>
                <mu2>0.4</mu2>
                <fdir1>0 0 0</fdir1>
                <slip1>0</slip1>
                <slip2>0</slip2>
              </ode>
              <torsional>
                <coefficient>1</coefficient>
                <patch_radius>0</patch_radius>
                <surface_radius>0</surface_radius>
                <use_patch_radius>1</use_patch_radius>
                <ode>
                  <slip>0</slip>
                </ode>
              </torsional>
            </friction>
            <contact>
              <ode/>
            </contact>
            <bounce/>
          </surface>
        </collision>
        <enable_wind>0</enable_wind>
      </link>
      <static>1</static>
      <pose>-1.87113 3.23127 0 0 0 -1.56316</pose>
    </model>
    <model name='aws_robomaker_warehouse_Bucket_01_021_clone'>
      <frame name='aws_robomaker_warehouse_Bucket_01::__model__' attached_to='aws_robomaker_warehouse_Bucket_01::body'>
        <pose relative_to='__model__'>0 0 0 0 -0 0</pose>
      </frame>
      <link name='aws_robomaker_warehouse_Bucket_01::body'>
        <inertial>
          <mass>2</mass>
          <pose>0 0 0 0 -0 0</pose>
          <inertia>
            <ixx>0.57</ixx>
            <ixy>0</ixy>
            <ixz>0</ixz>
            <iyy>0.474</iyy>
            <iyz>0</iyz>
            <izz>0.391</izz>
          </inertia>
        </inertial>
        <pose relative_to='aws_robomaker_warehouse_Bucket_01::__model__'>0 0 0 0 -0 0</pose>
        <self_collide>0</self_collide>
        <kinematic>0</kinematic>
        <gravity>1</gravity>
        <visual name='visual'>
          <geometry>
            <mesh>
              <uri>file://models/aws_robomaker_warehouse_Bucket_01/meshes/aws_robomaker_warehouse_Bucket_01_visual.DAE</uri>
            </mesh>
          </geometry>
          <meta>
            <layer>1</layer>
          </meta>
        </visual>
        <collision name='collision_0'>
          <laser_retro>0</laser_retro>
          <max_contacts>10</max_contacts>
          <pose>0 0 0 0 -0 0</pose>
          <geometry>
            <mesh>
              <uri>file://models/aws_robomaker_warehouse_Bucket_01/meshes/aws_robomaker_warehouse_Bucket_01_collision.DAE</uri>
              <scale>1 1 1</scale>
            </mesh>
          </geometry>
          <surface>
            <friction>
              <ode>
                <mu>0.4</mu>
                <mu2>0.4</mu2>
                <fdir1>0 0 0</fdir1>
                <slip1>0</slip1>
                <slip2>0</slip2>
              </ode>
              <torsional>
                <coefficient>1</coefficient>
                <patch_radius>0</patch_radius>
                <surface_radius>0</surface_radius>
                <use_patch_radius>1</use_patch_radius>
                <ode>
                  <slip>0</slip>
                </ode>
              </torsional>
            </friction>
            <contact>
              <ode/>
            </contact>
            <bounce/>
          </surface>
        </collision>
        <enable_wind>0</enable_wind>
      </link>
      <static>1</static>
      <pose>4.94933 -8.16306 0 0 0 -1.56316</pose>
    </model>
    <model name='cart'>
      <link name='base_footprint'>
        <inertial>
          <pose>-0 0 0.76506 0 -0 0</pose>
          <mass>30.163</mass>
          <inertia>
            <ixx>1.0132</ixx>
            <ixy>-2.3419e-15</ixy>
            <ixz>7.6733e-10</ixz>
            <iyy>1.6281</iyy>
            <iyz>-3.803e-10</iyz>
            <izz>2.1018</izz>
          </inertia>
        </inertial>
        <collision name='base_footprint_fixed_joint_lump__base_link_collision'>
          <pose>0 0 1.371 0 -0 0</pose>
          <geometry>
            <mesh>
              <scale>1 1 1</scale>
              <uri>file:////home/kraiwich/OpenTopic_ws/install/cart_description/share/cart_description/meshes/base_link.STL</uri>
            </mesh>
          </geometry>
          <surface>
            <contact>
              <ode/>
            </contact>
            <friction>
              <ode/>
              <torsional>
                <ode/>
              </torsional>
            </friction>
            <bounce/>
          </surface>
          <max_contacts>10</max_contacts>
        </collision>
        <visual name='base_footprint_fixed_joint_lump__base_link_visual'>
          <pose>0 0 1.371 0 -0 0</pose>
          <geometry>
            <mesh>
              <scale>1 1 1</scale>
              <uri>file:////home/kraiwich/OpenTopic_ws/install/cart_description/share/cart_description/meshes/base_link.STL</uri>
            </mesh>
          </geometry>
          <material>
            <script>
              <name>Gazebo/White</name>
              <uri>file://media/materials/scripts/gazebo.material</uri>
            </script>
          </material>
        </visual>
        <self_collide>0</self_collide>
        <enable_wind>0</enable_wind>
        <kinematic>0</kinematic>
      </link>
      <joint name='rev1_joint' type='revolute'>
        <pose relative_to='base_footprint'>0.455 0.359999 0.0965 0 -0 0</pose>
        <parent>base_footprint</parent>
        <child>rev1_link</child>
        <axis>
          <xyz>0 0 -1</xyz>
          <limit>
            <lower>-1e+16</lower>
            <upper>1e+16</upper>
          </limit>
          <dynamics>
            <spring_reference>0</spring_reference>
            <spring_stiffness>0</spring_stiffness>
          </dynamics>
        </axis>
      </joint>
      <link name='rev1_link'>
        <pose relative_to='rev1_joint'>0 0 0 0 -0 0</pose>
        <inertial>
          <pose>-0.008873 -6.6e-05 -0.024908 0 -0 0</pose>
          <mass>1.39604</mass>
          <inertia>
            <ixx>0.00039872</ixx>
            <ixy>-4.2724e-07</ixy>
            <ixz>-6.7183e-05</ixz>
            <iyy>0.00033801</iyy>
            <iyz>-8.9725e-07</iyz>
            <izz>0.00036573</izz>
          </inertia>
        </inertial>
        <collision name='rev1_link_collision'>
          <pose>0 0 0 0 -0 0</pose>
          <geometry>
            <mesh>
              <scale>1 1 1</scale>
              <uri>file:////home/kraiwich/OpenTopic_ws/install/cart_description/share/cart_description/meshes/rev1_link.STL</uri>
            </mesh>
          </geometry>
          <surface>
            <contact>
              <ode/>
            </contact>
            <friction>
              <ode>
                <mu>1000</mu>
                <mu2>1000</mu2>
              </ode>
              <torsional>
                <ode/>
              </torsional>
            </friction>
            <bounce/>
          </surface>
          <max_contacts>10</max_contacts>
        </collision>
        <visual name='rev1_link_visual'>
          <pose>0 0 0 0 -0 0</pose>
          <geometry>
            <mesh>
              <scale>1 1 1</scale>
              <uri>file:////home/kraiwich/OpenTopic_ws/install/cart_description/share/cart_description/meshes/rev1_link.STL</uri>
            </mesh>
          </geometry>
          <material>
            <script>
              <name>Gazebo/White</name>
              <uri>file://media/materials/scripts/gazebo.material</uri>
            </script>
          </material>
        </visual>
        <self_collide>0</self_collide>
        <enable_wind>0</enable_wind>
        <kinematic>0</kinematic>
      </link>
      <joint name='wheel_joint1' type='revolute'>
        <pose relative_to='rev1_link'>-0.025 0.021001 -0.059 -1.5708 0 0</pose>
        <parent>rev1_link</parent>
        <child>wheel_link1</child>
        <axis>
          <xyz>0 0 -1</xyz>
          <limit>
            <lower>-1e+16</lower>
            <upper>1e+16</upper>
          </limit>
          <dynamics>
            <spring_reference>0</spring_reference>
            <spring_stiffness>0</spring_stiffness>
          </dynamics>
        </axis>
      </joint>
      <link name='wheel_link1'>
        <pose relative_to='wheel_joint1'>0 0 0 0 -0 0</pose>
        <inertial>
          <pose>-0 -0 -0.021 0 -0 0</pose>
          <mass>3.17935</mass>
          <inertia>
            <ixx>8.2728e-05</ixx>
            <ixy>-9.2883e-10</ixy>
            <ixz>-2.5882e-10</ixz>
            <iyy>8.2727e-05</iyy>
            <iyz>-4.0977e-11</iyz>
            <izz>0.00012509</izz>
          </inertia>
        </inertial>
        <collision name='wheel_link1_collision'>
          <pose>0 0 0 0 -0 0</pose>
          <geometry>
            <mesh>
              <scale>1 1 1</scale>
              <uri>file:////home/kraiwich/OpenTopic_ws/install/cart_description/share/cart_description/meshes/wheel_link1.STL</uri>
            </mesh>
          </geometry>
          <surface>
            <contact>
              <ode/>
            </contact>
            <friction>
              <ode>
                <mu>1000</mu>
                <mu2>1000</mu2>
              </ode>
              <torsional>
                <ode/>
              </torsional>
            </friction>
            <bounce/>
          </surface>
          <max_contacts>10</max_contacts>
        </collision>
        <visual name='wheel_link1_visual'>
          <pose>0 0 0 0 -0 0</pose>
          <geometry>
            <mesh>
              <scale>1 1 1</scale>
              <uri>file:////home/kraiwich/OpenTopic_ws/install/cart_description/share/cart_description/meshes/wheel_link1.STL</uri>
            </mesh>
          </geometry>
          <material>
            <script>
              <name>Gazebo/Black</name>
              <uri>file://media/materials/scripts/gazebo.material</uri>
            </script>
          </material>
        </visual>
        <self_collide>0</self_collide>
        <enable_wind>0</enable_wind>
        <kinematic>0</kinematic>
      </link>
      <joint name='rev2_joint' type='revolute'>
        <pose relative_to='base_footprint'>-0.455 0.359999 0.0965 0 -0 0</pose>
        <parent>base_footprint</parent>
        <child>rev2_link</child>
        <axis>
          <xyz>0 0 -1</xyz>
          <limit>
            <lower>-1e+16</lower>
            <upper>1e+16</upper>
          </limit>
          <dynamics>
            <spring_reference>0</spring_reference>
            <spring_stiffness>0</spring_stiffness>
          </dynamics>
        </axis>
      </joint>
      <link name='rev2_link'>
        <pose relative_to='rev2_joint'>0 0 0 0 -0 0</pose>
        <inertial>
          <pose>-0.008873 -6.6e-05 -0.024908 0 -0 0</pose>
          <mass>1.39604</mass>
          <inertia>
            <ixx>0.000398723</ixx>
            <ixy>-4.27245e-07</ixy>
            <ixz>-6.71828e-05</ixz>
            <iyy>0.000338006</iyy>
            <iyz>-8.97252e-07</iyz>
            <izz>0.000365728</izz>
          </inertia>
        </inertial>
        <collision name='rev2_link_collision'>
          <pose>0 0 0 0 -0 0</pose>
          <geometry>
            <mesh>
              <scale>1 1 1</scale>
              <uri>file:////home/kraiwich/OpenTopic_ws/install/cart_description/share/cart_description/meshes/rev2_link.STL</uri>
            </mesh>
          </geometry>
          <surface>
            <contact>
              <ode/>
            </contact>
            <friction>
              <ode>
                <mu>1000</mu>
                <mu2>1000</mu2>
              </ode>
              <torsional>
                <ode/>
              </torsional>
            </friction>
            <bounce/>
          </surface>
          <max_contacts>10</max_contacts>
        </collision>
        <visual name='rev2_link_visual'>
          <pose>0 0 0 0 -0 0</pose>
          <geometry>
            <mesh>
              <scale>1 1 1</scale>
              <uri>file:////home/kraiwich/OpenTopic_ws/install/cart_description/share/cart_description/meshes/rev2_link.STL</uri>
            </mesh>
          </geometry>
          <material>
            <script>
              <name>Gazebo/White</name>
              <uri>file://media/materials/scripts/gazebo.material</uri>
            </script>
          </material>
        </visual>
        <self_collide>0</self_collide>
        <enable_wind>0</enable_wind>
        <kinematic>0</kinematic>
      </link>
      <joint name='wheel_joint2' type='revolute'>
        <pose relative_to='rev2_link'>-0.025001 0.021001 -0.059 -1.5708 0 0</pose>
        <parent>rev2_link</parent>
        <child>wheel_link2</child>
        <axis>
          <xyz>0 0 -1</xyz>
          <limit>
            <lower>-1e+16</lower>
            <upper>1e+16</upper>
          </limit>
          <dynamics>
            <spring_reference>0</spring_reference>
            <spring_stiffness>0</spring_stiffness>
          </dynamics>
        </axis>
      </joint>
      <link name='wheel_link2'>
        <pose relative_to='wheel_joint2'>0 0 0 0 -0 0</pose>
        <inertial>
          <pose>0 0 -0.021 0 -0 0</pose>
          <mass>3.17935</mass>
          <inertia>
            <ixx>8.27284e-05</ixx>
            <ixy>4.23195e-11</ixy>
            <ixz>3.01176e-10</ixz>
            <iyy>8.27261e-05</iyy>
            <iyz>2.65006e-10</iyz>
            <izz>0.00012509</izz>
          </inertia>
        </inertial>
        <collision name='wheel_link2_collision'>
          <pose>0 0 0 0 -0 0</pose>
          <geometry>
            <mesh>
              <scale>1 1 1</scale>
              <uri>file:////home/kraiwich/OpenTopic_ws/install/cart_description/share/cart_description/meshes/wheel_link2.STL</uri>
            </mesh>
          </geometry>
          <surface>
            <contact>
              <ode/>
            </contact>
            <friction>
              <ode>
                <mu>1000</mu>
                <mu2>1000</mu2>
              </ode>
              <torsional>
                <ode/>
              </torsional>
            </friction>
            <bounce/>
          </surface>
          <max_contacts>10</max_contacts>
        </collision>
        <visual name='wheel_link2_visual'>
          <pose>0 0 0 0 -0 0</pose>
          <geometry>
            <mesh>
              <scale>1 1 1</scale>
              <uri>file:////home/kraiwich/OpenTopic_ws/install/cart_description/share/cart_description/meshes/wheel_link2.STL</uri>
            </mesh>
          </geometry>
          <material>
            <script>
              <name>Gazebo/Black</name>
              <uri>file://media/materials/scripts/gazebo.material</uri>
            </script>
          </material>
        </visual>
        <self_collide>0</self_collide>
        <enable_wind>0</enable_wind>
        <kinematic>0</kinematic>
      </link>
      <joint name='rev3_joint' type='revolute'>
        <pose relative_to='base_footprint'>0.455 -0.360001 0.0965 0 -0 0</pose>
        <parent>base_footprint</parent>
        <child>rev3_link</child>
        <axis>
          <xyz>0 0 -1</xyz>
          <limit>
            <lower>-1e+16</lower>
            <upper>1e+16</upper>
          </limit>
          <dynamics>
            <spring_reference>0</spring_reference>
            <spring_stiffness>0</spring_stiffness>
          </dynamics>
        </axis>
      </joint>
      <link name='rev3_link'>
        <pose relative_to='rev3_joint'>0 0 0 0 -0 0</pose>
        <inertial>
          <pose>-0.008873 -6.6e-05 -0.024908 0 -0 0</pose>
          <mass>1.39604</mass>
          <inertia>
            <ixx>0.000398723</ixx>
            <ixy>-4.27245e-07</ixy>
            <ixz>-6.71828e-05</ixz>
            <iyy>0.000338006</iyy>
            <iyz>-8.97252e-07</iyz>
            <izz>0.000365728</izz>
          </inertia>
        </inertial>
        <collision name='rev3_link_collision'>
          <pose>0 0 0 0 -0 0</pose>
          <geometry>
            <mesh>
              <scale>1 1 1</scale>
              <uri>file:////home/kraiwich/OpenTopic_ws/install/cart_description/share/cart_description/meshes/rev3_link.STL</uri>
            </mesh>
          </geometry>
          <surface>
            <contact>
              <ode/>
            </contact>
            <friction>
              <ode>
                <mu>1000</mu>
                <mu2>1000</mu2>
              </ode>
              <torsional>
                <ode/>
              </torsional>
            </friction>
            <bounce/>
          </surface>
          <max_contacts>10</max_contacts>
        </collision>
        <visual name='rev3_link_visual'>
          <pose>0 0 0 0 -0 0</pose>
          <geometry>
            <mesh>
              <scale>1 1 1</scale>
              <uri>file:////home/kraiwich/OpenTopic_ws/install/cart_description/share/cart_description/meshes/rev3_link.STL</uri>
            </mesh>
          </geometry>
          <material>
            <script>
              <name>Gazebo/White</name>
              <uri>file://media/materials/scripts/gazebo.material</uri>
            </script>
          </material>
        </visual>
        <self_collide>0</self_collide>
        <enable_wind>0</enable_wind>
        <kinematic>0</kinematic>
      </link>
      <joint name='wheel_joint3' type='revolute'>
        <pose relative_to='rev3_link'>-0.025007 -0.020999 -0.058998 -1.5708 0 0</pose>
        <parent>rev3_link</parent>
        <child>wheel_link3</child>
        <axis>
          <xyz>0 0 -1</xyz>
          <limit>
            <lower>-1e+16</lower>
            <upper>1e+16</upper>
          </limit>
          <dynamics>
            <spring_reference>0</spring_reference>
            <spring_stiffness>0</spring_stiffness>
          </dynamics>
        </axis>
      </joint>
      <link name='wheel_link3'>
        <pose relative_to='wheel_joint3'>0 0 0 0 -0 0</pose>
        <inertial>
          <pose>7e-06 2e-06 0.021 0 -0 0</pose>
          <mass>3.17935</mass>
          <inertia>
            <ixx>8.2728e-05</ixx>
            <ixy>-9.2883e-10</ixy>
            <ixz>-2.5882e-10</ixz>
            <iyy>8.2727e-05</iyy>
            <iyz>-4.0977e-11</iyz>
            <izz>0.00012509</izz>
          </inertia>
        </inertial>
        <collision name='wheel_link3_collision'>
          <pose>0 0 0 0 -0 0</pose>
          <geometry>
            <mesh>
              <scale>1 1 1</scale>
              <uri>file:////home/kraiwich/OpenTopic_ws/install/cart_description/share/cart_description/meshes/wheel_link3.STL</uri>
            </mesh>
          </geometry>
          <surface>
            <contact>
              <ode/>
            </contact>
            <friction>
              <ode>
                <mu>1000</mu>
                <mu2>1000</mu2>
              </ode>
              <torsional>
                <ode/>
              </torsional>
            </friction>
            <bounce/>
          </surface>
          <max_contacts>10</max_contacts>
        </collision>
        <visual name='wheel_link3_visual'>
          <pose>0 0 0 0 -0 0</pose>
          <geometry>
            <mesh>
              <scale>1 1 1</scale>
              <uri>file:////home/kraiwich/OpenTopic_ws/install/cart_description/share/cart_description/meshes/wheel_link3.STL</uri>
            </mesh>
          </geometry>
          <material>
            <script>
              <name>Gazebo/Black</name>
              <uri>file://media/materials/scripts/gazebo.material</uri>
            </script>
          </material>
        </visual>
        <self_collide>0</self_collide>
        <enable_wind>0</enable_wind>
        <kinematic>0</kinematic>
      </link>
      <joint name='rev4_joint' type='revolute'>
        <pose relative_to='base_footprint'>-0.455 -0.360001 0.0965 0 -0 0</pose>
        <parent>base_footprint</parent>
        <child>rev4_link</child>
        <axis>
          <xyz>0 0 -1</xyz>
          <limit>
            <lower>-1e+16</lower>
            <upper>1e+16</upper>
          </limit>
          <dynamics>
            <spring_reference>0</spring_reference>
            <spring_stiffness>0</spring_stiffness>
          </dynamics>
        </axis>
      </joint>
      <link name='rev4_link'>
        <pose relative_to='rev4_joint'>0 0 0 0 -0 0</pose>
        <inertial>
          <pose>-0.008873 -6.6e-05 -0.024908 0 -0 0</pose>
          <mass>1.39604</mass>
          <inertia>
            <ixx>0.000398723</ixx>
            <ixy>-4.27245e-07</ixy>
            <ixz>-6.71828e-05</ixz>
            <iyy>0.000338006</iyy>
            <iyz>-8.97252e-07</iyz>
            <izz>0.000365728</izz>
          </inertia>
        </inertial>
        <collision name='rev4_link_collision'>
          <pose>0 0 0 0 -0 0</pose>
          <geometry>
            <mesh>
              <scale>1 1 1</scale>
              <uri>file:////home/kraiwich/OpenTopic_ws/install/cart_description/share/cart_description/meshes/rev4_link.STL</uri>
            </mesh>
          </geometry>
          <surface>
            <contact>
              <ode/>
            </contact>
            <friction>
              <ode>
                <mu>1000</mu>
                <mu2>1000</mu2>
              </ode>
              <torsional>
                <ode/>
              </torsional>
            </friction>
            <bounce/>
          </surface>
          <max_contacts>10</max_contacts>
        </collision>
        <visual name='rev4_link_visual'>
          <pose>0 0 0 0 -0 0</pose>
          <geometry>
            <mesh>
              <scale>1 1 1</scale>
              <uri>file:////home/kraiwich/OpenTopic_ws/install/cart_description/share/cart_description/meshes/rev4_link.STL</uri>
            </mesh>
          </geometry>
          <material>
            <script>
              <name>Gazebo/White</name>
              <uri>file://media/materials/scripts/gazebo.material</uri>
            </script>
          </material>
        </visual>
        <self_collide>0</self_collide>
        <enable_wind>0</enable_wind>
        <kinematic>0</kinematic>
      </link>
      <joint name='wheel_joint4' type='revolute'>
        <pose relative_to='rev4_link'>-0.025007 -0.020999 -0.058998 -1.5708 0 0</pose>
        <parent>rev4_link</parent>
        <child>wheel_link4</child>
        <axis>
          <xyz>0 0 -1</xyz>
          <limit>
            <lower>-1e+16</lower>
            <upper>1e+16</upper>
          </limit>
          <dynamics>
            <spring_reference>0</spring_reference>
            <spring_stiffness>0</spring_stiffness>
          </dynamics>
        </axis>
      </joint>
      <link name='wheel_link4'>
        <pose relative_to='wheel_joint4'>0 0 0 0 -0 0</pose>
        <inertial>
          <pose>7e-06 2e-06 0.021 0 -0 0</pose>
          <mass>3.17935</mass>
          <inertia>
            <ixx>8.27278e-05</ixx>
            <ixy>-9.28827e-10</ixy>
            <ixz>-2.58823e-10</ixz>
            <iyy>8.27267e-05</iyy>
            <iyz>-4.09773e-11</iyz>
            <izz>0.00012509</izz>
          </inertia>
        </inertial>
        <collision name='wheel_link4_collision'>
          <pose>0 0 0 0 -0 0</pose>
          <geometry>
            <mesh>
              <scale>1 1 1</scale>
              <uri>file:////home/kraiwich/OpenTopic_ws/install/cart_description/share/cart_description/meshes/wheel_link4.STL</uri>
            </mesh>
          </geometry>
          <surface>
            <contact>
              <ode/>
            </contact>
            <friction>
              <ode>
                <mu>1000</mu>
                <mu2>1000</mu2>
              </ode>
              <torsional>
                <ode/>
              </torsional>
            </friction>
            <bounce/>
          </surface>
          <max_contacts>10</max_contacts>
        </collision>
        <visual name='wheel_link4_visual'>
          <pose>0 0 0 0 -0 0</pose>
          <geometry>
            <mesh>
              <scale>1 1 1</scale>
              <uri>file:////home/kraiwich/OpenTopic_ws/install/cart_description/share/cart_description/meshes/wheel_link4.STL</uri>
            </mesh>
          </geometry>
          <material>
            <script>
              <name>Gazebo/Black</name>
              <uri>file://media/materials/scripts/gazebo.material</uri>
            </script>
          </material>
        </visual>
        <self_collide>0</self_collide>
        <enable_wind>0</enable_wind>
        <kinematic>0</kinematic>
      </link>
      <pose>-2 -2 0 0 -0 0</pose>
    </model>
    <model name='aruco_marker_6'>
      <static>1</static>
      <link name='link'>
        <visual name='visual'>
          <geometry>
            <box>
              <size>0.15 0.15 0.01</size>
            </box>
          </geometry>
          <material>
            <script>
              <uri>model://aruco_marker_6/materials/scripts</uri>
              <name>AruCo/Marker6</name>
            </script>
          </material>
        </visual>
        <self_collide>0</self_collide>
        <enable_wind>0</enable_wind>
        <kinematic>0</kinematic>
      </link>
      <pose>1.88299 9.52681 0 0 -0 0</pose>
    </model>
    <model name='aruco_marker_7'>
      <static>1</static>
      <link name='link'>
        <visual name='visual'>
          <geometry>
            <box>
              <size>0.15 0.15 0.01</size>
            </box>
          </geometry>
          <material>
            <script>
              <uri>model://aruco_marker_7/materials/scripts</uri>
              <name>AruCo/Marker7</name>
            </script>
          </material>
        </visual>
        <self_collide>0</self_collide>
        <enable_wind>0</enable_wind>
        <kinematic>0</kinematic>
      </link>
      <pose>-3.77954 10.6832 0 0 -0 0</pose>
    </model>
    <model name='aruco_marker_8'>
      <static>1</static>
      <link name='link'>
        <visual name='visual'>
          <geometry>
            <box>
              <size>0.15 0.15 0.01</size>
            </box>
          </geometry>
          <material>
            <script>
              <uri>model://aruco_marker_8/materials/scripts</uri>
              <name>AruCo/Marker8</name>
            </script>
          </material>
        </visual>
        <self_collide>0</self_collide>
        <enable_wind>0</enable_wind>
        <kinematic>0</kinematic>
      </link>
      <pose>-7.29572 9.287 0 0 -0 0</pose>
    </model>
  </world>
</sdf>
