<sdf version='1.7'>
  <world name='default'>
    <gravity>0 0 -9.8</gravity>
    <physics name='default_physics' default='0' type='ode'>
      <max_step_size>0.001</max_step_size>
      <real_time_factor>1</real_time_factor>
      <real_time_update_rate>1000</real_time_update_rate>
    </physics>
    <model name='aws_robomaker_warehouse_ShelfF_01_001'>
      <frame name='aws_robomaker_warehouse_ShelfF_01::__model__' attached_to='aws_robomaker_warehouse_ShelfF_01::link'>
        <pose relative_to='__model__'>0 0 0 0 -0 0</pose>
      </frame>
      <link name='aws_robomaker_warehouse_ShelfF_01::link'>
        <inertial>
          <mass>30</mass>
          <inertia>
            <ixx>907.144</ixx>
            <ixy>0</ixy>
            <ixz>0</ixz>
            <iyy>104.95</iyy>
            <iyz>0</iyz>
            <izz>824.248</izz>
          </inertia>
        </inertial>
        <collision name='collision'>
          <geometry>
            <mesh>
              <uri>file://models/aws_robomaker_warehouse_ShelfF_01/meshes/aws_robomaker_warehouse_ShelfF_01_collision.DAE</uri>
              <scale>1 1 1</scale>
            </mesh>
          </geometry>
          <surface>
            <friction>
              <ode>
                <mu>0.2</mu>
                <mu2>0.2</mu2>
                <fdir1>0 0 0</fdir1>
                <slip1>0</slip1>
                <slip2>0</slip2>
              </ode>
              <torsional>
                <ode/>
              </torsional>
            </friction>
            <contact>
              <ode/>
            </contact>
            <bounce/>
          </surface>
          <max_contacts>10</max_contacts>
        </collision>
        <visual name='visual'>
          <geometry>
            <mesh>
              <uri>file://models/aws_robomaker_warehouse_ShelfF_01/meshes/aws_robomaker_warehouse_ShelfF_01_visual.DAE</uri>
            </mesh>
          </geometry>
          <meta>
            <layer>1</layer>
          </meta>
        </visual>
        <pose relative_to='aws_robomaker_warehouse_ShelfF_01::__model__'>0 0 0 0 -0 0</pose>
        <self_collide>0</self_collide>
        <enable_wind>0</enable_wind>
        <kinematic>0</kinematic>
      </link>
      <static>1</static>
      <pose>-5.79514 -0.956635 0 0 -0 0</pose>
    </model>
    <model name='aws_robomaker_warehouse_WallB_01_001'>
      <frame name='aws_robomaker_warehouse_WallB_01::__model__' attached_to='aws_robomaker_warehouse_WallB_01::link'>
        <pose relative_to='__model__'>0 0 0 0 -0 0</pose>
      </frame>
      <link name='aws_robomaker_warehouse_WallB_01::link'>
        <inertial>
          <mass>1000</mass>
          <inertia>
            <ixx>840083</ixx>
            <ixy>0</ixy>
            <ixz>0</ixz>
            <iyy>475500</iyy>
            <iyz>0</iyz>
            <izz>1.30208e+06</izz>
          </inertia>
        </inertial>
        <collision name='collision'>
          <geometry>
            <mesh>
              <uri>file://models/aws_robomaker_warehouse_WallB_01/meshes/aws_robomaker_warehouse_WallB_01_collision.DAE</uri>
              <scale>1 1 1</scale>
            </mesh>
          </geometry>
          <surface>
            <friction>
              <ode>
                <mu>0.5</mu>
                <mu2>0.5</mu2>
                <fdir1>0 0 0</fdir1>
                <slip1>0</slip1>
                <slip2>0</slip2>
              </ode>
              <torsional>
                <ode/>
              </torsional>
            </friction>
            <contact>
              <ode/>
            </contact>
            <bounce/>
          </surface>
          <max_contacts>10</max_contacts>
        </collision>
        <visual name='visual'>
          <geometry>
            <mesh>
              <uri>file://models/aws_robomaker_warehouse_WallB_01/meshes/aws_robomaker_warehouse_WallB_01_visual.DAE</uri>
            </mesh>
          </geometry>
          <meta>
            <layer>2</layer>
          </meta>
        </visual>
        <pose relative_to='aws_robomaker_warehouse_WallB_01::__model__'>0 0 0 0 -0 0</pose>
        <self_collide>0</self_collide>
        <enable_wind>0</enable_wind>
        <kinematic>0</kinematic>
      </link>
      <static>1</static>
      <pose>0 0 0 0 -0 0</pose>
    </model>
    <model name='aws_robomaker_warehouse_ShelfE_01_001'>
      <frame name='aws_robomaker_warehouse_ShelfE_01::__model__' attached_to='aws_robomaker_warehouse_ShelfE_01::link'>
        <pose relative_to='__model__'>0 0 0 0 -0 0</pose>
      </frame>
      <link name='aws_robomaker_warehouse_ShelfE_01::link'>
        <inertial>
          <mass>30</mass>
          <inertia>
            <ixx>907.144</ixx>
            <ixy>0</ixy>
            <ixz>0</ixz>
            <iyy>104.95</iyy>
            <iyz>0</iyz>
            <izz>824.248</izz>
          </inertia>
        </inertial>
        <collision name='collision'>
          <geometry>
            <mesh>
              <uri>file://models/aws_robomaker_warehouse_ShelfE_01/meshes/aws_robomaker_warehouse_ShelfE_01_collision.DAE</uri>
              <scale>1 1 1</scale>
            </mesh>
          </geometry>
          <surface>
            <friction>
              <ode>
                <mu>0.2</mu>
                <mu2>0.2</mu2>
                <fdir1>0 0 0</fdir1>
                <slip1>0</slip1>
                <slip2>0</slip2>
              </ode>
              <torsional>
                <ode/>
              </torsional>
            </friction>
            <contact>
              <ode/>
            </contact>
            <bounce/>
          </surface>
          <max_contacts>10</max_contacts>
        </collision>
        <visual name='visual'>
          <geometry>
            <mesh>
              <uri>file://models/aws_robomaker_warehouse_ShelfE_01/meshes/aws_robomaker_warehouse_ShelfE_01_visual.DAE</uri>
            </mesh>
          </geometry>
          <meta>
            <layer>1</layer>
          </meta>
        </visual>
        <pose relative_to='aws_robomaker_warehouse_ShelfE_01::__model__'>0 0 0 0 -0 0</pose>
        <self_collide>0</self_collide>
        <enable_wind>0</enable_wind>
        <kinematic>0</kinematic>
      </link>
      <static>1</static>
      <pose>4.73156 0.57943 0 0 -0 0</pose>
    </model>
    <model name='aws_robomaker_warehouse_ShelfE_01_002'>
      <frame name='aws_robomaker_warehouse_ShelfE_01::__model__' attached_to='aws_robomaker_warehouse_ShelfE_01::link'>
        <pose relative_to='__model__'>0 0 0 0 -0 0</pose>
      </frame>
      <link name='aws_robomaker_warehouse_ShelfE_01::link'>
        <inertial>
          <mass>30</mass>
          <inertia>
            <ixx>907.144</ixx>
            <ixy>0</ixy>
            <ixz>0</ixz>
            <iyy>104.95</iyy>
            <iyz>0</iyz>
            <izz>824.248</izz>
          </inertia>
        </inertial>
        <collision name='collision'>
          <geometry>
            <mesh>
              <uri>file://models/aws_robomaker_warehouse_ShelfE_01/meshes/aws_robomaker_warehouse_ShelfE_01_collision.DAE</uri>
              <scale>1 1 1</scale>
            </mesh>
          </geometry>
          <surface>
            <friction>
              <ode>
                <mu>0.2</mu>
                <mu2>0.2</mu2>
                <fdir1>0 0 0</fdir1>
                <slip1>0</slip1>
                <slip2>0</slip2>
              </ode>
              <torsional>
                <ode/>
              </torsional>
            </friction>
            <contact>
              <ode/>
            </contact>
            <bounce/>
          </surface>
          <max_contacts>10</max_contacts>
        </collision>
        <visual name='visual'>
          <geometry>
            <mesh>
              <uri>file://models/aws_robomaker_warehouse_ShelfE_01/meshes/aws_robomaker_warehouse_ShelfE_01_visual.DAE</uri>
            </mesh>
          </geometry>
          <meta>
            <layer>1</layer>
          </meta>
        </visual>
        <pose relative_to='aws_robomaker_warehouse_ShelfE_01::__model__'>0 0 0 0 -0 0</pose>
        <self_collide>0</self_collide>
        <enable_wind>0</enable_wind>
        <kinematic>0</kinematic>
      </link>
      <static>1</static>
      <pose>4.73156 -4.82705 0 0 -0 0</pose>
    </model>
    <model name='aws_robomaker_warehouse_ShelfD_01_002'>
      <frame name='aws_robomaker_warehouse_ShelfD_01::__model__' attached_to='aws_robomaker_warehouse_ShelfD_01::link'>
        <pose relative_to='__model__'>0 0 0 0 -0 0</pose>
      </frame>
      <link name='aws_robomaker_warehouse_ShelfD_01::link'>
        <inertial>
          <mass>30</mass>
          <inertia>
            <ixx>907.144</ixx>
            <ixy>0</ixy>
            <ixz>0</ixz>
            <iyy>104.95</iyy>
            <iyz>0</iyz>
            <izz>824.248</izz>
          </inertia>
        </inertial>
        <collision name='collision'>
          <geometry>
            <mesh>
              <uri>file://models/aws_robomaker_warehouse_ShelfD_01/meshes/aws_robomaker_warehouse_ShelfD_01_collision.DAE</uri>
              <scale>1 1 1</scale>
            </mesh>
          </geometry>
          <surface>
            <friction>
              <ode>
                <mu>0.2</mu>
                <mu2>0.2</mu2>
                <fdir1>0 0 0</fdir1>
                <slip1>0</slip1>
                <slip2>0</slip2>
              </ode>
              <torsional>
                <ode/>
              </torsional>
            </friction>
            <contact>
              <ode/>
            </contact>
            <bounce/>
          </surface>
          <max_contacts>10</max_contacts>
        </collision>
        <visual name='visual'>
          <geometry>
            <mesh>
              <uri>file://models/aws_robomaker_warehouse_ShelfD_01/meshes/aws_robomaker_warehouse_ShelfD_01_visual.DAE</uri>
            </mesh>
          </geometry>
          <meta>
            <layer>1</layer>
          </meta>
        </visual>
        <pose relative_to='aws_robomaker_warehouse_ShelfD_01::__model__'>0 0 0 0 -0 0</pose>
        <self_collide>0</self_collide>
        <enable_wind>0</enable_wind>
        <kinematic>0</kinematic>
      </link>
      <static>1</static>
      <pose>4.73156 -3.03855 0 0 -0 0</pose>
    </model>
    <model name='aws_robomaker_warehouse_GroundB_01_001'>
      <frame name='aws_robomaker_warehouse_GroundB_01::__model__' attached_to='aws_robomaker_warehouse_GroundB_01::link'>
        <pose relative_to='__model__'>0 0 0 0 -0 0</pose>
      </frame>
      <link name='aws_robomaker_warehouse_GroundB_01::link'>
        <inertial>
          <mass>1000</mass>
          <inertia>
            <ixx>1.20008e+06</ixx>
            <ixy>0</ixy>
            <ixz>0</ixz>
            <iyy>8.33342e+06</iyy>
            <iyz>0</iyz>
            <izz>2.03333e+06</izz>
          </inertia>
        </inertial>
        <collision name='collision'>
          <geometry>
            <mesh>
              <uri>file://models/aws_robomaker_warehouse_GroundB_01/meshes/aws_robomaker_warehouse_GroundB_01_collision.DAE</uri>
              <scale>1 1 1</scale>
            </mesh>
          </geometry>
          <surface>
            <friction>
              <ode>
                <mu>100</mu>
                <mu2>50</mu2>
                <fdir1>0 0 0</fdir1>
                <slip1>0</slip1>
                <slip2>0</slip2>
              </ode>
              <torsional>
                <ode/>
              </torsional>
            </friction>
            <contact>
              <ode/>
            </contact>
            <bounce/>
          </surface>
          <max_contacts>10</max_contacts>
        </collision>
        <visual name='visual'>
          <geometry>
            <mesh>
              <uri>file://models/aws_robomaker_warehouse_GroundB_01/meshes/aws_robomaker_warehouse_GroundB_01_visual.DAE</uri>
            </mesh>
          </geometry>
          <meta>
            <layer>1</layer>
          </meta>
        </visual>
        <pose relative_to='aws_robomaker_warehouse_GroundB_01::__model__'>0 0 0 0 -0 0</pose>
        <self_collide>0</self_collide>
        <enable_wind>0</enable_wind>
        <kinematic>0</kinematic>
      </link>
      <static>1</static>
      <pose>0 0 -0.090092 0 -0 0</pose>
    </model>
    <model name='aws_robomaker_warehouse_Lamp_01_005'>
      <frame name='aws_robomaker_warehouse_Lamp_01::__model__' attached_to='aws_robomaker_warehouse_Lamp_01::link'>
        <pose relative_to='__model__'>0 0 0 0 -0 0</pose>
      </frame>
      <link name='aws_robomaker_warehouse_Lamp_01::link'>
        <inertial>
          <mass>30</mass>
          <inertia>
            <ixx>907.144</ixx>
            <ixy>0</ixy>
            <ixz>0</ixz>
            <iyy>104.95</iyy>
            <iyz>0</iyz>
            <izz>824.248</izz>
          </inertia>
        </inertial>
        <collision name='collision'>
          <geometry>
            <mesh>
              <uri>file://models/aws_robomaker_warehouse_Lamp_01/meshes/aws_robomaker_warehouse_Lamp_01_collision.DAE</uri>
              <scale>1 1 1</scale>
            </mesh>
          </geometry>
          <surface>
            <friction>
              <ode>
                <mu>0.2</mu>
                <mu2>0.2</mu2>
                <fdir1>0 0 0</fdir1>
                <slip1>0</slip1>
                <slip2>0</slip2>
              </ode>
              <torsional>
                <ode/>
              </torsional>
            </friction>
            <contact>
              <ode/>
            </contact>
            <bounce/>
          </surface>
          <max_contacts>10</max_contacts>
        </collision>
        <visual name='visual'>
          <geometry>
            <mesh>
              <uri>file://models/aws_robomaker_warehouse_Lamp_01/meshes/aws_robomaker_warehouse_Lamp_01_visual.DAE</uri>
            </mesh>
          </geometry>
          <meta>
            <layer>1</layer>
          </meta>
        </visual>
        <pose relative_to='aws_robomaker_warehouse_Lamp_01::__model__'>0 0 0 0 -0 0</pose>
        <self_collide>0</self_collide>
        <enable_wind>0</enable_wind>
        <kinematic>0</kinematic>
      </link>
      <static>1</static>
      <pose>0 0 -4 0 -0 0</pose>
    </model>
    <model name='aws_robomaker_warehouse_Bucket_01_020'>
      <frame name='aws_robomaker_warehouse_Bucket_01::__model__' attached_to='aws_robomaker_warehouse_Bucket_01::body'>
        <pose relative_to='__model__'>0 0 0 0 -0 0</pose>
      </frame>
      <link name='aws_robomaker_warehouse_Bucket_01::body'>
        <inertial>
          <mass>2</mass>
          <pose>0 0 0 0 -0 0</pose>
          <inertia>
            <ixx>0.57</ixx>
            <ixy>0</ixy>
            <ixz>0</ixz>
            <iyy>0.474</iyy>
            <iyz>0</iyz>
            <izz>0.391</izz>
          </inertia>
        </inertial>
        <pose relative_to='aws_robomaker_warehouse_Bucket_01::__model__'>0 0 0 0 -0 0</pose>
        <self_collide>0</self_collide>
        <kinematic>0</kinematic>
        <gravity>1</gravity>
        <visual name='visual'>
          <geometry>
            <mesh>
              <uri>file://models/aws_robomaker_warehouse_Bucket_01/meshes/aws_robomaker_warehouse_Bucket_01_visual.DAE</uri>
            </mesh>
          </geometry>
          <meta>
            <layer>1</layer>
          </meta>
        </visual>
        <collision name='collision_0'>
          <laser_retro>0</laser_retro>
          <max_contacts>10</max_contacts>
          <pose>0 0 0 0 -0 0</pose>
          <geometry>
            <mesh>
              <uri>file://models/aws_robomaker_warehouse_Bucket_01/meshes/aws_robomaker_warehouse_Bucket_01_collision.DAE</uri>
              <scale>1 1 1</scale>
            </mesh>
          </geometry>
          <surface>
            <friction>
              <ode>
                <mu>0.4</mu>
                <mu2>0.4</mu2>
                <fdir1>0 0 0</fdir1>
                <slip1>0</slip1>
                <slip2>0</slip2>
              </ode>
              <torsional>
                <coefficient>1</coefficient>
                <patch_radius>0</patch_radius>
                <surface_radius>0</surface_radius>
                <use_patch_radius>1</use_patch_radius>
                <ode>
                  <slip>0</slip>
                </ode>
              </torsional>
            </friction>
            <contact>
              <ode/>
            </contact>
            <bounce/>
          </surface>
        </collision>
        <enable_wind>0</enable_wind>
      </link>
      <static>1</static>
      <pose>0.433449 9.63171 0 0 0 -1.56316</pose>
    </model>
    <model name='aws_robomaker_warehouse_Bucket_01_021'>
      <frame name='aws_robomaker_warehouse_Bucket_01::__model__' attached_to='aws_robomaker_warehouse_Bucket_01::body'>
        <pose relative_to='__model__'>0 0 0 0 -0 0</pose>
      </frame>
      <link name='aws_robomaker_warehouse_Bucket_01::body'>
        <inertial>
          <mass>2</mass>
          <pose>0 0 0 0 -0 0</pose>
          <inertia>
            <ixx>0.57</ixx>
            <ixy>0</ixy>
            <ixz>0</ixz>
            <iyy>0.474</iyy>
            <iyz>0</iyz>
            <izz>0.391</izz>
          </inertia>
        </inertial>
        <pose relative_to='aws_robomaker_warehouse_Bucket_01::__model__'>0 0 0 0 -0 0</pose>
        <self_collide>0</self_collide>
        <kinematic>0</kinematic>
        <gravity>1</gravity>
        <visual name='visual'>
          <geometry>
            <mesh>
              <uri>file://models/aws_robomaker_warehouse_Bucket_01/meshes/aws_robomaker_warehouse_Bucket_01_visual.DAE</uri>
            </mesh>
          </geometry>
          <meta>
            <layer>1</layer>
          </meta>
        </visual>
        <collision name='collision_0'>
          <laser_retro>0</laser_retro>
          <max_contacts>10</max_contacts>
          <pose>0 0 0 0 -0 0</pose>
          <geometry>
            <mesh>
              <uri>file://models/aws_robomaker_warehouse_Bucket_01/meshes/aws_robomaker_warehouse_Bucket_01_collision.DAE</uri>
              <scale>1 1 1</scale>
            </mesh>
          </geometry>
          <surface>
            <friction>
              <ode>
                <mu>0.4</mu>
                <mu2>0.4</mu2>
                <fdir1>0 0 0</fdir1>
                <slip1>0</slip1>
                <slip2>0</slip2>
              </ode>
              <torsional>
                <coefficient>1</coefficient>
                <patch_radius>0</patch_radius>
                <surface_radius>0</surface_radius>
                <use_patch_radius>1</use_patch_radius>
                <ode>
                  <slip>0</slip>
                </ode>
              </torsional>
            </friction>
            <contact>
              <ode/>
            </contact>
            <bounce/>
          </surface>
        </collision>
        <enable_wind>0</enable_wind>
      </link>
      <static>1</static>
      <pose>-1.8321 -6.3752 0 0 0 -1.56316</pose>
    </model>
    <model name='aws_robomaker_warehouse_ClutteringA_01_016'>
      <frame name='aws_robomaker_warehouse_ClutteringA_01::__model__' attached_to='aws_robomaker_warehouse_ClutteringA_01::link'>
        <pose relative_to='__model__'>0 0 0 0 -0 0</pose>
      </frame>
      <link name='aws_robomaker_warehouse_ClutteringA_01::link'>
        <inertial>
          <mass>2</mass>
          <inertia>
            <ixx>0.841</ixx>
            <ixy>0</ixy>
            <ixz>0</ixz>
            <iyy>0.954</iyy>
            <iyz>0</iyz>
            <izz>1.422</izz>
          </inertia>
        </inertial>
        <collision name='collision'>
          <geometry>
            <mesh>
              <uri>file://models/aws_robomaker_warehouse_ClutteringA_01/meshes/aws_robomaker_warehouse_ClutteringA_01_collision.DAE</uri>
              <scale>1 1 1</scale>
            </mesh>
          </geometry>
          <surface>
            <friction>
              <ode>
                <mu>0.6</mu>
                <mu2>0.6</mu2>
                <fdir1>0 0 0</fdir1>
                <slip1>0</slip1>
                <slip2>0</slip2>
              </ode>
              <torsional>
                <coefficient>1</coefficient>
                <patch_radius>0</patch_radius>
                <surface_radius>0</surface_radius>
                <use_patch_radius>1</use_patch_radius>
                <ode>
                  <slip>0</slip>
                </ode>
              </torsional>
            </friction>
            <contact>
              <ode/>
            </contact>
            <bounce/>
          </surface>
          <max_contacts>10</max_contacts>
        </collision>
        <visual name='visual'>
          <geometry>
            <mesh>
              <uri>file://models/aws_robomaker_warehouse_ClutteringA_01/meshes/aws_robomaker_warehouse_ClutteringA_01_visual.DAE</uri>
            </mesh>
          </geometry>
          <meta>
            <layer>1</layer>
          </meta>
        </visual>
        <pose relative_to='aws_robomaker_warehouse_ClutteringA_01::__model__'>0 0 0 0 -0 0</pose>
        <self_collide>0</self_collide>
        <enable_wind>0</enable_wind>
        <kinematic>0</kinematic>
      </link>
      <static>1</static>
      <pose>5.70814 8.61684 -0.017477 0 -0 0</pose>
    </model>
    <model name='aws_robomaker_warehouse_ClutteringA_01_017'>
      <frame name='aws_robomaker_warehouse_ClutteringA_01::__model__' attached_to='aws_robomaker_warehouse_ClutteringA_01::link'>
        <pose relative_to='__model__'>0 0 0 0 -0 0</pose>
      </frame>
      <link name='aws_robomaker_warehouse_ClutteringA_01::link'>
        <inertial>
          <mass>2</mass>
          <inertia>
            <ixx>0.841</ixx>
            <ixy>0</ixy>
            <ixz>0</ixz>
            <iyy>0.954</iyy>
            <iyz>0</iyz>
            <izz>1.422</izz>
          </inertia>
        </inertial>
        <collision name='collision'>
          <geometry>
            <mesh>
              <uri>file://models/aws_robomaker_warehouse_ClutteringA_01/meshes/aws_robomaker_warehouse_ClutteringA_01_collision.DAE</uri>
              <scale>1 1 1</scale>
            </mesh>
          </geometry>
          <surface>
            <friction>
              <ode>
                <mu>0.6</mu>
                <mu2>0.6</mu2>
                <fdir1>0 0 0</fdir1>
                <slip1>0</slip1>
                <slip2>0</slip2>
              </ode>
              <torsional>
                <coefficient>1</coefficient>
                <patch_radius>0</patch_radius>
                <surface_radius>0</surface_radius>
                <use_patch_radius>1</use_patch_radius>
                <ode>
                  <slip>0</slip>
                </ode>
              </torsional>
            </friction>
            <contact>
              <ode/>
            </contact>
            <bounce/>
          </surface>
          <max_contacts>10</max_contacts>
        </collision>
        <visual name='visual'>
          <geometry>
            <mesh>
              <uri>file://models/aws_robomaker_warehouse_ClutteringA_01/meshes/aws_robomaker_warehouse_ClutteringA_01_visual.DAE</uri>
            </mesh>
          </geometry>
          <meta>
            <layer>1</layer>
          </meta>
        </visual>
        <pose relative_to='aws_robomaker_warehouse_ClutteringA_01::__model__'>0 0 0 0 -0 0</pose>
        <self_collide>0</self_collide>
        <enable_wind>0</enable_wind>
        <kinematic>0</kinematic>
      </link>
      <static>1</static>
      <pose>3.40864 8.61684 -0.017477 0 -0 0</pose>
    </model>
    <model name='aws_robomaker_warehouse_ClutteringC_01_027'>
      <frame name='aws_robomaker_warehouse_ClutteringC_01::__model__' attached_to='aws_robomaker_warehouse_ClutteringC_01::link'>
        <pose relative_to='__model__'>0 0 0 0 -0 0</pose>
      </frame>
      <link name='aws_robomaker_warehouse_ClutteringC_01::link'>
        <inertial>
          <mass>1</mass>
          <inertia>
            <ixx>1.558</ixx>
            <ixy>0</ixy>
            <ixz>0</ixz>
            <iyy>1.821</iyy>
            <iyz>0</iyz>
            <izz>1.892</izz>
          </inertia>
        </inertial>
        <collision name='collision'>
          <geometry>
            <mesh>
              <uri>file://models/aws_robomaker_warehouse_ClutteringC_01/meshes/aws_robomaker_warehouse_ClutteringC_01_collision.DAE</uri>
              <scale>1 1 1</scale>
            </mesh>
          </geometry>
          <surface>
            <friction>
              <ode>
                <mu>0.6</mu>
                <mu2>0.6</mu2>
                <fdir1>0 0 0</fdir1>
                <slip1>0</slip1>
                <slip2>0</slip2>
              </ode>
              <torsional>
                <coefficient>1</coefficient>
                <patch_radius>0</patch_radius>
                <surface_radius>0</surface_radius>
                <use_patch_radius>1</use_patch_radius>
                <ode>
                  <slip>0</slip>
                </ode>
              </torsional>
            </friction>
            <contact>
              <ode/>
            </contact>
            <bounce/>
          </surface>
          <max_contacts>10</max_contacts>
        </collision>
        <visual name='visual'>
          <geometry>
            <mesh>
              <uri>file://models/aws_robomaker_warehouse_ClutteringC_01/meshes/aws_robomaker_warehouse_ClutteringC_01_visual.DAE</uri>
            </mesh>
          </geometry>
          <meta>
            <layer>1</layer>
          </meta>
        </visual>
        <pose relative_to='aws_robomaker_warehouse_ClutteringC_01::__model__'>0 0 0 0 -0 0</pose>
        <self_collide>0</self_collide>
        <enable_wind>0</enable_wind>
        <kinematic>0</kinematic>
      </link>
      <static>1</static>
      <pose>3.32496 3.82245 -0.012064 0 -0 1.56387</pose>
    </model>
    <model name='aws_robomaker_warehouse_ClutteringC_01_028'>
      <frame name='aws_robomaker_warehouse_ClutteringC_01::__model__' attached_to='aws_robomaker_warehouse_ClutteringC_01::link'>
        <pose relative_to='__model__'>0 0 0 0 -0 0</pose>
      </frame>
      <link name='aws_robomaker_warehouse_ClutteringC_01::link'>
        <inertial>
          <mass>1</mass>
          <inertia>
            <ixx>1.558</ixx>
            <ixy>0</ixy>
            <ixz>0</ixz>
            <iyy>1.821</iyy>
            <iyz>0</iyz>
            <izz>1.892</izz>
          </inertia>
        </inertial>
        <collision name='collision'>
          <geometry>
            <mesh>
              <uri>file://models/aws_robomaker_warehouse_ClutteringC_01/meshes/aws_robomaker_warehouse_ClutteringC_01_collision.DAE</uri>
              <scale>1 1 1</scale>
            </mesh>
          </geometry>
          <surface>
            <friction>
              <ode>
                <mu>0.6</mu>
                <mu2>0.6</mu2>
                <fdir1>0 0 0</fdir1>
                <slip1>0</slip1>
                <slip2>0</slip2>
              </ode>
              <torsional>
                <coefficient>1</coefficient>
                <patch_radius>0</patch_radius>
                <surface_radius>0</surface_radius>
                <use_patch_radius>1</use_patch_radius>
                <ode>
                  <slip>0</slip>
                </ode>
              </torsional>
            </friction>
            <contact>
              <ode/>
            </contact>
            <bounce/>
          </surface>
          <max_contacts>10</max_contacts>
        </collision>
        <visual name='visual'>
          <geometry>
            <mesh>
              <uri>file://models/aws_robomaker_warehouse_ClutteringC_01/meshes/aws_robomaker_warehouse_ClutteringC_01_visual.DAE</uri>
            </mesh>
          </geometry>
          <meta>
            <layer>1</layer>
          </meta>
        </visual>
        <pose relative_to='aws_robomaker_warehouse_ClutteringC_01::__model__'>0 0 0 0 -0 0</pose>
        <self_collide>0</self_collide>
        <enable_wind>0</enable_wind>
        <kinematic>0</kinematic>
      </link>
      <static>1</static>
      <pose>5.54171 3.81648 -0.015663 0 0 -1.58319</pose>
    </model>
    <model name='aws_robomaker_warehouse_ClutteringC_01_032'>
      <frame name='aws_robomaker_warehouse_ClutteringC_01::__model__' attached_to='aws_robomaker_warehouse_ClutteringC_01::link'>
        <pose relative_to='__model__'>0 0 0 0 -0 0</pose>
      </frame>
      <link name='aws_robomaker_warehouse_ClutteringC_01::link'>
        <inertial>
          <mass>1</mass>
          <inertia>
            <ixx>1.558</ixx>
            <ixy>0</ixy>
            <ixz>0</ixz>
            <iyy>1.821</iyy>
            <iyz>0</iyz>
            <izz>1.892</izz>
          </inertia>
        </inertial>
        <collision name='collision'>
          <geometry>
            <mesh>
              <uri>file://models/aws_robomaker_warehouse_ClutteringC_01/meshes/aws_robomaker_warehouse_ClutteringC_01_collision.DAE</uri>
              <scale>1 1 1</scale>
            </mesh>
          </geometry>
          <surface>
            <friction>
              <ode>
                <mu>0.6</mu>
                <mu2>0.6</mu2>
                <fdir1>0 0 0</fdir1>
                <slip1>0</slip1>
                <slip2>0</slip2>
              </ode>
              <torsional>
                <coefficient>1</coefficient>
                <patch_radius>0</patch_radius>
                <surface_radius>0</surface_radius>
                <use_patch_radius>1</use_patch_radius>
                <ode>
                  <slip>0</slip>
                </ode>
              </torsional>
            </friction>
            <contact>
              <ode/>
            </contact>
            <bounce/>
          </surface>
          <max_contacts>10</max_contacts>
        </collision>
        <visual name='visual'>
          <geometry>
            <mesh>
              <uri>file://models/aws_robomaker_warehouse_ClutteringC_01/meshes/aws_robomaker_warehouse_ClutteringC_01_visual.DAE</uri>
            </mesh>
          </geometry>
          <meta>
            <layer>1</layer>
          </meta>
        </visual>
        <pose relative_to='aws_robomaker_warehouse_ClutteringC_01::__model__'>0 0 0 0 -0 0</pose>
        <self_collide>0</self_collide>
        <enable_wind>0</enable_wind>
        <kinematic>0</kinematic>
      </link>
      <static>1</static>
      <pose>-1.2196 9.407 -0.015663 0 -0 1.56387</pose>
    </model>
    <model name='aws_robomaker_warehouse_ClutteringD_01_005'>
      <frame name='aws_robomaker_warehouse_ClutteringD_01::__model__' attached_to='aws_robomaker_warehouse_ClutteringD_01::link'>
        <pose relative_to='__model__'>0 0 0 0 -0 0</pose>
      </frame>
      <link name='aws_robomaker_warehouse_ClutteringD_01::link'>
        <inertial>
          <mass>1</mass>
          <inertia>
            <ixx>1.558</ixx>
            <ixy>0</ixy>
            <ixz>0</ixz>
            <iyy>1.821</iyy>
            <iyz>0</iyz>
            <izz>1.892</izz>
          </inertia>
        </inertial>
        <collision name='collision'>
          <geometry>
            <mesh>
              <uri>file://models/aws_robomaker_warehouse_ClutteringD_01/meshes/aws_robomaker_warehouse_ClutteringD_01_collision.DAE</uri>
              <scale>1 1 1</scale>
            </mesh>
          </geometry>
          <surface>
            <friction>
              <ode>
                <mu>0.6</mu>
                <mu2>0.6</mu2>
                <fdir1>0 0 0</fdir1>
                <slip1>0</slip1>
                <slip2>0</slip2>
              </ode>
              <torsional>
                <coefficient>1</coefficient>
                <patch_radius>0</patch_radius>
                <surface_radius>0</surface_radius>
                <use_patch_radius>1</use_patch_radius>
                <ode>
                  <slip>0</slip>
                </ode>
              </torsional>
            </friction>
            <contact>
              <ode/>
            </contact>
            <bounce/>
          </surface>
          <max_contacts>10</max_contacts>
        </collision>
        <visual name='visual'>
          <geometry>
            <mesh>
              <uri>file://models/aws_robomaker_warehouse_ClutteringD_01/meshes/aws_robomaker_warehouse_ClutteringD_01_visual.DAE</uri>
            </mesh>
          </geometry>
          <meta>
            <layer>1</layer>
          </meta>
        </visual>
        <pose relative_to='aws_robomaker_warehouse_ClutteringD_01::__model__'>0 0 0 0 -0 0</pose>
        <self_collide>0</self_collide>
        <enable_wind>0</enable_wind>
        <kinematic>0</kinematic>
      </link>
      <static>1</static>
      <pose>-1.63468 -7.81181 -0.319559 0 -0 0</pose>
    </model>
    <light name='Warehouse_CeilingLight_003' type='point'>
      <pose>0 0 9 0 -0 0</pose>
      <diffuse>0.5 0.5 0.5 1</diffuse>
      <specular>0.2 0.2 0.2 1</specular>
      <attenuation>
        <range>80</range>
        <constant>0.3</constant>
        <linear>0.01</linear>
        <quadratic>0.001</quadratic>
      </attenuation>
      <cast_shadows>1</cast_shadows>
      <direction>0.1 0.1 -1</direction>
      <spot>
        <inner_angle>0</inner_angle>
        <outer_angle>0</outer_angle>
        <falloff>0</falloff>
      </spot>
    </light>
    <gui fullscreen='0'>
      <camera name='user_camera'>
        <pose>-3.89046 -0.106011 16.0894 -0 1.2018 0.0343</pose>
        <view_controller>orbit</view_controller>
        <projection_type>perspective</projection_type>
      </camera>
    </gui>
    <magnetic_field>6e-06 2.3e-05 -4.2e-05</magnetic_field>
    <atmosphere type='adiabatic'/>
    <scene>
      <ambient>0.4 0.4 0.4 1</ambient>
      <background>0.7 0.7 0.7 1</background>
      <shadows>1</shadows>
    </scene>
    <audio>
      <device>default</device>
    </audio>
    <wind/>
    <spherical_coordinates>
      <surface_model>EARTH_WGS84</surface_model>
      <latitude_deg>0</latitude_deg>
      <longitude_deg>0</longitude_deg>
      <elevation>0</elevation>
      <heading_deg>0</heading_deg>
    </spherical_coordinates>
    <model name='mir_robot'>
      <link name='base_footprint'>
        <inertial>
          <pose>-0.009572 1.7e-05 0.152334 0 -0 0</pose>
          <mass>70.96</mass>
          <inertia>
            <ixx>0.973179</ixx>
            <ixy>-0.369183</ixy>
            <ixz>-0.00771231</ixz>
            <iyy>2.26736</iyy>
            <iyz>-4.68795e-05</iyz>
            <izz>2.75838</izz>
          </inertia>
        </inertial>
        <collision name='base_footprint_fixed_joint_lump__base_link_collision'>
          <pose>0.037646 0 0 0 -0 0</pose>
          <geometry>
            <mesh>
              <scale>1 1 1</scale>
              <uri>model://mir_description/meshes/collision/mir_100_base.stl</uri>
            </mesh>
          </geometry>
          <surface>
            <contact>
              <ode/>
            </contact>
            <friction>
              <ode/>
              <torsional>
                <ode/>
              </torsional>
            </friction>
            <bounce/>
          </surface>
          <max_contacts>10</max_contacts>
        </collision>
        <collision name='base_footprint_fixed_joint_lump__back_laser_link_collision_1'>
          <pose>-0.3548 -0.2352 0.1914 3.14159 -0 -2.35619</pose>
          <geometry>
            <mesh>
              <scale>1 1 1</scale>
              <uri>model://mir_description/meshes/visual/sick_lms-100.stl</uri>
            </mesh>
          </geometry>
          <surface>
            <contact>
              <ode/>
            </contact>
            <friction>
              <ode/>
              <torsional>
                <ode/>
              </torsional>
            </friction>
            <bounce/>
          </surface>
          <max_contacts>10</max_contacts>
        </collision>
        <collision name='base_footprint_fixed_joint_lump__front_laser_link_collision_2'>
          <pose>0.4288 0.2358 0.1914 3.14159 -0 0.785398</pose>
          <geometry>
            <mesh>
              <scale>1 1 1</scale>
              <uri>model://mir_description/meshes/visual/sick_lms-100.stl</uri>
            </mesh>
          </geometry>
          <surface>
            <contact>
              <ode/>
            </contact>
            <friction>
              <ode/>
              <torsional>
                <ode/>
              </torsional>
            </friction>
            <bounce/>
          </surface>
          <max_contacts>10</max_contacts>
        </collision>
        <visual name='base_footprint_fixed_joint_lump__base_link_visual'>
          <pose>0.037646 0 0 0 -0 0</pose>
          <geometry>
            <mesh>
              <scale>1 1 1</scale>
              <uri>model://mir_description/meshes/visual/mir_100_base.stl</uri>
            </mesh>
          </geometry>
          <material>
            <script>
              <name>Gazebo/White</name>
              <uri>file://media/materials/scripts/gazebo.material</uri>
            </script>
          </material>
        </visual>
        <visual name='base_footprint_fixed_joint_lump__back_laser_link_visual_1'>
          <pose>-0.3548 -0.2352 0.1914 3.14159 -0 -2.35619</pose>
          <geometry>
            <mesh>
              <scale>1 1 1</scale>
              <uri>model://mir_description/meshes/visual/sick_lms-100.stl</uri>
            </mesh>
          </geometry>
          <material>
            <script>
              <name>Gazebo/FlatBlack</name>
              <uri>file://media/materials/scripts/gazebo.material</uri>
            </script>
          </material>
        </visual>
        <visual name='base_footprint_fixed_joint_lump__camera_link_visual_2'>
          <pose>0.465 0 0.28 0 -0 0</pose>
          <geometry>
            <box>
              <size>0.01 0.13 0.03</size>
            </box>
          </geometry>
          <material>
            <script>
              <name>Gazebo/Red</name>
              <uri>file://media/materials/scripts/gazebo.material</uri>
            </script>
          </material>
        </visual>
        <visual name='base_footprint_fixed_joint_lump__front_laser_link_visual_3'>
          <pose>0.4288 0.2358 0.1914 3.14159 -0 0.785398</pose>
          <geometry>
            <mesh>
              <scale>1 1 1</scale>
              <uri>model://mir_description/meshes/visual/sick_lms-100.stl</uri>
            </mesh>
          </geometry>
          <material>
            <script>
              <name>Gazebo/FlatBlack</name>
              <uri>file://media/materials/scripts/gazebo.material</uri>
            </script>
          </material>
        </visual>
        <sensor name='back_laser_link' type='ray'>
          <visualize>0</visualize>
          <update_rate>12.5</update_rate>
          <ray>
            <scan>
              <horizontal>
                <samples>541</samples>
                <resolution>1</resolution>
                <min_angle>-2.35619</min_angle>
                <max_angle>2.35619</max_angle>
              </horizontal>
              <vertical>
                <samples>1</samples>
                <min_angle>0</min_angle>
                <max_angle>0</max_angle>
              </vertical>
            </scan>
            <range>
              <min>0.05</min>
              <max>29</max>
              <resolution>0.01</resolution>
            </range>
            <noise>
              <type>gaussian</type>
              <mean>0</mean>
              <stddev>0.01</stddev>
            </noise>
          </ray>
          <plugin name='gazebo_ros_back_laser_link_controller' filename='libgazebo_ros_ray_sensor.so'>
            <ros>
              <remapping>~/out:=b_scan</remapping>
            </ros>
            <output_type>sensor_msgs/LaserScan</output_type>
            <frame_name>back_laser_link</frame_name>
          </plugin>
          <pose>-0.3548 -0.2352 0.1914 0 0 -2.35619</pose>
        </sensor>
        <sensor name='depth_camera' type='depth'>
          <visualize>1</visualize>
          <update_rate>10</update_rate>
          <plugin name='depth_camera_controller' filename='libgazebo_ros_camera.so'>
            <always_on>1</always_on>
            <update_rate>10.0</update_rate>
            <camera_name>depth_camera</camera_name>
            <frame_name>camera_link_optical</frame_name>
            <topic_name>camera/depth/image_raw</topic_name>
          </plugin>
          <plugin name='point_cloud_plugin' filename='libgazebo_ros_point_cloud.so'>
            <always_on>1</always_on>
            <update_rate>10.0</update_rate>
            <frame_name>camera_link_optical</frame_name>
            <topic_name>camera/depth/points</topic_name>
          </plugin>
          <pose>0.465 0 0.28 0 -0 0</pose>
          <camera>
            <horizontal_fov>1.047</horizontal_fov>
            <image>
              <width>320</width>
              <height>240</height>
            </image>
            <clip>
              <near>0.1</near>
              <far>100</far>
            </clip>
          </camera>
          <depth_camera>
            <horizontal_fov>1.089</horizontal_fov>
            <image>
              <format>FLOAT32</format>
              <width>640</width>
              <height>480</height>
            </image>
            <clip>
              <near>0.05</near>
              <far>8.0</far>
            </clip>
          </depth_camera>
        </sensor>
        <sensor name='front_laser_link' type='ray'>
          <visualize>0</visualize>
          <update_rate>12.5</update_rate>
          <ray>
            <scan>
              <horizontal>
                <samples>541</samples>
                <resolution>1</resolution>
                <min_angle>-2.35619</min_angle>
                <max_angle>2.35619</max_angle>
              </horizontal>
              <vertical>
                <samples>1</samples>
                <min_angle>0</min_angle>
                <max_angle>0</max_angle>
              </vertical>
            </scan>
            <range>
              <min>0.05</min>
              <max>29</max>
              <resolution>0.01</resolution>
            </range>
            <noise>
              <type>gaussian</type>
              <mean>0</mean>
              <stddev>0.01</stddev>
            </noise>
          </ray>
          <plugin name='gazebo_ros_front_laser_link_controller' filename='libgazebo_ros_ray_sensor.so'>
            <ros>
              <remapping>~/out:=f_scan</remapping>
            </ros>
            <output_type>sensor_msgs/LaserScan</output_type>
            <frame_name>front_laser_link</frame_name>
          </plugin>
          <pose>0.4288 0.2358 0.1914 0 -0 0.785398</pose>
        </sensor>
        <gravity>1</gravity>
        <sensor name='imu_sensor' type='imu'>
          <always_on>1</always_on>
          <update_rate>50</update_rate>
          <visualize>1</visualize>
          <imu>
            <angular_velocity>
              <x>
                <noise type='gaussian'>
                  <mean>0</mean>
                  <stddev>0.00017</stddev>
                  <bias_mean>7.5e-06</bias_mean>
                  <bias_stddev>8e-07</bias_stddev>
                </noise>
              </x>
              <y>
                <noise type='gaussian'>
                  <mean>0</mean>
                  <stddev>0.00017</stddev>
                  <bias_mean>7.5e-06</bias_mean>
                  <bias_stddev>8e-07</bias_stddev>
                </noise>
              </y>
              <z>
                <noise type='gaussian'>
                  <mean>0</mean>
                  <stddev>0.00017</stddev>
                  <bias_mean>7.5e-06</bias_mean>
                  <bias_stddev>8e-07</bias_stddev>
                </noise>
              </z>
            </angular_velocity>
            <linear_acceleration>
              <x>
                <noise type='gaussian'>
                  <mean>0</mean>
                  <stddev>0.00017</stddev>
                  <bias_mean>0.1</bias_mean>
                  <bias_stddev>0.001</bias_stddev>
                </noise>
              </x>
              <y>
                <noise type='gaussian'>
                  <mean>0</mean>
                  <stddev>0.00017</stddev>
                  <bias_mean>0.1</bias_mean>
                  <bias_stddev>0.001</bias_stddev>
                </noise>
              </y>
              <z>
                <noise type='gaussian'>
                  <mean>0</mean>
                  <stddev>0.00017</stddev>
                  <bias_mean>0.1</bias_mean>
                  <bias_stddev>0.001</bias_stddev>
                </noise>
              </z>
            </linear_acceleration>
          </imu>
          <plugin name='imu_plugin' filename='libgazebo_ros_imu_sensor.so'>
            <initial_orientation_as_reference>0</initial_orientation_as_reference>
            <ros>
              <namespace>imu_data</namespace>
              <remapping>~/out:=data</remapping>
              <frame_name>imu_frame</frame_name>
            </ros>
          </plugin>
          <pose>0 0 0.25 0 -0 0</pose>
        </sensor>
        <self_collide>0</self_collide>
        <enable_wind>0</enable_wind>
        <kinematic>0</kinematic>
      </link>
      <joint name='bl_caster_rotation_joint' type='revolute'>
        <pose relative_to='base_footprint'>-0.270154 0.203 0.1565 0 -0 0</pose>
        <parent>base_footprint</parent>
        <child>bl_caster_rotation_link</child>
        <axis>
          <xyz>0 0 1</xyz>
          <limit>
            <lower>-1e+16</lower>
            <upper>1e+16</upper>
          </limit>
          <dynamics>
            <damping>0</damping>
            <friction>0.5</friction>
            <spring_reference>0</spring_reference>
            <spring_stiffness>0</spring_stiffness>
          </dynamics>
        </axis>
      </joint>
      <link name='bl_caster_rotation_link'>
        <pose relative_to='bl_caster_rotation_joint'>0 0 0 0 -0 0</pose>
        <inertial>
          <pose>0 0 -0.0425 0.418879 0 1.5708</pose>
          <mass>0.309754</mass>
          <inertia>
            <ixx>0.000584452</ixx>
            <ixy>0</ixy>
            <ixz>0</ixz>
            <iyy>0.000528726</iyy>
            <iyz>0</iyz>
            <izz>0.000179236</izz>
          </inertia>
        </inertial>
        <collision name='bl_caster_rotation_link_collision'>
          <pose>0 0 0 0 -0 0</pose>
          <geometry>
            <mesh>
              <scale>1 1 1</scale>
              <uri>model://mir_description/meshes/collision/caster_wheel_base.stl</uri>
            </mesh>
          </geometry>
          <surface>
            <contact>
              <ode/>
            </contact>
            <friction>
              <ode/>
              <torsional>
                <ode/>
              </torsional>
            </friction>
            <bounce/>
          </surface>
          <max_contacts>10</max_contacts>
        </collision>
        <visual name='bl_caster_rotation_link_visual'>
          <pose>0 0 0 0 -0 0</pose>
          <geometry>
            <mesh>
              <scale>1 1 1</scale>
              <uri>model://mir_description/meshes/visual/caster_wheel_base.stl</uri>
            </mesh>
          </geometry>
          <material>
            <script>
              <name>Gazebo/Grey</name>
              <uri>file://media/materials/scripts/gazebo.material</uri>
            </script>
          </material>
        </visual>
        <self_collide>0</self_collide>
        <enable_wind>0</enable_wind>
        <kinematic>0</kinematic>
      </link>
      <joint name='bl_caster_wheel_joint' type='revolute'>
        <pose relative_to='bl_caster_rotation_link'>-0.0382 0 -0.094 0 -0 0</pose>
        <parent>bl_caster_rotation_link</parent>
        <child>bl_caster_wheel_link</child>
        <axis>
          <xyz>0 1 0</xyz>
          <limit>
            <lower>-1e+16</lower>
            <upper>1e+16</upper>
          </limit>
          <dynamics>
            <spring_reference>0</spring_reference>
            <spring_stiffness>0</spring_stiffness>
          </dynamics>
        </axis>
      </joint>
      <link name='bl_caster_wheel_link'>
        <pose relative_to='bl_caster_wheel_joint'>0 0 0 0 -0 0</pose>
        <inertial>
          <pose>0 0 0 1.5708 -0 0</pose>
          <mass>1</mass>
          <inertia>
            <ixx>0.0010619</ixx>
            <ixy>0</ixy>
            <ixz>0</ixz>
            <iyy>0.0010619</iyy>
            <iyz>0</iyz>
            <izz>0.00195312</izz>
          </inertia>
        </inertial>
        <collision name='bl_caster_wheel_link_collision'>
          <pose>0 0 0 1.5708 -0 0</pose>
          <geometry>
            <cylinder>
              <length>0.032</length>
              <radius>0.0625</radius>
            </cylinder>
          </geometry>
          <surface>
            <friction>
              <ode>
                <mu>1</mu>
                <mu2>1</mu2>
                <fdir1>0 0 1</fdir1>
                <slip1>0</slip1>
                <slip2>0.5</slip2>
              </ode>
              <torsional>
                <ode/>
              </torsional>
            </friction>
            <contact>
              <ode>
                <kp>1e+08</kp>
                <min_depth>0</min_depth>
              </ode>
            </contact>
            <bounce/>
          </surface>
          <max_contacts>10</max_contacts>
        </collision>
        <visual name='bl_caster_wheel_link_visual'>
          <pose>0 0 0 0 -0 0</pose>
          <geometry>
            <mesh>
              <scale>1 1 1</scale>
              <uri>model://mir_description/meshes/visual/wheel.stl</uri>
            </mesh>
          </geometry>
          <material>
            <script>
              <name>Gazebo/DarkGrey</name>
              <uri>file://media/materials/scripts/gazebo.material</uri>
            </script>
          </material>
        </visual>
        <self_collide>0</self_collide>
        <enable_wind>0</enable_wind>
        <kinematic>0</kinematic>
      </link>
      <joint name='br_caster_rotation_joint' type='revolute'>
        <pose relative_to='base_footprint'>-0.270154 -0.203 0.1565 0 -0 0</pose>
        <parent>base_footprint</parent>
        <child>br_caster_rotation_link</child>
        <axis>
          <xyz>0 0 1</xyz>
          <limit>
            <lower>-1e+16</lower>
            <upper>1e+16</upper>
          </limit>
          <dynamics>
            <damping>0</damping>
            <friction>0.5</friction>
            <spring_reference>0</spring_reference>
            <spring_stiffness>0</spring_stiffness>
          </dynamics>
        </axis>
      </joint>
      <link name='br_caster_rotation_link'>
        <pose relative_to='br_caster_rotation_joint'>0 0 0 0 -0 0</pose>
        <inertial>
          <pose>0 0 -0.0425 0.418879 0 1.5708</pose>
          <mass>0.309754</mass>
          <inertia>
            <ixx>0.000584452</ixx>
            <ixy>0</ixy>
            <ixz>0</ixz>
            <iyy>0.000528726</iyy>
            <iyz>0</iyz>
            <izz>0.000179236</izz>
          </inertia>
        </inertial>
        <collision name='br_caster_rotation_link_collision'>
          <pose>0 0 0 0 -0 0</pose>
          <geometry>
            <mesh>
              <scale>1 1 1</scale>
              <uri>model://mir_description/meshes/collision/caster_wheel_base.stl</uri>
            </mesh>
          </geometry>
          <surface>
            <contact>
              <ode/>
            </contact>
            <friction>
              <ode/>
              <torsional>
                <ode/>
              </torsional>
            </friction>
            <bounce/>
          </surface>
          <max_contacts>10</max_contacts>
        </collision>
        <visual name='br_caster_rotation_link_visual'>
          <pose>0 0 0 0 -0 0</pose>
          <geometry>
            <mesh>
              <scale>1 1 1</scale>
              <uri>model://mir_description/meshes/visual/caster_wheel_base.stl</uri>
            </mesh>
          </geometry>
          <material>
            <script>
              <name>Gazebo/Grey</name>
              <uri>file://media/materials/scripts/gazebo.material</uri>
            </script>
          </material>
        </visual>
        <self_collide>0</self_collide>
        <enable_wind>0</enable_wind>
        <kinematic>0</kinematic>
      </link>
      <joint name='br_caster_wheel_joint' type='revolute'>
        <pose relative_to='br_caster_rotation_link'>-0.0382 0 -0.094 0 -0 0</pose>
        <parent>br_caster_rotation_link</parent>
        <child>br_caster_wheel_link</child>
        <axis>
          <xyz>0 1 0</xyz>
          <limit>
            <lower>-1e+16</lower>
            <upper>1e+16</upper>
          </limit>
          <dynamics>
            <spring_reference>0</spring_reference>
            <spring_stiffness>0</spring_stiffness>
          </dynamics>
        </axis>
      </joint>
      <link name='br_caster_wheel_link'>
        <pose relative_to='br_caster_wheel_joint'>0 0 0 0 -0 0</pose>
        <inertial>
          <pose>0 0 0 1.5708 -0 0</pose>
          <mass>1</mass>
          <inertia>
            <ixx>0.0010619</ixx>
            <ixy>0</ixy>
            <ixz>0</ixz>
            <iyy>0.0010619</iyy>
            <iyz>0</iyz>
            <izz>0.00195312</izz>
          </inertia>
        </inertial>
        <collision name='br_caster_wheel_link_collision'>
          <pose>0 0 0 1.5708 -0 0</pose>
          <geometry>
            <cylinder>
              <length>0.032</length>
              <radius>0.0625</radius>
            </cylinder>
          </geometry>
          <surface>
            <friction>
              <ode>
                <mu>1</mu>
                <mu2>1</mu2>
                <fdir1>0 0 1</fdir1>
                <slip1>0</slip1>
                <slip2>0.5</slip2>
              </ode>
              <torsional>
                <ode/>
              </torsional>
            </friction>
            <contact>
              <ode>
                <kp>1e+08</kp>
                <min_depth>0</min_depth>
              </ode>
            </contact>
            <bounce/>
          </surface>
          <max_contacts>10</max_contacts>
        </collision>
        <visual name='br_caster_wheel_link_visual'>
          <pose>0 0 0 0 -0 0</pose>
          <geometry>
            <mesh>
              <scale>1 1 1</scale>
              <uri>model://mir_description/meshes/visual/wheel.stl</uri>
            </mesh>
          </geometry>
          <material>
            <script>
              <name>Gazebo/DarkGrey</name>
              <uri>file://media/materials/scripts/gazebo.material</uri>
            </script>
          </material>
        </visual>
        <self_collide>0</self_collide>
        <enable_wind>0</enable_wind>
        <kinematic>0</kinematic>
      </link>
      <joint name='fl_caster_rotation_joint' type='revolute'>
        <pose relative_to='base_footprint'>0.341346 0.203 0.1565 0 -0 0</pose>
        <parent>base_footprint</parent>
        <child>fl_caster_rotation_link</child>
        <axis>
          <xyz>0 0 1</xyz>
          <limit>
            <lower>-1e+16</lower>
            <upper>1e+16</upper>
          </limit>
          <dynamics>
            <damping>0</damping>
            <friction>0.5</friction>
            <spring_reference>0</spring_reference>
            <spring_stiffness>0</spring_stiffness>
          </dynamics>
        </axis>
      </joint>
      <link name='fl_caster_rotation_link'>
        <pose relative_to='fl_caster_rotation_joint'>0 0 0 0 -0 0</pose>
        <inertial>
          <pose>0 0 -0.0425 0.418879 0 1.5708</pose>
          <mass>0.309754</mass>
          <inertia>
            <ixx>0.000584452</ixx>
            <ixy>0</ixy>
            <ixz>0</ixz>
            <iyy>0.000528726</iyy>
            <iyz>0</iyz>
            <izz>0.000179236</izz>
          </inertia>
        </inertial>
        <collision name='fl_caster_rotation_link_collision'>
          <pose>0 0 0 0 -0 0</pose>
          <geometry>
            <mesh>
              <scale>1 1 1</scale>
              <uri>model://mir_description/meshes/collision/caster_wheel_base.stl</uri>
            </mesh>
          </geometry>
          <surface>
            <contact>
              <ode/>
            </contact>
            <friction>
              <ode/>
              <torsional>
                <ode/>
              </torsional>
            </friction>
            <bounce/>
          </surface>
          <max_contacts>10</max_contacts>
        </collision>
        <visual name='fl_caster_rotation_link_visual'>
          <pose>0 0 0 0 -0 0</pose>
          <geometry>
            <mesh>
              <scale>1 1 1</scale>
              <uri>model://mir_description/meshes/visual/caster_wheel_base.stl</uri>
            </mesh>
          </geometry>
          <material>
            <script>
              <name>Gazebo/Grey</name>
              <uri>file://media/materials/scripts/gazebo.material</uri>
            </script>
          </material>
        </visual>
        <self_collide>0</self_collide>
        <enable_wind>0</enable_wind>
        <kinematic>0</kinematic>
      </link>
      <joint name='fl_caster_wheel_joint' type='revolute'>
        <pose relative_to='fl_caster_rotation_link'>-0.0382 0 -0.094 0 -0 0</pose>
        <parent>fl_caster_rotation_link</parent>
        <child>fl_caster_wheel_link</child>
        <axis>
          <xyz>0 1 0</xyz>
          <limit>
            <lower>-1e+16</lower>
            <upper>1e+16</upper>
          </limit>
          <dynamics>
            <spring_reference>0</spring_reference>
            <spring_stiffness>0</spring_stiffness>
          </dynamics>
        </axis>
      </joint>
      <link name='fl_caster_wheel_link'>
        <pose relative_to='fl_caster_wheel_joint'>0 0 0 0 -0 0</pose>
        <inertial>
          <pose>0 0 0 1.5708 -0 0</pose>
          <mass>1</mass>
          <inertia>
            <ixx>0.0010619</ixx>
            <ixy>0</ixy>
            <ixz>0</ixz>
            <iyy>0.0010619</iyy>
            <iyz>0</iyz>
            <izz>0.00195312</izz>
          </inertia>
        </inertial>
        <collision name='fl_caster_wheel_link_collision'>
          <pose>0 0 0 1.5708 -0 0</pose>
          <geometry>
            <cylinder>
              <length>0.032</length>
              <radius>0.0625</radius>
            </cylinder>
          </geometry>
          <surface>
            <friction>
              <ode>
                <mu>1</mu>
                <mu2>1</mu2>
                <fdir1>0 0 1</fdir1>
                <slip1>0</slip1>
                <slip2>0.5</slip2>
              </ode>
              <torsional>
                <ode/>
              </torsional>
            </friction>
            <contact>
              <ode>
                <kp>1e+08</kp>
                <min_depth>0</min_depth>
              </ode>
            </contact>
            <bounce/>
          </surface>
          <max_contacts>10</max_contacts>
        </collision>
        <visual name='fl_caster_wheel_link_visual'>
          <pose>0 0 0 0 -0 0</pose>
          <geometry>
            <mesh>
              <scale>1 1 1</scale>
              <uri>model://mir_description/meshes/visual/wheel.stl</uri>
            </mesh>
          </geometry>
          <material>
            <script>
              <name>Gazebo/DarkGrey</name>
              <uri>file://media/materials/scripts/gazebo.material</uri>
            </script>
          </material>
        </visual>
        <self_collide>0</self_collide>
        <enable_wind>0</enable_wind>
        <kinematic>0</kinematic>
      </link>
      <joint name='fr_caster_rotation_joint' type='revolute'>
        <pose relative_to='base_footprint'>0.341346 -0.203 0.1565 0 -0 0</pose>
        <parent>base_footprint</parent>
        <child>fr_caster_rotation_link</child>
        <axis>
          <xyz>0 0 1</xyz>
          <limit>
            <lower>-1e+16</lower>
            <upper>1e+16</upper>
          </limit>
          <dynamics>
            <damping>0</damping>
            <friction>0.5</friction>
            <spring_reference>0</spring_reference>
            <spring_stiffness>0</spring_stiffness>
          </dynamics>
        </axis>
      </joint>
      <link name='fr_caster_rotation_link'>
        <pose relative_to='fr_caster_rotation_joint'>0 0 0 0 -0 0</pose>
        <inertial>
          <pose>0 0 -0.0425 0.418879 0 1.5708</pose>
          <mass>0.309754</mass>
          <inertia>
            <ixx>0.000584452</ixx>
            <ixy>0</ixy>
            <ixz>0</ixz>
            <iyy>0.000528726</iyy>
            <iyz>0</iyz>
            <izz>0.000179236</izz>
          </inertia>
        </inertial>
        <collision name='fr_caster_rotation_link_collision'>
          <pose>0 0 0 0 -0 0</pose>
          <geometry>
            <mesh>
              <scale>1 1 1</scale>
              <uri>model://mir_description/meshes/collision/caster_wheel_base.stl</uri>
            </mesh>
          </geometry>
          <surface>
            <contact>
              <ode/>
            </contact>
            <friction>
              <ode/>
              <torsional>
                <ode/>
              </torsional>
            </friction>
            <bounce/>
          </surface>
          <max_contacts>10</max_contacts>
        </collision>
        <visual name='fr_caster_rotation_link_visual'>
          <pose>0 0 0 0 -0 0</pose>
          <geometry>
            <mesh>
              <scale>1 1 1</scale>
              <uri>model://mir_description/meshes/visual/caster_wheel_base.stl</uri>
            </mesh>
          </geometry>
          <material>
            <script>
              <name>Gazebo/Grey</name>
              <uri>file://media/materials/scripts/gazebo.material</uri>
            </script>
          </material>
        </visual>
        <self_collide>0</self_collide>
        <enable_wind>0</enable_wind>
        <kinematic>0</kinematic>
      </link>
      <joint name='fr_caster_wheel_joint' type='revolute'>
        <pose relative_to='fr_caster_rotation_link'>-0.0382 0 -0.094 0 -0 0</pose>
        <parent>fr_caster_rotation_link</parent>
        <child>fr_caster_wheel_link</child>
        <axis>
          <xyz>0 1 0</xyz>
          <limit>
            <lower>-1e+16</lower>
            <upper>1e+16</upper>
          </limit>
          <dynamics>
            <spring_reference>0</spring_reference>
            <spring_stiffness>0</spring_stiffness>
          </dynamics>
        </axis>
      </joint>
      <link name='fr_caster_wheel_link'>
        <pose relative_to='fr_caster_wheel_joint'>0 0 0 0 -0 0</pose>
        <inertial>
          <pose>0 0 0 1.5708 -0 0</pose>
          <mass>1</mass>
          <inertia>
            <ixx>0.0010619</ixx>
            <ixy>0</ixy>
            <ixz>0</ixz>
            <iyy>0.0010619</iyy>
            <iyz>0</iyz>
            <izz>0.00195312</izz>
          </inertia>
        </inertial>
        <collision name='fr_caster_wheel_link_collision'>
          <pose>0 0 0 1.5708 -0 0</pose>
          <geometry>
            <cylinder>
              <length>0.032</length>
              <radius>0.0625</radius>
            </cylinder>
          </geometry>
          <surface>
            <friction>
              <ode>
                <mu>1</mu>
                <mu2>1</mu2>
                <fdir1>0 0 1</fdir1>
                <slip1>0</slip1>
                <slip2>0.5</slip2>
              </ode>
              <torsional>
                <ode/>
              </torsional>
            </friction>
            <contact>
              <ode>
                <kp>1e+08</kp>
                <min_depth>0</min_depth>
              </ode>
            </contact>
            <bounce/>
          </surface>
          <max_contacts>10</max_contacts>
        </collision>
        <visual name='fr_caster_wheel_link_visual'>
          <pose>0 0 0 0 -0 0</pose>
          <geometry>
            <mesh>
              <scale>1 1 1</scale>
              <uri>model://mir_description/meshes/visual/wheel.stl</uri>
            </mesh>
          </geometry>
          <material>
            <script>
              <name>Gazebo/DarkGrey</name>
              <uri>file://media/materials/scripts/gazebo.material</uri>
            </script>
          </material>
        </visual>
        <self_collide>0</self_collide>
        <enable_wind>0</enable_wind>
        <kinematic>0</kinematic>
      </link>
      <joint name='left_wheel_joint' type='revolute'>
        <pose relative_to='base_footprint'>0 0.222604 0.0625 0 -0 0</pose>
        <parent>base_footprint</parent>
        <child>left_wheel_link</child>
        <axis>
          <xyz>0 1 0</xyz>
          <limit>
            <effort>100</effort>
            <velocity>20</velocity>
            <lower>-1e+16</lower>
            <upper>1e+16</upper>
          </limit>
          <dynamics>
            <spring_reference>0</spring_reference>
            <spring_stiffness>0</spring_stiffness>
          </dynamics>
        </axis>
      </joint>
      <link name='left_wheel_link'>
        <pose relative_to='left_wheel_joint'>0 0 0 0 -0 0</pose>
        <inertial>
          <pose>0 0 0 1.5708 -0 0</pose>
          <mass>1</mass>
          <inertia>
            <ixx>0.0010619</ixx>
            <ixy>0</ixy>
            <ixz>0</ixz>
            <iyy>0.0010619</iyy>
            <iyz>0</iyz>
            <izz>0.00195312</izz>
          </inertia>
        </inertial>
        <collision name='left_wheel_link_collision'>
          <pose>0 0 0 1.5708 -0 0</pose>
          <geometry>
            <cylinder>
              <length>0.032</length>
              <radius>0.0625</radius>
            </cylinder>
          </geometry>
          <surface>
            <friction>
              <ode>
                <mu>300</mu>
                <mu2>300</mu2>
                <fdir1>0 0 1</fdir1>
              </ode>
              <torsional>
                <coefficient>300</coefficient>
                <use_patch_radius>0</use_patch_radius>
                <surface_radius>0.0625</surface_radius>
                <ode/>
              </torsional>
            </friction>
            <contact>
              <ode>
                <min_depth>0.001</min_depth>
              </ode>
            </contact>
            <bounce/>
          </surface>
          <max_contacts>10</max_contacts>
        </collision>
        <visual name='left_wheel_link_visual'>
          <pose>0 0 0 0 -0 0</pose>
          <geometry>
            <mesh>
              <scale>1 1 1</scale>
              <uri>model://mir_description/meshes/visual/wheel.stl</uri>
            </mesh>
          </geometry>
          <material>
            <script>
              <name>Gazebo/DarkGrey</name>
              <uri>file://media/materials/scripts/gazebo.material</uri>
            </script>
          </material>
        </visual>
        <self_collide>0</self_collide>
        <enable_wind>0</enable_wind>
        <kinematic>0</kinematic>
      </link>
      <joint name='right_wheel_joint' type='revolute'>
        <pose relative_to='base_footprint'>0 -0.222604 0.0625 0 -0 0</pose>
        <parent>base_footprint</parent>
        <child>right_wheel_link</child>
        <axis>
          <xyz>0 1 0</xyz>
          <limit>
            <effort>100</effort>
            <velocity>20</velocity>
            <lower>-1e+16</lower>
            <upper>1e+16</upper>
          </limit>
          <dynamics>
            <spring_reference>0</spring_reference>
            <spring_stiffness>0</spring_stiffness>
          </dynamics>
        </axis>
      </joint>
      <link name='right_wheel_link'>
        <pose relative_to='right_wheel_joint'>0 0 0 0 -0 0</pose>
        <inertial>
          <pose>0 0 0 1.5708 -0 0</pose>
          <mass>1</mass>
          <inertia>
            <ixx>0.0010619</ixx>
            <ixy>0</ixy>
            <ixz>0</ixz>
            <iyy>0.0010619</iyy>
            <iyz>0</iyz>
            <izz>0.00195312</izz>
          </inertia>
        </inertial>
        <collision name='right_wheel_link_collision'>
          <pose>0 0 0 1.5708 -0 0</pose>
          <geometry>
            <cylinder>
              <length>0.032</length>
              <radius>0.0625</radius>
            </cylinder>
          </geometry>
          <surface>
            <friction>
              <ode>
                <mu>300</mu>
                <mu2>300</mu2>
                <fdir1>0 0 1</fdir1>
              </ode>
              <torsional>
                <coefficient>300</coefficient>
                <use_patch_radius>0</use_patch_radius>
                <surface_radius>0.0625</surface_radius>
                <ode/>
              </torsional>
            </friction>
            <contact>
              <ode>
                <min_depth>0.001</min_depth>
              </ode>
            </contact>
            <bounce/>
          </surface>
          <max_contacts>10</max_contacts>
        </collision>
        <visual name='right_wheel_link_visual'>
          <pose>0 0 0 0 -0 0</pose>
          <geometry>
            <mesh>
              <scale>1 1 1</scale>
              <uri>model://mir_description/meshes/visual/wheel.stl</uri>
            </mesh>
          </geometry>
          <material>
            <script>
              <name>Gazebo/DarkGrey</name>
              <uri>file://media/materials/scripts/gazebo.material</uri>
            </script>
          </material>
        </visual>
        <self_collide>0</self_collide>
        <enable_wind>0</enable_wind>
        <kinematic>0</kinematic>
      </link>
      <plugin name='fl_caster_rotation_joint_states' filename='libgazebo_ros_joint_state_publisher.so'>
        <ros>
          <namespace/>
        </ros>
        <update_rate>200.0</update_rate>
        <joint_name>fl_caster_rotation_joint</joint_name>
      </plugin>
      <plugin name='fl_caster_wheel_joint_states' filename='libgazebo_ros_joint_state_publisher.so'>
        <ros>
          <namespace/>
        </ros>
        <update_rate>200.0</update_rate>
        <joint_name>fl_caster_wheel_joint</joint_name>
      </plugin>
      <plugin name='fr_caster_rotation_joint_states' filename='libgazebo_ros_joint_state_publisher.so'>
        <ros>
          <namespace/>
        </ros>
        <update_rate>200.0</update_rate>
        <joint_name>fr_caster_rotation_joint</joint_name>
      </plugin>
      <plugin name='fr_caster_wheel_joint_states' filename='libgazebo_ros_joint_state_publisher.so'>
        <ros>
          <namespace/>
        </ros>
        <update_rate>200.0</update_rate>
        <joint_name>fr_caster_wheel_joint</joint_name>
      </plugin>
      <plugin name='bl_caster_rotation_joint_states' filename='libgazebo_ros_joint_state_publisher.so'>
        <ros>
          <namespace/>
        </ros>
        <update_rate>200.0</update_rate>
        <joint_name>bl_caster_rotation_joint</joint_name>
      </plugin>
      <plugin name='bl_caster_wheel_joint_states' filename='libgazebo_ros_joint_state_publisher.so'>
        <ros>
          <namespace/>
        </ros>
        <update_rate>200.0</update_rate>
        <joint_name>bl_caster_wheel_joint</joint_name>
      </plugin>
      <plugin name='br_caster_rotation_joint_states' filename='libgazebo_ros_joint_state_publisher.so'>
        <ros>
          <namespace/>
        </ros>
        <update_rate>200.0</update_rate>
        <joint_name>br_caster_rotation_joint</joint_name>
      </plugin>
      <plugin name='br_caster_wheel_joint_states' filename='libgazebo_ros_joint_state_publisher.so'>
        <ros>
          <namespace/>
        </ros>
        <update_rate>200.0</update_rate>
        <joint_name>br_caster_wheel_joint</joint_name>
      </plugin>
      <plugin name='p3d_base_controller' filename='libgazebo_ros_p3d.so'>
        <ros>
          <remapping>odom:=base_pose_ground_truth</remapping>
        </ros>
        <always_on>1</always_on>
        <update_rate>50.0</update_rate>
        <body_name>base_footprint</body_name>
        <gaussian_noise>0.01</gaussian_noise>
        <frame_name>map</frame_name>
        <xyz_offset>0 0 0</xyz_offset>
        <rpy_offset>0 0 0</rpy_offset>
      </plugin>
      <static>0</static>
      <plugin name='joint_states' filename='libgazebo_ros_joint_state_publisher.so'>
        <ros>
          <namespace/>
        </ros>
        <update_rate>1000.0</update_rate>
        <joint_name>right_wheel_joint</joint_name>
        <joint_name>left_wheel_joint</joint_name>
      </plugin>
      <plugin name='diff_drive_controller' filename='libgazebo_ros_diff_drive.so'>
        <ros>
          <remapping>cmd_vel:=cmd_vel</remapping>
          <remapping>odom:=odom</remapping>
        </ros>
        <legacy_mode>0</legacy_mode>
        <always_on>1</always_on>
        <update_rate>1000.0</update_rate>
        <left_joint>left_wheel_joint</left_joint>
        <right_joint>right_wheel_joint</right_joint>
        <wheel_separation>0.445208</wheel_separation>
        <wheel_diameter>0.125</wheel_diameter>
        <odometry_frame>odom</odometry_frame>
        <robot_base_frame>base_footprint</robot_base_frame>
        <publish_odom>1</publish_odom>
        <publish_wheel_tf>0</publish_wheel_tf>
        <publish_odom_tf>1</publish_odom_tf>
        <max_wheel_torque>10</max_wheel_torque>
        <max_wheel_acceleration>2.8</max_wheel_acceleration>
      </plugin>
      <pose>0 0 0 0 -0 0</pose>
    </model>
    <model name='aruco_marker_0'>
      <static>1</static>
      <link name='link'>
        <visual name='visual'>
          <geometry>
            <box>
              <size>0.15 0.15 0.01</size>
            </box>
          </geometry>
          <material>
            <script>
              <uri>model://aruco_marker_0/materials/scripts</uri>
              <name>AruCo/Marker0</name>
            </script>
          </material>
        </visual>
        <self_collide>0</self_collide>
        <enable_wind>0</enable_wind>
        <kinematic>0</kinematic>
      </link>
      <pose>1.84354 -9.70764 0 0 -0 0</pose>
    </model>
    <state world_name='default'>
      <sim_time>970 178000000</sim_time>
      <real_time>29 479160108</real_time>
      <wall_time>1747060873 196337116</wall_time>
      <iterations>28800</iterations>
      <model name='aruco_marker_0'>
        <pose>1.82 -10.312 0.3124 1.57079 -1.57079 3.14159</pose>
        <scale>1 1 1</scale>
        <link name='link'>
          <pose>1.82 -10.312 0.3124 1.57079 -1.57079 3.14159</pose>
          <velocity>0 0 0 0 -0 0</velocity>
          <acceleration>0 0 0 0 -0 0</acceleration>
          <wrench>0 0 0 0 -0 0</wrench>
        </link>
      </model>
      <model name='aruco_marker_1'>
        <pose>6.83852 -9.81975 0.3124 3.14159 -1.57079 3.14159</pose>
        <scale>1 1 1</scale>
        <link name='link'>
          <pose>6.83852 -9.81975 0.3124 3.14159 -1.57079 3.14159</pose>
          <velocity>0 0 0 0 -0 0</velocity>
          <acceleration>0 0 0 0 -0 0</acceleration>
          <wrench>0 0 0 0 -0 0</wrench>
        </link>
      </model>
      <model name='aruco_marker_2'>
        <pose>6.84472 2.21096 0.3124 3.14159 -1.57079 3.14159</pose>
        <scale>1 1 1</scale>
        <link name='link'>
          <pose>6.84472 2.21096 0.3124 3.14159 -1.57079 3.14159</pose>
          <velocity>0 0 0 0 -0 0</velocity>
          <acceleration>0 0 0 0 -0 0</acceleration>
          <wrench>0 0 0 0 -0 0</wrench>
        </link>
      </model>
      <model name='aruco_marker_3'>
        <pose>1.76363 10.3152 0.3124 -1.4289 -1.57079 2.9997</pose>
        <scale>1 1 1</scale>
        <link name='link'>
          <pose>1.76363 10.3152 0.3124 -1.4289 -1.57079 2.9997</pose>
          <velocity>0 0 0 0 -0 0</velocity>
          <acceleration>0 0 0 0 -0 0</acceleration>
          <wrench>0 0 0 0 -0 0</wrench>
        </link>
      </model>
      <model name='aruco_marker_4'>
        <pose>-3.81013 10.3104 0.3124 -1.4289 -1.57079 2.9997</pose>
        <scale>1 1 1</scale>
        <link name='link'>
          <pose>-3.81013 10.3104 0.3124 -1.4289 -1.57079 2.9997</pose>
          <velocity>0 0 0 0 -0 0</velocity>
          <acceleration>0 0 0 0 -0 0</acceleration>
          <wrench>0 0 0 0 -0 0</wrench>
        </link>
      </model>
      <model name='aruco_marker_5'>
        <pose>-6.85611 9.18903 0.3124 0 -1.57079 -3.14159</pose>
        <scale>1 1 1</scale>
        <link name='link'>
          <pose>-6.85611 9.18903 0.3124 0 -1.57079 -3.14159</pose>
          <velocity>0 0 0 0 -0 0</velocity>
          <acceleration>0 0 0 0 -0 0</acceleration>
          <wrench>0 0 0 0 -0 0</wrench>
        </link>
      </model>
      <model name='aws_robomaker_warehouse_Bucket_01_020'>
        <pose>0.433449 9.63171 0 0 0 -1.56316</pose>
        <scale>1 1 1</scale>
        <link name='aws_robomaker_warehouse_Bucket_01::body'>
          <pose>0.433449 9.63171 0 0 0 -1.56316</pose>
          <velocity>0 0 0 0 -0 0</velocity>
          <acceleration>0 0 0 0 -0 0</acceleration>
          <wrench>0 0 0 0 -0 0</wrench>
        </link>
      </model>
      <model name='aws_robomaker_warehouse_Bucket_01_020_clone'>
        <pose>-1.87113 3.23127 0 0 0 -1.56316</pose>
        <scale>1 1 1</scale>
        <link name='aws_robomaker_warehouse_Bucket_01::body'>
          <pose>-1.87113 3.23127 0 0 0 -1.56316</pose>
          <velocity>0 0 0 0 -0 0</velocity>
          <acceleration>0 0 0 0 -0 0</acceleration>
          <wrench>0 0 0 0 -0 0</wrench>
        </link>
      </model>
      <model name='aws_robomaker_warehouse_Bucket_01_021'>
        <pose>-1.8321 -6.3752 0 0 0 -1.56316</pose>
        <scale>1 1 1</scale>
        <link name='aws_robomaker_warehouse_Bucket_01::body'>
          <pose>-1.8321 -6.3752 0 0 0 -1.56316</pose>
          <velocity>0 0 0 0 -0 0</velocity>
          <acceleration>0 0 0 0 -0 0</acceleration>
          <wrench>0 0 0 0 -0 0</wrench>
        </link>
      </model>
      <model name='aws_robomaker_warehouse_Bucket_01_021_clone'>
        <pose>4.94933 -8.16306 0 0 0 -1.56316</pose>
        <scale>1 1 1</scale>
        <link name='aws_robomaker_warehouse_Bucket_01::body'>
          <pose>4.94933 -8.16306 0 0 0 -1.56316</pose>
          <velocity>0 0 0 0 -0 0</velocity>
          <acceleration>0 0 0 0 -0 0</acceleration>
          <wrench>0 0 0 0 -0 0</wrench>
        </link>
      </model>
      <model name='aws_robomaker_warehouse_ClutteringA_01_016'>
        <pose>5.70814 8.61684 -0.017477 0 -0 0</pose>
        <scale>1 1 1</scale>
        <link name='aws_robomaker_warehouse_ClutteringA_01::link'>
          <pose>5.70814 8.61684 -0.017477 0 -0 0</pose>
          <velocity>0 0 0 0 -0 0</velocity>
          <acceleration>0 0 0 0 -0 0</acceleration>
          <wrench>0 0 0 0 -0 0</wrench>
        </link>
      </model>
      <model name='aws_robomaker_warehouse_ClutteringA_01_017'>
        <pose>3.40864 8.61684 -0.017477 0 -0 0</pose>
        <scale>1 1 1</scale>
        <link name='aws_robomaker_warehouse_ClutteringA_01::link'>
          <pose>3.40864 8.61684 -0.017477 0 -0 0</pose>
          <velocity>0 0 0 0 -0 0</velocity>
          <acceleration>0 0 0 0 -0 0</acceleration>
          <wrench>0 0 0 0 -0 0</wrench>
        </link>
      </model>
      <model name='aws_robomaker_warehouse_ClutteringC_01_027'>
        <pose>3.32496 3.82245 -0.012064 0 -0 1.56387</pose>
        <scale>1 1 1</scale>
        <link name='aws_robomaker_warehouse_ClutteringC_01::link'>
          <pose>3.32496 3.82245 -0.012064 0 -0 1.56387</pose>
          <velocity>0 0 0 0 -0 0</velocity>
          <acceleration>0 0 0 0 -0 0</acceleration>
          <wrench>0 0 0 0 -0 0</wrench>
        </link>
      </model>
      <model name='aws_robomaker_warehouse_ClutteringC_01_028'>
        <pose>5.54171 3.81648 -0.015663 0 0 -1.58319</pose>
        <scale>1 1 1</scale>
        <link name='aws_robomaker_warehouse_ClutteringC_01::link'>
          <pose>5.54171 3.81648 -0.015663 0 0 -1.58319</pose>
          <velocity>0 0 0 0 -0 0</velocity>
          <acceleration>0 0 0 0 -0 0</acceleration>
          <wrench>0 0 0 0 -0 0</wrench>
        </link>
      </model>
      <model name='aws_robomaker_warehouse_ClutteringC_01_032'>
        <pose>-1.2196 9.407 -0.015663 0 -0 1.56387</pose>
        <scale>1 1 1</scale>
        <link name='aws_robomaker_warehouse_ClutteringC_01::link'>
          <pose>-1.2196 9.407 -0.015663 0 -0 1.56387</pose>
          <velocity>0 0 0 0 -0 0</velocity>
          <acceleration>0 0 0 0 -0 0</acceleration>
          <wrench>0 0 0 0 -0 0</wrench>
        </link>
      </model>
      <model name='aws_robomaker_warehouse_ClutteringD_01_005'>
        <pose>-1.63468 -7.81181 -0.319559 0 -0 0</pose>
        <scale>1 1 1</scale>
        <link name='aws_robomaker_warehouse_ClutteringD_01::link'>
          <pose>-1.63468 -7.81181 -0.319559 0 -0 0</pose>
          <velocity>0 0 0 0 -0 0</velocity>
          <acceleration>0 0 0 0 -0 0</acceleration>
          <wrench>0 0 0 0 -0 0</wrench>
        </link>
      </model>
      <model name='aws_robomaker_warehouse_GroundB_01_001'>
        <pose>0 0 -0.090092 0 -0 0</pose>
        <scale>1 1 1</scale>
        <link name='aws_robomaker_warehouse_GroundB_01::link'>
          <pose>0 0 -0.090092 0 -0 0</pose>
          <velocity>0 0 0 0 -0 0</velocity>
          <acceleration>0 0 0 0 -0 0</acceleration>
          <wrench>0 0 0 0 -0 0</wrench>
        </link>
      </model>
      <model name='aws_robomaker_warehouse_Lamp_01_005'>
        <pose>0 0 -4 0 -0 0</pose>
        <scale>1 1 1</scale>
        <link name='aws_robomaker_warehouse_Lamp_01::link'>
          <pose>0 0 -4 0 -0 0</pose>
          <velocity>0 0 0 0 -0 0</velocity>
          <acceleration>0 0 0 0 -0 0</acceleration>
          <wrench>0 0 0 0 -0 0</wrench>
        </link>
      </model>
      <model name='aws_robomaker_warehouse_ShelfD_01_002'>
        <pose>4.73156 -3.03855 0 0 -0 0</pose>
        <scale>1 1 1</scale>
        <link name='aws_robomaker_warehouse_ShelfD_01::link'>
          <pose>4.73156 -3.03855 0 0 -0 0</pose>
          <velocity>0 0 0 0 -0 0</velocity>
          <acceleration>0 0 0 0 -0 0</acceleration>
          <wrench>0 0 0 0 -0 0</wrench>
        </link>
      </model>
      <model name='aws_robomaker_warehouse_ShelfE_01_001'>
        <pose>4.73156 0.57943 0 0 -0 0</pose>
        <scale>1 1 1</scale>
        <link name='aws_robomaker_warehouse_ShelfE_01::link'>
          <pose>4.73156 0.57943 0 0 -0 0</pose>
          <velocity>0 0 0 0 -0 0</velocity>
          <acceleration>0 0 0 0 -0 0</acceleration>
          <wrench>0 0 0 0 -0 0</wrench>
        </link>
      </model>
      <model name='aws_robomaker_warehouse_ShelfE_01_002'>
        <pose>4.73156 -4.82705 0 0 -0 0</pose>
        <scale>1 1 1</scale>
        <link name='aws_robomaker_warehouse_ShelfE_01::link'>
          <pose>4.73156 -4.82705 0 0 -0 0</pose>
          <velocity>0 0 0 0 -0 0</velocity>
          <acceleration>0 0 0 0 -0 0</acceleration>
          <wrench>0 0 0 0 -0 0</wrench>
        </link>
      </model>
      <model name='aws_robomaker_warehouse_ShelfF_01_001'>
        <pose>-5.79514 -0.956635 0 0 -0 0</pose>
        <scale>1 1 1</scale>
        <link name='aws_robomaker_warehouse_ShelfF_01::link'>
          <pose>-5.79514 -0.956635 0 0 -0 0</pose>
          <velocity>0 0 0 0 -0 0</velocity>
          <acceleration>0 0 0 0 -0 0</acceleration>
          <wrench>0 0 0 0 -0 0</wrench>
        </link>
      </model>
      <model name='aws_robomaker_warehouse_WallB_01_001'>
        <pose>0 0 0 0 -0 0</pose>
        <scale>1 1 1</scale>
        <link name='aws_robomaker_warehouse_WallB_01::link'>
          <pose>0 0 0 0 -0 0</pose>
          <velocity>0 0 0 0 -0 0</velocity>
          <acceleration>0 0 0 0 -0 0</acceleration>
          <wrench>0 0 0 0 -0 0</wrench>
        </link>
      </model>
      <model name='cart'>
        <pose>-2.03807 -1.97077 0.03408 -1e-06 3e-06 0.169229</pose>
        <scale>1 1 1</scale>
        <link name='base_footprint'>
          <pose>-2.03807 -1.97077 0.03408 -1e-06 3e-06 0.169229</pose>
          <velocity>-0.00175 -0.00284 0.001629 -0.00573 0.003716 -0.000268</velocity>
          <acceleration>1.02177 1.11919 3.25906 1.97516 0.559881 0.058181</acceleration>
          <wrench>30.8197 33.7583 98.3031 0 -0 0</wrench>
        </link>
        <link name='rev1_link'>
          <pose>-1.6502 -1.53928 0.13058 -3e-05 0.000103 2.44372</pose>
          <velocity>-0.001142 -0.001887 -0.003189 0.015285 0.038254 0.131168</velocity>
          <acceleration>-4.14995 -2.98402 -7.07477 -2.98414 -1.08243 -2.80785</acceleration>
          <wrench>-5.7935 -4.16581 -9.87666 0 -0 0</wrench>
        </link>
        <link name='rev2_link'>
          <pose>-2.5472 -1.69254 0.130584 -6.4e-05 0.000141 -2.07265</pose>
          <velocity>-0.000526 -0.001449 0.002982 0.047192 -0.007925 0.0004</velocity>
          <acceleration>-1.44163 -3.11466 6.76837 -2.58854 -1.31453 -2.7858</acceleration>
          <wrench>-2.01257 -4.34819 9.44891 0 -0 0</wrench>
        </link>
        <link name='rev3_link'>
          <pose>-1.52893 -2.24899 0.130583 5.1e-05 0.000176 0.314326</pose>
          <velocity>-0.000748 -0.001998 0.002397 -0.003615 0.032723 -0.117961</velocity>
          <acceleration>-4.60132 -4.41788 5.36697 1.61079 -1.34983 0.215143</acceleration>
          <wrench>-6.42362 -6.16754 7.4925 0 -0 0</wrench>
        </link>
        <link name='rev4_link'>
          <pose>-2.42594 -2.40225 0.130584 -6e-06 -8.6e-05 -0.77243</pose>
          <velocity>-0.002008 -0.000961 0.005919 -0.018848 -0.006518 -0.102588</velocity>
          <acceleration>-3.1039 -3.50283 11.5265 1.27457 -1.20995 -0.605344</acceleration>
          <wrench>-4.33317 -4.89009 16.0915 0 -0 0</wrench>
        </link>
        <link name='wheel_link1'>
          <pose>-1.64454 -1.57144 0.071601 -1.57073 0.489578 2.44379</pose>
          <velocity>0.002457 -0.000951 -0.010329 0.02847 -0.023875 0.118011</velocity>
          <acceleration>-0.364293 -0.530044 -19.0989 -2.76004 0.597237 2.57369</acceleration>
          <wrench>-1.15821 -1.68519 -60.7221 0 -0 0</wrench>
        </link>
        <link name='wheel_link2'>
          <pose>-2.51676 -1.68073 0.07161 1.57073 -0.431363 1.06896</pose>
          <velocity>-0.000665 0.000915 0.009693 -0.01343 -0.024448 0.022563</velocity>
          <acceleration>-1.56917 -2.12277 18.2152 -1.70271 1.35935 -0.839403</acceleration>
          <wrench>-4.98893 -6.74904 57.9124 0 -0 0</wrench>
        </link>
        <link name='wheel_link3'>
          <pose>-1.54622 -2.2767 0.071617 1.571 1.25548 -2.82705</pose>
          <velocity>-0.002557 0.000458 0.010009 -0.032081 -0.011078 -0.093667</velocity>
          <acceleration>-1.8587 -1.12034 18.5931 1.70239 -0.226717 2.77018</acceleration>
          <wrench>-5.90946 -3.56194 59.1141 0 -0 0</wrench>
        </link>
        <link name='wheel_link4'>
          <pose>-2.4585 -2.39984 0.071609 1.57086 -0.024526 2.36919</pose>
          <velocity>-0.001469 0.00187 0.010016 -0.007619 0.006172 -0.0961</velocity>
          <acceleration>-0.282375 -0.586045 19.6224 -2.18918 0.17514 2.95921</acceleration>
          <wrench>-0.897768 -1.86324 62.3863 0 -0 0</wrench>
        </link>
      </model>
      <model name='mir_robot'>
        <pose>-0.212597 0.007158 0.034221 3e-06 -1.1e-05 -0.000667</pose>
        <scale>1 1 1</scale>
        <link name='base_footprint'>
          <pose>-0.212597 0.007158 0.034221 3e-06 -1.1e-05 -0.000667</pose>
          <velocity>-7.6e-05 -0.000182 -2.9e-05 2.5e-05 -3.6e-05 0.000128</velocity>
          <acceleration>0.00054 0.025434 -0.003959 -0.01986 -0.001329 -0.029538</acceleration>
          <wrench>0.038303 1.80476 -0.280943 0 -0 0</wrench>
        </link>
        <link name='bl_caster_rotation_link'>
          <pose>-0.482616 0.210338 0.190722 1e-06 7.6e-05 3.01346</pose>
          <velocity>-9.6e-05 -0.000157 -1.1e-05 -0.000539 -0.000436 0.004609</velocity>
          <acceleration>0.009814 0.013936 -0.003796 -0.022119 -0.108975 0.014442</acceleration>
          <wrench>0.00304 0.004317 -0.001176 0 -0 0</wrench>
        </link>
        <link name='bl_caster_wheel_link'>
          <pose>-0.444727 0.205457 0.096724 -2e-06 0.606485 3.01346</pose>
          <velocity>-6.4e-05 9e-06 2e-06 -0.000219 -0.001619 0.004575</velocity>
          <acceleration>0.009771 0.008416 -0.000497 -0.15317 0.030881 0.009597</acceleration>
          <wrench>0.009771 0.008416 -0.000497 0 -0 0</wrench>
        </link>
        <link name='br_caster_rotation_link'>
          <pose>-0.482887 -0.195662 0.190722 2e-06 9.3e-05 3.01598</pose>
          <velocity>-4.2e-05 -0.000162 -1.4e-05 -0.000493 -0.00061 0.004411</velocity>
          <acceleration>-0.008288 0.01589 -0.000758 0.005399 -0.000537 -0.0157</acceleration>
          <wrench>-0.002567 0.004922 -0.000235 0 -0 0</wrench>
        </link>
        <link name='br_caster_wheel_link'>
          <pose>-0.444985 -0.200448 0.096724 -1e-06 0.589521 3.01598</pose>
          <velocity>-6e-06 -1e-06 4e-06 -0.000222 -0.001978 0.004382</velocity>
          <acceleration>-0.007033 0.009704 -0.000582 -0.139512 0.033016 -0.004736</acceleration>
          <wrench>-0.007033 0.009704 -0.000582 0 -0 0</wrench>
        </link>
        <link name='fl_caster_rotation_link'>
          <pose>0.128883 0.20993 0.190725 4e-06 -9e-06 -3.11559</pose>
          <velocity>-0.000105 -0.000126 -5e-06 -0.000343 -0.000184 0.003981</velocity>
          <acceleration>0.011858 0.008275 -0.002756 0.204073 -0.0969 -0.305658</acceleration>
          <wrench>0.003673 0.002563 -0.000854 0 -0 0</wrench>
        </link>
        <link name='fl_caster_wheel_link'>
          <pose>0.16707 0.210923 0.096724 1e-06 0.675066 -3.11559</pose>
          <velocity>-0.000101 1.3e-05 -0 -0.000208 -0.001619 0.003974</velocity>
          <acceleration>0.010448 0.000132 8.3e-05 0.00225 -7.8e-05 -0.143812</acceleration>
          <wrench>0.010448 0.000132 8.3e-05 0 -0 0</wrench>
        </link>
        <link name='fr_caster_rotation_link'>
          <pose>0.128612 -0.19607 0.190724 3e-06 8e-06 -3.11589</pose>
          <velocity>-5e-05 -0.000107 -8e-06 -0.000467 -0.000377 0.003006</velocity>
          <acceleration>-0.006891 0.008609 4.3e-05 0.088322 0.019118 -0.092666</acceleration>
          <wrench>-0.002134 0.002667 1.3e-05 0 -0 0</wrench>
        </link>
        <link name='fr_caster_wheel_link'>
          <pose>0.1668 -0.195088 0.096724 3e-06 0.607168 -3.11589</pose>
          <velocity>-3.9e-05 -4e-06 3e-06 0.000102 -0.001898 0.002975</velocity>
          <acceleration>-0.006771 0.00488 -0.000385 -0.080853 0.00188 -0.001679</acceleration>
          <wrench>-0.006771 0.00488 -0.000385 0 -0 0</wrench>
        </link>
        <link name='left_wheel_link'>
          <pose>-0.212449 0.22976 0.096725 -3.14154 -0.433693 3.1409</pose>
          <velocity>-0.000108 -0.000191 -9e-06 0.003346 -0.001677 -9.4e-05</velocity>
          <acceleration>0.00475 0.023047 -0.005825 -0.367023 0.072356 0.018132</acceleration>
          <wrench>0.00475 0.023047 -0.005825 0 -0 0</wrench>
        </link>
        <link name='right_wheel_link'>
          <pose>-0.212746 -0.215444 0.096725 3.1415 0.112413 3.14092</pose>
          <velocity>-6.5e-05 -0.000143 8e-06 0.002281 -0.001032 2.1e-05</velocity>
          <acceleration>-0.001358 0.018949 -0.000855 -0.303232 -0.021113 0.003117</acceleration>
          <wrench>-0.001358 0.018949 -0.000855 0 -0 0</wrench>
        </link>
      </model>
      <light name='Warehouse_CeilingLight_003'>
        <pose>0 0 9 0 -0 0</pose>
      </light>
    </state>
    <model name='aruco_marker_1'>
      <static>1</static>
      <link name='link'>
        <visual name='visual'>
          <geometry>
            <box>
              <size>0.15 0.15 0.01</size>
            </box>
          </geometry>
          <material>
            <script>
              <uri>model://aruco_marker_1/materials/scripts</uri>
              <name>AruCo/Marker1</name>
            </script>
          </material>
        </visual>
        <self_collide>0</self_collide>
        <enable_wind>0</enable_wind>
        <kinematic>0</kinematic>
      </link>
      <pose>6.68568 -9.99923 0 0 -0 0</pose>
    </model>
    <model name='aruco_marker_2'>
      <static>1</static>
      <link name='link'>
        <visual name='visual'>
          <geometry>
            <box>
              <size>0.15 0.15 0.01</size>
            </box>
          </geometry>
          <material>
            <script>
              <uri>model://aruco_marker_2/materials/scripts</uri>
              <name>AruCo/Marker2</name>
            </script>
          </material>
        </visual>
        <self_collide>0</self_collide>
        <enable_wind>0</enable_wind>
        <kinematic>0</kinematic>
      </link>
      <pose>7.83095 2.31895 0 0 -0 0</pose>
    </model>
    <model name='aruco_marker_3'>
      <static>1</static>
      <link name='link'>
        <visual name='visual'>
          <geometry>
            <box>
              <size>0.15 0.15 0.01</size>
            </box>
          </geometry>
          <material>
            <script>
              <uri>model://aruco_marker_3/materials/scripts</uri>
              <name>AruCo/Marker3</name>
            </script>
          </material>
        </visual>
        <self_collide>0</self_collide>
        <enable_wind>0</enable_wind>
        <kinematic>0</kinematic>
      </link>
      <pose>1.58684 10.8851 0 0 -0 0</pose>
    </model>
    <model name='aruco_marker_4'>
      <static>1</static>
      <link name='link'>
        <visual name='visual'>
          <geometry>
            <box>
              <size>0.15 0.15 0.01</size>
            </box>
          </geometry>
          <material>
            <script>
              <uri>model://aruco_marker_4/materials/scripts</uri>
              <name>AruCo/Marker4</name>
            </script>
          </material>
        </visual>
        <self_collide>0</self_collide>
        <enable_wind>0</enable_wind>
        <kinematic>0</kinematic>
      </link>
      <pose>-3.85436 10.7375 0 0 -0 0</pose>
    </model>
    <model name='aruco_marker_5'>
      <static>1</static>
      <link name='link'>
        <visual name='visual'>
          <geometry>
            <box>
              <size>0.15 0.15 0.01</size>
            </box>
          </geometry>
          <material>
            <script>
              <uri>model://aruco_marker_5/materials/scripts</uri>
              <name>AruCo/Marker5</name>
            </script>
          </material>
        </visual>
        <self_collide>0</self_collide>
        <enable_wind>0</enable_wind>
        <kinematic>0</kinematic>
      </link>
      <pose>-6.14092 9.19602 0 0 -0 0</pose>
    </model>
    <model name='aws_robomaker_warehouse_Bucket_01_020_clone'>
      <frame name='aws_robomaker_warehouse_Bucket_01::__model__' attached_to='aws_robomaker_warehouse_Bucket_01::body'>
        <pose relative_to='__model__'>0 0 0 0 -0 0</pose>
      </frame>
      <link name='aws_robomaker_warehouse_Bucket_01::body'>
        <inertial>
          <mass>2</mass>
          <pose>0 0 0 0 -0 0</pose>
          <inertia>
            <ixx>0.57</ixx>
            <ixy>0</ixy>
            <ixz>0</ixz>
            <iyy>0.474</iyy>
            <iyz>0</iyz>
            <izz>0.391</izz>
          </inertia>
        </inertial>
        <pose relative_to='aws_robomaker_warehouse_Bucket_01::__model__'>0 0 0 0 -0 0</pose>
        <self_collide>0</self_collide>
        <kinematic>0</kinematic>
        <gravity>1</gravity>
        <visual name='visual'>
          <geometry>
            <mesh>
              <uri>file://models/aws_robomaker_warehouse_Bucket_01/meshes/aws_robomaker_warehouse_Bucket_01_visual.DAE</uri>
            </mesh>
          </geometry>
          <meta>
            <layer>1</layer>
          </meta>
        </visual>
        <collision name='collision_0'>
          <laser_retro>0</laser_retro>
          <max_contacts>10</max_contacts>
          <pose>0 0 0 0 -0 0</pose>
          <geometry>
            <mesh>
              <uri>file://models/aws_robomaker_warehouse_Bucket_01/meshes/aws_robomaker_warehouse_Bucket_01_collision.DAE</uri>
              <scale>1 1 1</scale>
            </mesh>
          </geometry>
          <surface>
            <friction>
              <ode>
                <mu>0.4</mu>
                <mu2>0.4</mu2>
                <fdir1>0 0 0</fdir1>
                <slip1>0</slip1>
                <slip2>0</slip2>
              </ode>
              <torsional>
                <coefficient>1</coefficient>
                <patch_radius>0</patch_radius>
                <surface_radius>0</surface_radius>
                <use_patch_radius>1</use_patch_radius>
                <ode>
                  <slip>0</slip>
                </ode>
              </torsional>
            </friction>
            <contact>
              <ode/>
            </contact>
            <bounce/>
          </surface>
        </collision>
        <enable_wind>0</enable_wind>
      </link>
      <static>1</static>
      <pose>-1.87113 3.23127 0 0 0 -1.56316</pose>
    </model>
    <model name='aws_robomaker_warehouse_Bucket_01_021_clone'>
      <frame name='aws_robomaker_warehouse_Bucket_01::__model__' attached_to='aws_robomaker_warehouse_Bucket_01::body'>
        <pose relative_to='__model__'>0 0 0 0 -0 0</pose>
      </frame>
      <link name='aws_robomaker_warehouse_Bucket_01::body'>
        <inertial>
          <mass>2</mass>
          <pose>0 0 0 0 -0 0</pose>
          <inertia>
            <ixx>0.57</ixx>
            <ixy>0</ixy>
            <ixz>0</ixz>
            <iyy>0.474</iyy>
            <iyz>0</iyz>
            <izz>0.391</izz>
          </inertia>
        </inertial>
        <pose relative_to='aws_robomaker_warehouse_Bucket_01::__model__'>0 0 0 0 -0 0</pose>
        <self_collide>0</self_collide>
        <kinematic>0</kinematic>
        <gravity>1</gravity>
        <visual name='visual'>
          <geometry>
            <mesh>
              <uri>file://models/aws_robomaker_warehouse_Bucket_01/meshes/aws_robomaker_warehouse_Bucket_01_visual.DAE</uri>
            </mesh>
          </geometry>
          <meta>
            <layer>1</layer>
          </meta>
        </visual>
        <collision name='collision_0'>
          <laser_retro>0</laser_retro>
          <max_contacts>10</max_contacts>
          <pose>0 0 0 0 -0 0</pose>
          <geometry>
            <mesh>
              <uri>file://models/aws_robomaker_warehouse_Bucket_01/meshes/aws_robomaker_warehouse_Bucket_01_collision.DAE</uri>
              <scale>1 1 1</scale>
            </mesh>
          </geometry>
          <surface>
            <friction>
              <ode>
                <mu>0.4</mu>
                <mu2>0.4</mu2>
                <fdir1>0 0 0</fdir1>
                <slip1>0</slip1>
                <slip2>0</slip2>
              </ode>
              <torsional>
                <coefficient>1</coefficient>
                <patch_radius>0</patch_radius>
                <surface_radius>0</surface_radius>
                <use_patch_radius>1</use_patch_radius>
                <ode>
                  <slip>0</slip>
                </ode>
              </torsional>
            </friction>
            <contact>
              <ode/>
            </contact>
            <bounce/>
          </surface>
        </collision>
        <enable_wind>0</enable_wind>
      </link>
      <static>1</static>
      <pose>4.94933 -8.16306 0 0 0 -1.56316</pose>
    </model>
    <model name='cart'>
      <link name='base_footprint'>
        <inertial>
          <pose>-0 0 0.76506 0 -0 0</pose>
          <mass>30.163</mass>
          <inertia>
            <ixx>1.0132</ixx>
            <ixy>-2.3419e-15</ixy>
            <ixz>7.6733e-10</ixz>
            <iyy>1.6281</iyy>
            <iyz>-3.803e-10</iyz>
            <izz>2.1018</izz>
          </inertia>
        </inertial>
        <collision name='base_footprint_fixed_joint_lump__base_link_collision'>
          <pose>0 0 1.371 0 -0 0</pose>
          <geometry>
            <mesh>
              <scale>1 1 1</scale>
              <uri>file:////home/kraiwich/OpenTopic_ws/install/cart_description/share/cart_description/meshes/base_link.STL</uri>
            </mesh>
          </geometry>
          <surface>
            <contact>
              <ode/>
            </contact>
            <friction>
              <ode/>
              <torsional>
                <ode/>
              </torsional>
            </friction>
            <bounce/>
          </surface>
          <max_contacts>10</max_contacts>
        </collision>
        <visual name='base_footprint_fixed_joint_lump__base_link_visual'>
          <pose>0 0 1.371 0 -0 0</pose>
          <geometry>
            <mesh>
              <scale>1 1 1</scale>
              <uri>file:////home/kraiwich/OpenTopic_ws/install/cart_description/share/cart_description/meshes/base_link.STL</uri>
            </mesh>
          </geometry>
          <material>
            <script>
              <name>Gazebo/White</name>
              <uri>file://media/materials/scripts/gazebo.material</uri>
            </script>
          </material>
        </visual>
        <self_collide>0</self_collide>
        <enable_wind>0</enable_wind>
        <kinematic>0</kinematic>
      </link>
      <joint name='rev1_joint' type='revolute'>
        <pose relative_to='base_footprint'>0.455 0.359999 0.0965 0 -0 0</pose>
        <parent>base_footprint</parent>
        <child>rev1_link</child>
        <axis>
          <xyz>0 0 -1</xyz>
          <limit>
            <lower>-1e+16</lower>
            <upper>1e+16</upper>
          </limit>
          <dynamics>
            <spring_reference>0</spring_reference>
            <spring_stiffness>0</spring_stiffness>
          </dynamics>
        </axis>
      </joint>
      <link name='rev1_link'>
        <pose relative_to='rev1_joint'>0 0 0 0 -0 0</pose>
        <inertial>
          <pose>-0.008873 -6.6e-05 -0.024908 0 -0 0</pose>
          <mass>1.39604</mass>
          <inertia>
            <ixx>0.00039872</ixx>
            <ixy>-4.2724e-07</ixy>
            <ixz>-6.7183e-05</ixz>
            <iyy>0.00033801</iyy>
            <iyz>-8.9725e-07</iyz>
            <izz>0.00036573</izz>
          </inertia>
        </inertial>
        <collision name='rev1_link_collision'>
          <pose>0 0 0 0 -0 0</pose>
          <geometry>
            <mesh>
              <scale>1 1 1</scale>
              <uri>file:////home/kraiwich/OpenTopic_ws/install/cart_description/share/cart_description/meshes/rev1_link.STL</uri>
            </mesh>
          </geometry>
          <surface>
            <contact>
              <ode/>
            </contact>
            <friction>
              <ode>
                <mu>1000</mu>
                <mu2>1000</mu2>
              </ode>
              <torsional>
                <ode/>
              </torsional>
            </friction>
            <bounce/>
          </surface>
          <max_contacts>10</max_contacts>
        </collision>
        <visual name='rev1_link_visual'>
          <pose>0 0 0 0 -0 0</pose>
          <geometry>
            <mesh>
              <scale>1 1 1</scale>
              <uri>file:////home/kraiwich/OpenTopic_ws/install/cart_description/share/cart_description/meshes/rev1_link.STL</uri>
            </mesh>
          </geometry>
          <material>
            <script>
              <name>Gazebo/White</name>
              <uri>file://media/materials/scripts/gazebo.material</uri>
            </script>
          </material>
        </visual>
        <self_collide>0</self_collide>
        <enable_wind>0</enable_wind>
        <kinematic>0</kinematic>
      </link>
      <joint name='wheel_joint1' type='revolute'>
        <pose relative_to='rev1_link'>-0.025 0.021001 -0.059 -1.5708 0 0</pose>
        <parent>rev1_link</parent>
        <child>wheel_link1</child>
        <axis>
          <xyz>0 0 -1</xyz>
          <limit>
            <lower>-1e+16</lower>
            <upper>1e+16</upper>
          </limit>
          <dynamics>
            <spring_reference>0</spring_reference>
            <spring_stiffness>0</spring_stiffness>
          </dynamics>
        </axis>
      </joint>
      <link name='wheel_link1'>
        <pose relative_to='wheel_joint1'>0 0 0 0 -0 0</pose>
        <inertial>
          <pose>-0 -0 -0.021 0 -0 0</pose>
          <mass>3.17935</mass>
          <inertia>
            <ixx>8.2728e-05</ixx>
            <ixy>-9.2883e-10</ixy>
            <ixz>-2.5882e-10</ixz>
            <iyy>8.2727e-05</iyy>
            <iyz>-4.0977e-11</iyz>
            <izz>0.00012509</izz>
          </inertia>
        </inertial>
        <collision name='wheel_link1_collision'>
          <pose>0 0 0 0 -0 0</pose>
          <geometry>
            <mesh>
              <scale>1 1 1</scale>
              <uri>file:////home/kraiwich/OpenTopic_ws/install/cart_description/share/cart_description/meshes/wheel_link1.STL</uri>
            </mesh>
          </geometry>
          <surface>
            <contact>
              <ode/>
            </contact>
            <friction>
              <ode>
                <mu>1000</mu>
                <mu2>1000</mu2>
              </ode>
              <torsional>
                <ode/>
              </torsional>
            </friction>
            <bounce/>
          </surface>
          <max_contacts>10</max_contacts>
        </collision>
        <visual name='wheel_link1_visual'>
          <pose>0 0 0 0 -0 0</pose>
          <geometry>
            <mesh>
              <scale>1 1 1</scale>
              <uri>file:////home/kraiwich/OpenTopic_ws/install/cart_description/share/cart_description/meshes/wheel_link1.STL</uri>
            </mesh>
          </geometry>
          <material>
            <script>
              <name>Gazebo/Black</name>
              <uri>file://media/materials/scripts/gazebo.material</uri>
            </script>
          </material>
        </visual>
        <self_collide>0</self_collide>
        <enable_wind>0</enable_wind>
        <kinematic>0</kinematic>
      </link>
      <joint name='rev2_joint' type='revolute'>
        <pose relative_to='base_footprint'>-0.455 0.359999 0.0965 0 -0 0</pose>
        <parent>base_footprint</parent>
        <child>rev2_link</child>
        <axis>
          <xyz>0 0 -1</xyz>
          <limit>
            <lower>-1e+16</lower>
            <upper>1e+16</upper>
          </limit>
          <dynamics>
            <spring_reference>0</spring_reference>
            <spring_stiffness>0</spring_stiffness>
          </dynamics>
        </axis>
      </joint>
      <link name='rev2_link'>
        <pose relative_to='rev2_joint'>0 0 0 0 -0 0</pose>
        <inertial>
          <pose>-0.008873 -6.6e-05 -0.024908 0 -0 0</pose>
          <mass>1.39604</mass>
          <inertia>
            <ixx>0.000398723</ixx>
            <ixy>-4.27245e-07</ixy>
            <ixz>-6.71828e-05</ixz>
            <iyy>0.000338006</iyy>
            <iyz>-8.97252e-07</iyz>
            <izz>0.000365728</izz>
          </inertia>
        </inertial>
        <collision name='rev2_link_collision'>
          <pose>0 0 0 0 -0 0</pose>
          <geometry>
            <mesh>
              <scale>1 1 1</scale>
              <uri>file:////home/kraiwich/OpenTopic_ws/install/cart_description/share/cart_description/meshes/rev2_link.STL</uri>
            </mesh>
          </geometry>
          <surface>
            <contact>
              <ode/>
            </contact>
            <friction>
              <ode>
                <mu>1000</mu>
                <mu2>1000</mu2>
              </ode>
              <torsional>
                <ode/>
              </torsional>
            </friction>
            <bounce/>
          </surface>
          <max_contacts>10</max_contacts>
        </collision>
        <visual name='rev2_link_visual'>
          <pose>0 0 0 0 -0 0</pose>
          <geometry>
            <mesh>
              <scale>1 1 1</scale>
              <uri>file:////home/kraiwich/OpenTopic_ws/install/cart_description/share/cart_description/meshes/rev2_link.STL</uri>
            </mesh>
          </geometry>
          <material>
            <script>
              <name>Gazebo/White</name>
              <uri>file://media/materials/scripts/gazebo.material</uri>
            </script>
          </material>
        </visual>
        <self_collide>0</self_collide>
        <enable_wind>0</enable_wind>
        <kinematic>0</kinematic>
      </link>
      <joint name='wheel_joint2' type='revolute'>
        <pose relative_to='rev2_link'>-0.025001 0.021001 -0.059 -1.5708 0 0</pose>
        <parent>rev2_link</parent>
        <child>wheel_link2</child>
        <axis>
          <xyz>0 0 -1</xyz>
          <limit>
            <lower>-1e+16</lower>
            <upper>1e+16</upper>
          </limit>
          <dynamics>
            <spring_reference>0</spring_reference>
            <spring_stiffness>0</spring_stiffness>
          </dynamics>
        </axis>
      </joint>
      <link name='wheel_link2'>
        <pose relative_to='wheel_joint2'>0 0 0 0 -0 0</pose>
        <inertial>
          <pose>0 0 -0.021 0 -0 0</pose>
          <mass>3.17935</mass>
          <inertia>
            <ixx>8.27284e-05</ixx>
            <ixy>4.23195e-11</ixy>
            <ixz>3.01176e-10</ixz>
            <iyy>8.27261e-05</iyy>
            <iyz>2.65006e-10</iyz>
            <izz>0.00012509</izz>
          </inertia>
        </inertial>
        <collision name='wheel_link2_collision'>
          <pose>0 0 0 0 -0 0</pose>
          <geometry>
            <mesh>
              <scale>1 1 1</scale>
              <uri>file:////home/kraiwich/OpenTopic_ws/install/cart_description/share/cart_description/meshes/wheel_link2.STL</uri>
            </mesh>
          </geometry>
          <surface>
            <contact>
              <ode/>
            </contact>
            <friction>
              <ode>
                <mu>1000</mu>
                <mu2>1000</mu2>
              </ode>
              <torsional>
                <ode/>
              </torsional>
            </friction>
            <bounce/>
          </surface>
          <max_contacts>10</max_contacts>
        </collision>
        <visual name='wheel_link2_visual'>
          <pose>0 0 0 0 -0 0</pose>
          <geometry>
            <mesh>
              <scale>1 1 1</scale>
              <uri>file:////home/kraiwich/OpenTopic_ws/install/cart_description/share/cart_description/meshes/wheel_link2.STL</uri>
            </mesh>
          </geometry>
          <material>
            <script>
              <name>Gazebo/Black</name>
              <uri>file://media/materials/scripts/gazebo.material</uri>
            </script>
          </material>
        </visual>
        <self_collide>0</self_collide>
        <enable_wind>0</enable_wind>
        <kinematic>0</kinematic>
      </link>
      <joint name='rev3_joint' type='revolute'>
        <pose relative_to='base_footprint'>0.455 -0.360001 0.0965 0 -0 0</pose>
        <parent>base_footprint</parent>
        <child>rev3_link</child>
        <axis>
          <xyz>0 0 -1</xyz>
          <limit>
            <lower>-1e+16</lower>
            <upper>1e+16</upper>
          </limit>
          <dynamics>
            <spring_reference>0</spring_reference>
            <spring_stiffness>0</spring_stiffness>
          </dynamics>
        </axis>
      </joint>
      <link name='rev3_link'>
        <pose relative_to='rev3_joint'>0 0 0 0 -0 0</pose>
        <inertial>
          <pose>-0.008873 -6.6e-05 -0.024908 0 -0 0</pose>
          <mass>1.39604</mass>
          <inertia>
            <ixx>0.000398723</ixx>
            <ixy>-4.27245e-07</ixy>
            <ixz>-6.71828e-05</ixz>
            <iyy>0.000338006</iyy>
            <iyz>-8.97252e-07</iyz>
            <izz>0.000365728</izz>
          </inertia>
        </inertial>
        <collision name='rev3_link_collision'>
          <pose>0 0 0 0 -0 0</pose>
          <geometry>
            <mesh>
              <scale>1 1 1</scale>
              <uri>file:////home/kraiwich/OpenTopic_ws/install/cart_description/share/cart_description/meshes/rev3_link.STL</uri>
            </mesh>
          </geometry>
          <surface>
            <contact>
              <ode/>
            </contact>
            <friction>
              <ode>
                <mu>1000</mu>
                <mu2>1000</mu2>
              </ode>
              <torsional>
                <ode/>
              </torsional>
            </friction>
            <bounce/>
          </surface>
          <max_contacts>10</max_contacts>
        </collision>
        <visual name='rev3_link_visual'>
          <pose>0 0 0 0 -0 0</pose>
          <geometry>
            <mesh>
              <scale>1 1 1</scale>
              <uri>file:////home/kraiwich/OpenTopic_ws/install/cart_description/share/cart_description/meshes/rev3_link.STL</uri>
            </mesh>
          </geometry>
          <material>
            <script>
              <name>Gazebo/White</name>
              <uri>file://media/materials/scripts/gazebo.material</uri>
            </script>
          </material>
        </visual>
        <self_collide>0</self_collide>
        <enable_wind>0</enable_wind>
        <kinematic>0</kinematic>
      </link>
      <joint name='wheel_joint3' type='revolute'>
        <pose relative_to='rev3_link'>-0.025007 -0.020999 -0.058998 -1.5708 0 0</pose>
        <parent>rev3_link</parent>
        <child>wheel_link3</child>
        <axis>
          <xyz>0 0 -1</xyz>
          <limit>
            <lower>-1e+16</lower>
            <upper>1e+16</upper>
          </limit>
          <dynamics>
            <spring_reference>0</spring_reference>
            <spring_stiffness>0</spring_stiffness>
          </dynamics>
        </axis>
      </joint>
      <link name='wheel_link3'>
        <pose relative_to='wheel_joint3'>0 0 0 0 -0 0</pose>
        <inertial>
          <pose>7e-06 2e-06 0.021 0 -0 0</pose>
          <mass>3.17935</mass>
          <inertia>
            <ixx>8.2728e-05</ixx>
            <ixy>-9.2883e-10</ixy>
            <ixz>-2.5882e-10</ixz>
            <iyy>8.2727e-05</iyy>
            <iyz>-4.0977e-11</iyz>
            <izz>0.00012509</izz>
          </inertia>
        </inertial>
        <collision name='wheel_link3_collision'>
          <pose>0 0 0 0 -0 0</pose>
          <geometry>
            <mesh>
              <scale>1 1 1</scale>
              <uri>file:////home/kraiwich/OpenTopic_ws/install/cart_description/share/cart_description/meshes/wheel_link3.STL</uri>
            </mesh>
          </geometry>
          <surface>
            <contact>
              <ode/>
            </contact>
            <friction>
              <ode>
                <mu>1000</mu>
                <mu2>1000</mu2>
              </ode>
              <torsional>
                <ode/>
              </torsional>
            </friction>
            <bounce/>
          </surface>
          <max_contacts>10</max_contacts>
        </collision>
        <visual name='wheel_link3_visual'>
          <pose>0 0 0 0 -0 0</pose>
          <geometry>
            <mesh>
              <scale>1 1 1</scale>
              <uri>file:////home/kraiwich/OpenTopic_ws/install/cart_description/share/cart_description/meshes/wheel_link3.STL</uri>
            </mesh>
          </geometry>
          <material>
            <script>
              <name>Gazebo/Black</name>
              <uri>file://media/materials/scripts/gazebo.material</uri>
            </script>
          </material>
        </visual>
        <self_collide>0</self_collide>
        <enable_wind>0</enable_wind>
        <kinematic>0</kinematic>
      </link>
      <joint name='rev4_joint' type='revolute'>
        <pose relative_to='base_footprint'>-0.455 -0.360001 0.0965 0 -0 0</pose>
        <parent>base_footprint</parent>
        <child>rev4_link</child>
        <axis>
          <xyz>0 0 -1</xyz>
          <limit>
            <lower>-1e+16</lower>
            <upper>1e+16</upper>
          </limit>
          <dynamics>
            <spring_reference>0</spring_reference>
            <spring_stiffness>0</spring_stiffness>
          </dynamics>
        </axis>
      </joint>
      <link name='rev4_link'>
        <pose relative_to='rev4_joint'>0 0 0 0 -0 0</pose>
        <inertial>
          <pose>-0.008873 -6.6e-05 -0.024908 0 -0 0</pose>
          <mass>1.39604</mass>
          <inertia>
            <ixx>0.000398723</ixx>
            <ixy>-4.27245e-07</ixy>
            <ixz>-6.71828e-05</ixz>
            <iyy>0.000338006</iyy>
            <iyz>-8.97252e-07</iyz>
            <izz>0.000365728</izz>
          </inertia>
        </inertial>
        <collision name='rev4_link_collision'>
          <pose>0 0 0 0 -0 0</pose>
          <geometry>
            <mesh>
              <scale>1 1 1</scale>
              <uri>file:////home/kraiwich/OpenTopic_ws/install/cart_description/share/cart_description/meshes/rev4_link.STL</uri>
            </mesh>
          </geometry>
          <surface>
            <contact>
              <ode/>
            </contact>
            <friction>
              <ode>
                <mu>1000</mu>
                <mu2>1000</mu2>
              </ode>
              <torsional>
                <ode/>
              </torsional>
            </friction>
            <bounce/>
          </surface>
          <max_contacts>10</max_contacts>
        </collision>
        <visual name='rev4_link_visual'>
          <pose>0 0 0 0 -0 0</pose>
          <geometry>
            <mesh>
              <scale>1 1 1</scale>
              <uri>file:////home/kraiwich/OpenTopic_ws/install/cart_description/share/cart_description/meshes/rev4_link.STL</uri>
            </mesh>
          </geometry>
          <material>
            <script>
              <name>Gazebo/White</name>
              <uri>file://media/materials/scripts/gazebo.material</uri>
            </script>
          </material>
        </visual>
        <self_collide>0</self_collide>
        <enable_wind>0</enable_wind>
        <kinematic>0</kinematic>
      </link>
      <joint name='wheel_joint4' type='revolute'>
        <pose relative_to='rev4_link'>-0.025007 -0.020999 -0.058998 -1.5708 0 0</pose>
        <parent>rev4_link</parent>
        <child>wheel_link4</child>
        <axis>
          <xyz>0 0 -1</xyz>
          <limit>
            <lower>-1e+16</lower>
            <upper>1e+16</upper>
          </limit>
          <dynamics>
            <spring_reference>0</spring_reference>
            <spring_stiffness>0</spring_stiffness>
          </dynamics>
        </axis>
      </joint>
      <link name='wheel_link4'>
        <pose relative_to='wheel_joint4'>0 0 0 0 -0 0</pose>
        <inertial>
          <pose>7e-06 2e-06 0.021 0 -0 0</pose>
          <mass>3.17935</mass>
          <inertia>
            <ixx>8.27278e-05</ixx>
            <ixy>-9.28827e-10</ixy>
            <ixz>-2.58823e-10</ixz>
            <iyy>8.27267e-05</iyy>
            <iyz>-4.09773e-11</iyz>
            <izz>0.00012509</izz>
          </inertia>
        </inertial>
        <collision name='wheel_link4_collision'>
          <pose>0 0 0 0 -0 0</pose>
          <geometry>
            <mesh>
              <scale>1 1 1</scale>
              <uri>file:////home/kraiwich/OpenTopic_ws/install/cart_description/share/cart_description/meshes/wheel_link4.STL</uri>
            </mesh>
          </geometry>
          <surface>
            <contact>
              <ode/>
            </contact>
            <friction>
              <ode>
                <mu>1000</mu>
                <mu2>1000</mu2>
              </ode>
              <torsional>
                <ode/>
              </torsional>
            </friction>
            <bounce/>
          </surface>
          <max_contacts>10</max_contacts>
        </collision>
        <visual name='wheel_link4_visual'>
          <pose>0 0 0 0 -0 0</pose>
          <geometry>
            <mesh>
              <scale>1 1 1</scale>
              <uri>file:////home/kraiwich/OpenTopic_ws/install/cart_description/share/cart_description/meshes/wheel_link4.STL</uri>
            </mesh>
          </geometry>
          <material>
            <script>
              <name>Gazebo/Black</name>
              <uri>file://media/materials/scripts/gazebo.material</uri>
            </script>
          </material>
        </visual>
        <self_collide>0</self_collide>
        <enable_wind>0</enable_wind>
        <kinematic>0</kinematic>
      </link>
      <pose>-2 -2 0 0 -0 0</pose>
    </model>
  </world>
</sdf>
