<sdf version='1.7'>
  <world name='default'>
    <gravity>0 0 -9.8</gravity>
    <physics name='default_physics' default='0' type='ode'>
      <max_step_size>0.001</max_step_size>
      <real_time_factor>1</real_time_factor>
      <real_time_update_rate>1000</real_time_update_rate>
    </physics>
    <plugin name='ground_truth' filename='libgazebo_ros_p3d.so'>
      <ros>
        <namespace>/world_ground_truth</namespace>
        <remapping>odom:=pose</remapping>
      </ros>
      <body_name>mir_robot::base_link</body_name>
      <frame_name>world</frame_name>
      <update_rate>100.0</update_rate>
    </plugin>
    <model name='aws_robomaker_warehouse_ShelfF_01_001'>
      <frame name='aws_robomaker_warehouse_ShelfF_01::__model__' attached_to='aws_robomaker_warehouse_ShelfF_01::link'>
        <pose relative_to='__model__'>0 0 0 0 -0 0</pose>
      </frame>
      <link name='aws_robomaker_warehouse_ShelfF_01::link'>
        <inertial>
          <mass>30</mass>
          <inertia>
            <ixx>907.144</ixx>
            <ixy>0</ixy>
            <ixz>0</ixz>
            <iyy>104.95</iyy>
            <iyz>0</iyz>
            <izz>824.248</izz>
          </inertia>
        </inertial>
        <collision name='collision'>
          <geometry>
            <mesh>
              <uri>file://models/aws_robomaker_warehouse_ShelfF_01/meshes/aws_robomaker_warehouse_ShelfF_01_collision.DAE</uri>
              <scale>1 1 1</scale>
            </mesh>
          </geometry>
          <surface>
            <friction>
              <ode>
                <mu>0.2</mu>
                <mu2>0.2</mu2>
                <fdir1>0 0 0</fdir1>
                <slip1>0</slip1>
                <slip2>0</slip2>
              </ode>
              <torsional>
                <ode/>
              </torsional>
            </friction>
            <contact>
              <ode/>
            </contact>
            <bounce/>
          </surface>
          <max_contacts>10</max_contacts>
        </collision>
        <visual name='visual'>
          <geometry>
            <mesh>
              <uri>file://models/aws_robomaker_warehouse_ShelfF_01/meshes/aws_robomaker_warehouse_ShelfF_01_visual.DAE</uri>
            </mesh>
          </geometry>
          <meta>
            <layer>1</layer>
          </meta>
        </visual>
        <pose relative_to='aws_robomaker_warehouse_ShelfF_01::__model__'>0 0 0 0 -0 0</pose>
        <self_collide>0</self_collide>
        <enable_wind>0</enable_wind>
        <kinematic>0</kinematic>
      </link>
      <static>1</static>
      <pose>-5.79514 -0.956635 0 0 -0 0</pose>
    </model>
    <model name='aws_robomaker_warehouse_WallB_01_001'>
      <frame name='aws_robomaker_warehouse_WallB_01::__model__' attached_to='aws_robomaker_warehouse_WallB_01::link'>
        <pose relative_to='__model__'>0 0 0 0 -0 0</pose>
      </frame>
      <link name='aws_robomaker_warehouse_WallB_01::link'>
        <inertial>
          <mass>1000</mass>
          <inertia>
            <ixx>840083</ixx>
            <ixy>0</ixy>
            <ixz>0</ixz>
            <iyy>475500</iyy>
            <iyz>0</iyz>
            <izz>1.30208e+06</izz>
          </inertia>
        </inertial>
        <collision name='collision'>
          <geometry>
            <mesh>
              <uri>file://models/aws_robomaker_warehouse_WallB_01/meshes/aws_robomaker_warehouse_WallB_01_collision.DAE</uri>
              <scale>1 1 1</scale>
            </mesh>
          </geometry>
          <surface>
            <friction>
              <ode>
                <mu>0.5</mu>
                <mu2>0.5</mu2>
                <fdir1>0 0 0</fdir1>
                <slip1>0</slip1>
                <slip2>0</slip2>
              </ode>
              <torsional>
                <ode/>
              </torsional>
            </friction>
            <contact>
              <ode/>
            </contact>
            <bounce/>
          </surface>
          <max_contacts>10</max_contacts>
        </collision>
        <visual name='visual'>
          <geometry>
            <mesh>
              <uri>file://models/aws_robomaker_warehouse_WallB_01/meshes/aws_robomaker_warehouse_WallB_01_visual.DAE</uri>
            </mesh>
          </geometry>
          <meta>
            <layer>2</layer>
          </meta>
        </visual>
        <pose relative_to='aws_robomaker_warehouse_WallB_01::__model__'>0 0 0 0 -0 0</pose>
        <self_collide>0</self_collide>
        <enable_wind>0</enable_wind>
        <kinematic>0</kinematic>
      </link>
      <static>1</static>
      <pose>0 0 0 0 -0 0</pose>
    </model>
    <model name='aws_robomaker_warehouse_ShelfE_01_001'>
      <frame name='aws_robomaker_warehouse_ShelfE_01::__model__' attached_to='aws_robomaker_warehouse_ShelfE_01::link'>
        <pose relative_to='__model__'>0 0 0 0 -0 0</pose>
      </frame>
      <link name='aws_robomaker_warehouse_ShelfE_01::link'>
        <inertial>
          <mass>30</mass>
          <inertia>
            <ixx>907.144</ixx>
            <ixy>0</ixy>
            <ixz>0</ixz>
            <iyy>104.95</iyy>
            <iyz>0</iyz>
            <izz>824.248</izz>
          </inertia>
        </inertial>
        <collision name='collision'>
          <geometry>
            <mesh>
              <uri>file://models/aws_robomaker_warehouse_ShelfE_01/meshes/aws_robomaker_warehouse_ShelfE_01_collision.DAE</uri>
              <scale>1 1 1</scale>
            </mesh>
          </geometry>
          <surface>
            <friction>
              <ode>
                <mu>0.2</mu>
                <mu2>0.2</mu2>
                <fdir1>0 0 0</fdir1>
                <slip1>0</slip1>
                <slip2>0</slip2>
              </ode>
              <torsional>
                <ode/>
              </torsional>
            </friction>
            <contact>
              <ode/>
            </contact>
            <bounce/>
          </surface>
          <max_contacts>10</max_contacts>
        </collision>
        <visual name='visual'>
          <geometry>
            <mesh>
              <uri>file://models/aws_robomaker_warehouse_ShelfE_01/meshes/aws_robomaker_warehouse_ShelfE_01_visual.DAE</uri>
            </mesh>
          </geometry>
          <meta>
            <layer>1</layer>
          </meta>
        </visual>
        <pose relative_to='aws_robomaker_warehouse_ShelfE_01::__model__'>0 0 0 0 -0 0</pose>
        <self_collide>0</self_collide>
        <enable_wind>0</enable_wind>
        <kinematic>0</kinematic>
      </link>
      <static>1</static>
      <pose>4.73156 0.57943 0 0 -0 0</pose>
    </model>
    <model name='aws_robomaker_warehouse_ShelfE_01_002'>
      <frame name='aws_robomaker_warehouse_ShelfE_01::__model__' attached_to='aws_robomaker_warehouse_ShelfE_01::link'>
        <pose relative_to='__model__'>0 0 0 0 -0 0</pose>
      </frame>
      <link name='aws_robomaker_warehouse_ShelfE_01::link'>
        <inertial>
          <mass>30</mass>
          <inertia>
            <ixx>907.144</ixx>
            <ixy>0</ixy>
            <ixz>0</ixz>
            <iyy>104.95</iyy>
            <iyz>0</iyz>
            <izz>824.248</izz>
          </inertia>
        </inertial>
        <collision name='collision'>
          <geometry>
            <mesh>
              <uri>file://models/aws_robomaker_warehouse_ShelfE_01/meshes/aws_robomaker_warehouse_ShelfE_01_collision.DAE</uri>
              <scale>1 1 1</scale>
            </mesh>
          </geometry>
          <surface>
            <friction>
              <ode>
                <mu>0.2</mu>
                <mu2>0.2</mu2>
                <fdir1>0 0 0</fdir1>
                <slip1>0</slip1>
                <slip2>0</slip2>
              </ode>
              <torsional>
                <ode/>
              </torsional>
            </friction>
            <contact>
              <ode/>
            </contact>
            <bounce/>
          </surface>
          <max_contacts>10</max_contacts>
        </collision>
        <visual name='visual'>
          <geometry>
            <mesh>
              <uri>file://models/aws_robomaker_warehouse_ShelfE_01/meshes/aws_robomaker_warehouse_ShelfE_01_visual.DAE</uri>
            </mesh>
          </geometry>
          <meta>
            <layer>1</layer>
          </meta>
        </visual>
        <pose relative_to='aws_robomaker_warehouse_ShelfE_01::__model__'>0 0 0 0 -0 0</pose>
        <self_collide>0</self_collide>
        <enable_wind>0</enable_wind>
        <kinematic>0</kinematic>
      </link>
      <static>1</static>
      <pose>4.73156 -4.82705 0 0 -0 0</pose>
    </model>
    <model name='aws_robomaker_warehouse_ShelfD_01_002'>
      <frame name='aws_robomaker_warehouse_ShelfD_01::__model__' attached_to='aws_robomaker_warehouse_ShelfD_01::link'>
        <pose relative_to='__model__'>0 0 0 0 -0 0</pose>
      </frame>
      <link name='aws_robomaker_warehouse_ShelfD_01::link'>
        <inertial>
          <mass>30</mass>
          <inertia>
            <ixx>907.144</ixx>
            <ixy>0</ixy>
            <ixz>0</ixz>
            <iyy>104.95</iyy>
            <iyz>0</iyz>
            <izz>824.248</izz>
          </inertia>
        </inertial>
        <collision name='collision'>
          <geometry>
            <mesh>
              <uri>file://models/aws_robomaker_warehouse_ShelfD_01/meshes/aws_robomaker_warehouse_ShelfD_01_collision.DAE</uri>
              <scale>1 1 1</scale>
            </mesh>
          </geometry>
          <surface>
            <friction>
              <ode>
                <mu>0.2</mu>
                <mu2>0.2</mu2>
                <fdir1>0 0 0</fdir1>
                <slip1>0</slip1>
                <slip2>0</slip2>
              </ode>
              <torsional>
                <ode/>
              </torsional>
            </friction>
            <contact>
              <ode/>
            </contact>
            <bounce/>
          </surface>
          <max_contacts>10</max_contacts>
        </collision>
        <visual name='visual'>
          <geometry>
            <mesh>
              <uri>file://models/aws_robomaker_warehouse_ShelfD_01/meshes/aws_robomaker_warehouse_ShelfD_01_visual.DAE</uri>
            </mesh>
          </geometry>
          <meta>
            <layer>1</layer>
          </meta>
        </visual>
        <pose relative_to='aws_robomaker_warehouse_ShelfD_01::__model__'>0 0 0 0 -0 0</pose>
        <self_collide>0</self_collide>
        <enable_wind>0</enable_wind>
        <kinematic>0</kinematic>
      </link>
      <static>1</static>
      <pose>4.73156 -3.03855 0 0 -0 0</pose>
    </model>
    <model name='aws_robomaker_warehouse_GroundB_01_001'>
      <frame name='aws_robomaker_warehouse_GroundB_01::__model__' attached_to='aws_robomaker_warehouse_GroundB_01::link'>
        <pose relative_to='__model__'>0 0 0 0 -0 0</pose>
      </frame>
      <link name='aws_robomaker_warehouse_GroundB_01::link'>
        <inertial>
          <mass>1000</mass>
          <inertia>
            <ixx>1.20008e+06</ixx>
            <ixy>0</ixy>
            <ixz>0</ixz>
            <iyy>8.33342e+06</iyy>
            <iyz>0</iyz>
            <izz>2.03333e+06</izz>
          </inertia>
        </inertial>
        <collision name='collision'>
          <geometry>
            <mesh>
              <uri>file://models/aws_robomaker_warehouse_GroundB_01/meshes/aws_robomaker_warehouse_GroundB_01_collision.DAE</uri>
              <scale>1 1 1</scale>
            </mesh>
          </geometry>
          <surface>
            <friction>
              <ode>
                <mu>100</mu>
                <mu2>50</mu2>
                <fdir1>0 0 0</fdir1>
                <slip1>0</slip1>
                <slip2>0</slip2>
              </ode>
              <torsional>
                <ode/>
              </torsional>
            </friction>
            <contact>
              <ode/>
            </contact>
            <bounce/>
          </surface>
          <max_contacts>10</max_contacts>
        </collision>
        <visual name='visual'>
          <geometry>
            <mesh>
              <uri>file://models/aws_robomaker_warehouse_GroundB_01/meshes/aws_robomaker_warehouse_GroundB_01_visual.DAE</uri>
            </mesh>
          </geometry>
          <meta>
            <layer>1</layer>
          </meta>
        </visual>
        <pose relative_to='aws_robomaker_warehouse_GroundB_01::__model__'>0 0 0 0 -0 0</pose>
        <self_collide>0</self_collide>
        <enable_wind>0</enable_wind>
        <kinematic>0</kinematic>
      </link>
      <static>1</static>
      <pose>0 0 -0.090092 0 -0 0</pose>
    </model>
    <model name='aws_robomaker_warehouse_Lamp_01_005'>
      <frame name='aws_robomaker_warehouse_Lamp_01::__model__' attached_to='aws_robomaker_warehouse_Lamp_01::link'>
        <pose relative_to='__model__'>0 0 0 0 -0 0</pose>
      </frame>
      <link name='aws_robomaker_warehouse_Lamp_01::link'>
        <inertial>
          <mass>30</mass>
          <inertia>
            <ixx>907.144</ixx>
            <ixy>0</ixy>
            <ixz>0</ixz>
            <iyy>104.95</iyy>
            <iyz>0</iyz>
            <izz>824.248</izz>
          </inertia>
        </inertial>
        <collision name='collision'>
          <geometry>
            <mesh>
              <uri>file://models/aws_robomaker_warehouse_Lamp_01/meshes/aws_robomaker_warehouse_Lamp_01_collision.DAE</uri>
              <scale>1 1 1</scale>
            </mesh>
          </geometry>
          <surface>
            <friction>
              <ode>
                <mu>0.2</mu>
                <mu2>0.2</mu2>
                <fdir1>0 0 0</fdir1>
                <slip1>0</slip1>
                <slip2>0</slip2>
              </ode>
              <torsional>
                <ode/>
              </torsional>
            </friction>
            <contact>
              <ode/>
            </contact>
            <bounce/>
          </surface>
          <max_contacts>10</max_contacts>
        </collision>
        <visual name='visual'>
          <geometry>
            <mesh>
              <uri>file://models/aws_robomaker_warehouse_Lamp_01/meshes/aws_robomaker_warehouse_Lamp_01_visual.DAE</uri>
            </mesh>
          </geometry>
          <meta>
            <layer>1</layer>
          </meta>
        </visual>
        <pose relative_to='aws_robomaker_warehouse_Lamp_01::__model__'>0 0 0 0 -0 0</pose>
        <self_collide>0</self_collide>
        <enable_wind>0</enable_wind>
        <kinematic>0</kinematic>
      </link>
      <static>1</static>
      <pose>0 0 -4 0 -0 0</pose>
    </model>
    <model name='aws_robomaker_warehouse_Bucket_01_020'>
      <frame name='aws_robomaker_warehouse_Bucket_01::__model__' attached_to='aws_robomaker_warehouse_Bucket_01::body'>
        <pose relative_to='__model__'>0 0 0 0 -0 0</pose>
      </frame>
      <link name='aws_robomaker_warehouse_Bucket_01::body'>
        <inertial>
          <mass>2</mass>
          <pose>0 0 0 0 -0 0</pose>
          <inertia>
            <ixx>0.57</ixx>
            <ixy>0</ixy>
            <ixz>0</ixz>
            <iyy>0.474</iyy>
            <iyz>0</iyz>
            <izz>0.391</izz>
          </inertia>
        </inertial>
        <pose relative_to='aws_robomaker_warehouse_Bucket_01::__model__'>0 0 0 0 -0 0</pose>
        <self_collide>0</self_collide>
        <kinematic>0</kinematic>
        <gravity>1</gravity>
        <visual name='visual'>
          <geometry>
            <mesh>
              <uri>file://models/aws_robomaker_warehouse_Bucket_01/meshes/aws_robomaker_warehouse_Bucket_01_visual.DAE</uri>
            </mesh>
          </geometry>
          <meta>
            <layer>1</layer>
          </meta>
        </visual>
        <collision name='collision_0'>
          <laser_retro>0</laser_retro>
          <max_contacts>10</max_contacts>
          <pose>0 0 0 0 -0 0</pose>
          <geometry>
            <mesh>
              <uri>file://models/aws_robomaker_warehouse_Bucket_01/meshes/aws_robomaker_warehouse_Bucket_01_collision.DAE</uri>
              <scale>1 1 1</scale>
            </mesh>
          </geometry>
          <surface>
            <friction>
              <ode>
                <mu>0.4</mu>
                <mu2>0.4</mu2>
                <fdir1>0 0 0</fdir1>
                <slip1>0</slip1>
                <slip2>0</slip2>
              </ode>
              <torsional>
                <coefficient>1</coefficient>
                <patch_radius>0</patch_radius>
                <surface_radius>0</surface_radius>
                <use_patch_radius>1</use_patch_radius>
                <ode>
                  <slip>0</slip>
                </ode>
              </torsional>
            </friction>
            <contact>
              <ode/>
            </contact>
            <bounce/>
          </surface>
        </collision>
        <enable_wind>0</enable_wind>
      </link>
      <static>1</static>
      <pose>0.433449 9.63171 0 0 0 -1.56316</pose>
    </model>
    <model name='aws_robomaker_warehouse_Bucket_01_021'>
      <frame name='aws_robomaker_warehouse_Bucket_01::__model__' attached_to='aws_robomaker_warehouse_Bucket_01::body'>
        <pose relative_to='__model__'>0 0 0 0 -0 0</pose>
      </frame>
      <link name='aws_robomaker_warehouse_Bucket_01::body'>
        <inertial>
          <mass>2</mass>
          <pose>0 0 0 0 -0 0</pose>
          <inertia>
            <ixx>0.57</ixx>
            <ixy>0</ixy>
            <ixz>0</ixz>
            <iyy>0.474</iyy>
            <iyz>0</iyz>
            <izz>0.391</izz>
          </inertia>
        </inertial>
        <pose relative_to='aws_robomaker_warehouse_Bucket_01::__model__'>0 0 0 0 -0 0</pose>
        <self_collide>0</self_collide>
        <kinematic>0</kinematic>
        <gravity>1</gravity>
        <visual name='visual'>
          <geometry>
            <mesh>
              <uri>file://models/aws_robomaker_warehouse_Bucket_01/meshes/aws_robomaker_warehouse_Bucket_01_visual.DAE</uri>
            </mesh>
          </geometry>
          <meta>
            <layer>1</layer>
          </meta>
        </visual>
        <collision name='collision_0'>
          <laser_retro>0</laser_retro>
          <max_contacts>10</max_contacts>
          <pose>0 0 0 0 -0 0</pose>
          <geometry>
            <mesh>
              <uri>file://models/aws_robomaker_warehouse_Bucket_01/meshes/aws_robomaker_warehouse_Bucket_01_collision.DAE</uri>
              <scale>1 1 1</scale>
            </mesh>
          </geometry>
          <surface>
            <friction>
              <ode>
                <mu>0.4</mu>
                <mu2>0.4</mu2>
                <fdir1>0 0 0</fdir1>
                <slip1>0</slip1>
                <slip2>0</slip2>
              </ode>
              <torsional>
                <coefficient>1</coefficient>
                <patch_radius>0</patch_radius>
                <surface_radius>0</surface_radius>
                <use_patch_radius>1</use_patch_radius>
                <ode>
                  <slip>0</slip>
                </ode>
              </torsional>
            </friction>
            <contact>
              <ode/>
            </contact>
            <bounce/>
          </surface>
        </collision>
        <enable_wind>0</enable_wind>
      </link>
      <static>1</static>
      <pose>-1.8321 -6.3752 0 0 0 -1.56316</pose>
    </model>
    <model name='aws_robomaker_warehouse_ClutteringA_01_016'>
      <frame name='aws_robomaker_warehouse_ClutteringA_01::__model__' attached_to='aws_robomaker_warehouse_ClutteringA_01::link'>
        <pose relative_to='__model__'>0 0 0 0 -0 0</pose>
      </frame>
      <link name='aws_robomaker_warehouse_ClutteringA_01::link'>
        <inertial>
          <mass>2</mass>
          <inertia>
            <ixx>0.841</ixx>
            <ixy>0</ixy>
            <ixz>0</ixz>
            <iyy>0.954</iyy>
            <iyz>0</iyz>
            <izz>1.422</izz>
          </inertia>
        </inertial>
        <collision name='collision'>
          <geometry>
            <mesh>
              <uri>file://models/aws_robomaker_warehouse_ClutteringA_01/meshes/aws_robomaker_warehouse_ClutteringA_01_collision.DAE</uri>
              <scale>1 1 1</scale>
            </mesh>
          </geometry>
          <surface>
            <friction>
              <ode>
                <mu>0.6</mu>
                <mu2>0.6</mu2>
                <fdir1>0 0 0</fdir1>
                <slip1>0</slip1>
                <slip2>0</slip2>
              </ode>
              <torsional>
                <coefficient>1</coefficient>
                <patch_radius>0</patch_radius>
                <surface_radius>0</surface_radius>
                <use_patch_radius>1</use_patch_radius>
                <ode>
                  <slip>0</slip>
                </ode>
              </torsional>
            </friction>
            <contact>
              <ode/>
            </contact>
            <bounce/>
          </surface>
          <max_contacts>10</max_contacts>
        </collision>
        <visual name='visual'>
          <geometry>
            <mesh>
              <uri>file://models/aws_robomaker_warehouse_ClutteringA_01/meshes/aws_robomaker_warehouse_ClutteringA_01_visual.DAE</uri>
            </mesh>
          </geometry>
          <meta>
            <layer>1</layer>
          </meta>
        </visual>
        <pose relative_to='aws_robomaker_warehouse_ClutteringA_01::__model__'>0 0 0 0 -0 0</pose>
        <self_collide>0</self_collide>
        <enable_wind>0</enable_wind>
        <kinematic>0</kinematic>
      </link>
      <static>1</static>
      <pose>5.70814 8.61684 -0.017477 0 -0 0</pose>
    </model>
    <model name='aws_robomaker_warehouse_ClutteringA_01_017'>
      <frame name='aws_robomaker_warehouse_ClutteringA_01::__model__' attached_to='aws_robomaker_warehouse_ClutteringA_01::link'>
        <pose relative_to='__model__'>0 0 0 0 -0 0</pose>
      </frame>
      <link name='aws_robomaker_warehouse_ClutteringA_01::link'>
        <inertial>
          <mass>2</mass>
          <inertia>
            <ixx>0.841</ixx>
            <ixy>0</ixy>
            <ixz>0</ixz>
            <iyy>0.954</iyy>
            <iyz>0</iyz>
            <izz>1.422</izz>
          </inertia>
        </inertial>
        <collision name='collision'>
          <geometry>
            <mesh>
              <uri>file://models/aws_robomaker_warehouse_ClutteringA_01/meshes/aws_robomaker_warehouse_ClutteringA_01_collision.DAE</uri>
              <scale>1 1 1</scale>
            </mesh>
          </geometry>
          <surface>
            <friction>
              <ode>
                <mu>0.6</mu>
                <mu2>0.6</mu2>
                <fdir1>0 0 0</fdir1>
                <slip1>0</slip1>
                <slip2>0</slip2>
              </ode>
              <torsional>
                <coefficient>1</coefficient>
                <patch_radius>0</patch_radius>
                <surface_radius>0</surface_radius>
                <use_patch_radius>1</use_patch_radius>
                <ode>
                  <slip>0</slip>
                </ode>
              </torsional>
            </friction>
            <contact>
              <ode/>
            </contact>
            <bounce/>
          </surface>
          <max_contacts>10</max_contacts>
        </collision>
        <visual name='visual'>
          <geometry>
            <mesh>
              <uri>file://models/aws_robomaker_warehouse_ClutteringA_01/meshes/aws_robomaker_warehouse_ClutteringA_01_visual.DAE</uri>
            </mesh>
          </geometry>
          <meta>
            <layer>1</layer>
          </meta>
        </visual>
        <pose relative_to='aws_robomaker_warehouse_ClutteringA_01::__model__'>0 0 0 0 -0 0</pose>
        <self_collide>0</self_collide>
        <enable_wind>0</enable_wind>
        <kinematic>0</kinematic>
      </link>
      <static>1</static>
      <pose>3.40864 8.61684 -0.017477 0 -0 0</pose>
    </model>
    <model name='aws_robomaker_warehouse_ClutteringC_01_027'>
      <frame name='aws_robomaker_warehouse_ClutteringC_01::__model__' attached_to='aws_robomaker_warehouse_ClutteringC_01::link'>
        <pose relative_to='__model__'>0 0 0 0 -0 0</pose>
      </frame>
      <link name='aws_robomaker_warehouse_ClutteringC_01::link'>
        <inertial>
          <mass>1</mass>
          <inertia>
            <ixx>1.558</ixx>
            <ixy>0</ixy>
            <ixz>0</ixz>
            <iyy>1.821</iyy>
            <iyz>0</iyz>
            <izz>1.892</izz>
          </inertia>
        </inertial>
        <collision name='collision'>
          <geometry>
            <mesh>
              <uri>file://models/aws_robomaker_warehouse_ClutteringC_01/meshes/aws_robomaker_warehouse_ClutteringC_01_collision.DAE</uri>
              <scale>1 1 1</scale>
            </mesh>
          </geometry>
          <surface>
            <friction>
              <ode>
                <mu>0.6</mu>
                <mu2>0.6</mu2>
                <fdir1>0 0 0</fdir1>
                <slip1>0</slip1>
                <slip2>0</slip2>
              </ode>
              <torsional>
                <coefficient>1</coefficient>
                <patch_radius>0</patch_radius>
                <surface_radius>0</surface_radius>
                <use_patch_radius>1</use_patch_radius>
                <ode>
                  <slip>0</slip>
                </ode>
              </torsional>
            </friction>
            <contact>
              <ode/>
            </contact>
            <bounce/>
          </surface>
          <max_contacts>10</max_contacts>
        </collision>
        <visual name='visual'>
          <geometry>
            <mesh>
              <uri>file://models/aws_robomaker_warehouse_ClutteringC_01/meshes/aws_robomaker_warehouse_ClutteringC_01_visual.DAE</uri>
            </mesh>
          </geometry>
          <meta>
            <layer>1</layer>
          </meta>
        </visual>
        <pose relative_to='aws_robomaker_warehouse_ClutteringC_01::__model__'>0 0 0 0 -0 0</pose>
        <self_collide>0</self_collide>
        <enable_wind>0</enable_wind>
        <kinematic>0</kinematic>
      </link>
      <static>1</static>
      <pose>3.32496 3.82245 -0.012064 0 -0 1.56387</pose>
    </model>
    <model name='aws_robomaker_warehouse_ClutteringC_01_028'>
      <frame name='aws_robomaker_warehouse_ClutteringC_01::__model__' attached_to='aws_robomaker_warehouse_ClutteringC_01::link'>
        <pose relative_to='__model__'>0 0 0 0 -0 0</pose>
      </frame>
      <link name='aws_robomaker_warehouse_ClutteringC_01::link'>
        <inertial>
          <mass>1</mass>
          <inertia>
            <ixx>1.558</ixx>
            <ixy>0</ixy>
            <ixz>0</ixz>
            <iyy>1.821</iyy>
            <iyz>0</iyz>
            <izz>1.892</izz>
          </inertia>
        </inertial>
        <collision name='collision'>
          <geometry>
            <mesh>
              <uri>file://models/aws_robomaker_warehouse_ClutteringC_01/meshes/aws_robomaker_warehouse_ClutteringC_01_collision.DAE</uri>
              <scale>1 1 1</scale>
            </mesh>
          </geometry>
          <surface>
            <friction>
              <ode>
                <mu>0.6</mu>
                <mu2>0.6</mu2>
                <fdir1>0 0 0</fdir1>
                <slip1>0</slip1>
                <slip2>0</slip2>
              </ode>
              <torsional>
                <coefficient>1</coefficient>
                <patch_radius>0</patch_radius>
                <surface_radius>0</surface_radius>
                <use_patch_radius>1</use_patch_radius>
                <ode>
                  <slip>0</slip>
                </ode>
              </torsional>
            </friction>
            <contact>
              <ode/>
            </contact>
            <bounce/>
          </surface>
          <max_contacts>10</max_contacts>
        </collision>
        <visual name='visual'>
          <geometry>
            <mesh>
              <uri>file://models/aws_robomaker_warehouse_ClutteringC_01/meshes/aws_robomaker_warehouse_ClutteringC_01_visual.DAE</uri>
            </mesh>
          </geometry>
          <meta>
            <layer>1</layer>
          </meta>
        </visual>
        <pose relative_to='aws_robomaker_warehouse_ClutteringC_01::__model__'>0 0 0 0 -0 0</pose>
        <self_collide>0</self_collide>
        <enable_wind>0</enable_wind>
        <kinematic>0</kinematic>
      </link>
      <static>1</static>
      <pose>5.54171 3.81648 -0.015663 0 0 -1.58319</pose>
    </model>
    <model name='aws_robomaker_warehouse_ClutteringC_01_032'>
      <frame name='aws_robomaker_warehouse_ClutteringC_01::__model__' attached_to='aws_robomaker_warehouse_ClutteringC_01::link'>
        <pose relative_to='__model__'>0 0 0 0 -0 0</pose>
      </frame>
      <link name='aws_robomaker_warehouse_ClutteringC_01::link'>
        <inertial>
          <mass>1</mass>
          <inertia>
            <ixx>1.558</ixx>
            <ixy>0</ixy>
            <ixz>0</ixz>
            <iyy>1.821</iyy>
            <iyz>0</iyz>
            <izz>1.892</izz>
          </inertia>
        </inertial>
        <collision name='collision'>
          <geometry>
            <mesh>
              <uri>file://models/aws_robomaker_warehouse_ClutteringC_01/meshes/aws_robomaker_warehouse_ClutteringC_01_collision.DAE</uri>
              <scale>1 1 1</scale>
            </mesh>
          </geometry>
          <surface>
            <friction>
              <ode>
                <mu>0.6</mu>
                <mu2>0.6</mu2>
                <fdir1>0 0 0</fdir1>
                <slip1>0</slip1>
                <slip2>0</slip2>
              </ode>
              <torsional>
                <coefficient>1</coefficient>
                <patch_radius>0</patch_radius>
                <surface_radius>0</surface_radius>
                <use_patch_radius>1</use_patch_radius>
                <ode>
                  <slip>0</slip>
                </ode>
              </torsional>
            </friction>
            <contact>
              <ode/>
            </contact>
            <bounce/>
          </surface>
          <max_contacts>10</max_contacts>
        </collision>
        <visual name='visual'>
          <geometry>
            <mesh>
              <uri>file://models/aws_robomaker_warehouse_ClutteringC_01/meshes/aws_robomaker_warehouse_ClutteringC_01_visual.DAE</uri>
            </mesh>
          </geometry>
          <meta>
            <layer>1</layer>
          </meta>
        </visual>
        <pose relative_to='aws_robomaker_warehouse_ClutteringC_01::__model__'>0 0 0 0 -0 0</pose>
        <self_collide>0</self_collide>
        <enable_wind>0</enable_wind>
        <kinematic>0</kinematic>
      </link>
      <static>1</static>
      <pose>-1.2196 9.407 -0.015663 0 -0 1.56387</pose>
    </model>
    <model name='aws_robomaker_warehouse_ClutteringD_01_005'>
      <frame name='aws_robomaker_warehouse_ClutteringD_01::__model__' attached_to='aws_robomaker_warehouse_ClutteringD_01::link'>
        <pose relative_to='__model__'>0 0 0 0 -0 0</pose>
      </frame>
      <link name='aws_robomaker_warehouse_ClutteringD_01::link'>
        <inertial>
          <mass>1</mass>
          <inertia>
            <ixx>1.558</ixx>
            <ixy>0</ixy>
            <ixz>0</ixz>
            <iyy>1.821</iyy>
            <iyz>0</iyz>
            <izz>1.892</izz>
          </inertia>
        </inertial>
        <collision name='collision'>
          <geometry>
            <mesh>
              <uri>file://models/aws_robomaker_warehouse_ClutteringD_01/meshes/aws_robomaker_warehouse_ClutteringD_01_collision.DAE</uri>
              <scale>1 1 1</scale>
            </mesh>
          </geometry>
          <surface>
            <friction>
              <ode>
                <mu>0.6</mu>
                <mu2>0.6</mu2>
                <fdir1>0 0 0</fdir1>
                <slip1>0</slip1>
                <slip2>0</slip2>
              </ode>
              <torsional>
                <coefficient>1</coefficient>
                <patch_radius>0</patch_radius>
                <surface_radius>0</surface_radius>
                <use_patch_radius>1</use_patch_radius>
                <ode>
                  <slip>0</slip>
                </ode>
              </torsional>
            </friction>
            <contact>
              <ode/>
            </contact>
            <bounce/>
          </surface>
          <max_contacts>10</max_contacts>
        </collision>
        <visual name='visual'>
          <geometry>
            <mesh>
              <uri>file://models/aws_robomaker_warehouse_ClutteringD_01/meshes/aws_robomaker_warehouse_ClutteringD_01_visual.DAE</uri>
            </mesh>
          </geometry>
          <meta>
            <layer>1</layer>
          </meta>
        </visual>
        <pose relative_to='aws_robomaker_warehouse_ClutteringD_01::__model__'>0 0 0 0 -0 0</pose>
        <self_collide>0</self_collide>
        <enable_wind>0</enable_wind>
        <kinematic>0</kinematic>
      </link>
      <static>1</static>
      <pose>-1.63468 -7.81181 -0.319559 0 -0 0</pose>
    </model>
    <light name='Warehouse_CeilingLight_003' type='point'>
      <pose>0 0 9 0 -0 0</pose>
      <diffuse>0.5 0.5 0.5 1</diffuse>
      <specular>0.2 0.2 0.2 1</specular>
      <attenuation>
        <range>80</range>
        <constant>0.3</constant>
        <linear>0.01</linear>
        <quadratic>0.001</quadratic>
      </attenuation>
      <cast_shadows>1</cast_shadows>
      <direction>0.1 0.1 -1</direction>
      <spot>
        <inner_angle>0</inner_angle>
        <outer_angle>0</outer_angle>
        <falloff>0</falloff>
      </spot>
    </light>
    <gui fullscreen='0'>
      <camera name='user_camera'>
        <pose>-1.10421 0.734139 9.79219 0 1.5698 0.006014</pose>
        <view_controller>orbit</view_controller>
        <projection_type>perspective</projection_type>
      </camera>
    </gui>
    <magnetic_field>6e-06 2.3e-05 -4.2e-05</magnetic_field>
    <atmosphere type='adiabatic'/>
    <scene>
      <ambient>0.4 0.4 0.4 1</ambient>
      <background>0.7 0.7 0.7 1</background>
      <shadows>1</shadows>
    </scene>
    <audio>
      <device>default</device>
    </audio>
    <wind/>
    <spherical_coordinates>
      <surface_model>EARTH_WGS84</surface_model>
      <latitude_deg>0</latitude_deg>
      <longitude_deg>0</longitude_deg>
      <elevation>0</elevation>
      <heading_deg>0</heading_deg>
    </spherical_coordinates>
    <model name='mir_robot'>
      <link name='base_footprint'>
        <inertial>
          <pose>-0.009572 1.7e-05 0.152334 0 -0 0</pose>
          <mass>70.96</mass>
          <inertia>
            <ixx>0.973179</ixx>
            <ixy>-0.369183</ixy>
            <ixz>-0.00771231</ixz>
            <iyy>2.26736</iyy>
            <iyz>-4.68795e-05</iyz>
            <izz>2.75838</izz>
          </inertia>
        </inertial>
        <collision name='base_footprint_fixed_joint_lump__base_link_collision'>
          <pose>0.037646 0 0 0 -0 0</pose>
          <geometry>
            <mesh>
              <scale>1 1 1</scale>
              <uri>model://mir_description/meshes/collision/mir_100_base.stl</uri>
            </mesh>
          </geometry>
          <surface>
            <contact>
              <ode/>
            </contact>
            <friction>
              <ode/>
              <torsional>
                <ode/>
              </torsional>
            </friction>
            <bounce/>
          </surface>
          <max_contacts>10</max_contacts>
        </collision>
        <collision name='base_footprint_fixed_joint_lump__back_laser_link_collision_1'>
          <pose>-0.3548 -0.2352 0.1914 3.14159 -0 -2.35619</pose>
          <geometry>
            <mesh>
              <scale>1 1 1</scale>
              <uri>model://mir_description/meshes/visual/sick_lms-100.stl</uri>
            </mesh>
          </geometry>
          <surface>
            <contact>
              <ode/>
            </contact>
            <friction>
              <ode/>
              <torsional>
                <ode/>
              </torsional>
            </friction>
            <bounce/>
          </surface>
          <max_contacts>10</max_contacts>
        </collision>
        <collision name='base_footprint_fixed_joint_lump__front_laser_link_collision_2'>
          <pose>0.4288 0.2358 0.1914 3.14159 -0 0.785398</pose>
          <geometry>
            <mesh>
              <scale>1 1 1</scale>
              <uri>model://mir_description/meshes/visual/sick_lms-100.stl</uri>
            </mesh>
          </geometry>
          <surface>
            <contact>
              <ode/>
            </contact>
            <friction>
              <ode/>
              <torsional>
                <ode/>
              </torsional>
            </friction>
            <bounce/>
          </surface>
          <max_contacts>10</max_contacts>
        </collision>
        <visual name='base_footprint_fixed_joint_lump__base_link_visual'>
          <pose>0.037646 0 0 0 -0 0</pose>
          <geometry>
            <mesh>
              <scale>1 1 1</scale>
              <uri>model://mir_description/meshes/visual/mir_100_base.stl</uri>
            </mesh>
          </geometry>
          <material>
            <script>
              <name>Gazebo/White</name>
              <uri>file://media/materials/scripts/gazebo.material</uri>
            </script>
          </material>
        </visual>
        <visual name='base_footprint_fixed_joint_lump__back_laser_link_visual_1'>
          <pose>-0.3548 -0.2352 0.1914 3.14159 -0 -2.35619</pose>
          <geometry>
            <mesh>
              <scale>1 1 1</scale>
              <uri>model://mir_description/meshes/visual/sick_lms-100.stl</uri>
            </mesh>
          </geometry>
          <material>
            <script>
              <name>Gazebo/FlatBlack</name>
              <uri>file://media/materials/scripts/gazebo.material</uri>
            </script>
          </material>
        </visual>
        <visual name='base_footprint_fixed_joint_lump__camera_link_visual_2'>
          <pose>0.465 0 0.28 0 -0 0</pose>
          <geometry>
            <box>
              <size>0.01 0.13 0.03</size>
            </box>
          </geometry>
          <material>
            <script>
              <name>Gazebo/Red</name>
              <uri>file://media/materials/scripts/gazebo.material</uri>
            </script>
          </material>
        </visual>
        <visual name='base_footprint_fixed_joint_lump__front_laser_link_visual_3'>
          <pose>0.4288 0.2358 0.1914 3.14159 -0 0.785398</pose>
          <geometry>
            <mesh>
              <scale>1 1 1</scale>
              <uri>model://mir_description/meshes/visual/sick_lms-100.stl</uri>
            </mesh>
          </geometry>
          <material>
            <script>
              <name>Gazebo/FlatBlack</name>
              <uri>file://media/materials/scripts/gazebo.material</uri>
            </script>
          </material>
        </visual>
        <sensor name='back_laser_link' type='ray'>
          <visualize>0</visualize>
          <update_rate>12.5</update_rate>
          <ray>
            <scan>
              <horizontal>
                <samples>541</samples>
                <resolution>1</resolution>
                <min_angle>-2.35619</min_angle>
                <max_angle>2.35619</max_angle>
              </horizontal>
              <vertical>
                <samples>1</samples>
                <min_angle>0</min_angle>
                <max_angle>0</max_angle>
              </vertical>
            </scan>
            <range>
              <min>0.05</min>
              <max>29</max>
              <resolution>0.01</resolution>
            </range>
            <noise>
              <type>gaussian</type>
              <mean>0</mean>
              <stddev>0.01</stddev>
            </noise>
          </ray>
          <plugin name='gazebo_ros_back_laser_link_controller' filename='libgazebo_ros_ray_sensor.so'>
            <ros>
              <remapping>~/out:=b_scan</remapping>
            </ros>
            <output_type>sensor_msgs/LaserScan</output_type>
            <frame_name>back_laser_link</frame_name>
          </plugin>
          <pose>-0.3548 -0.2352 0.1914 0 0 -2.35619</pose>
        </sensor>
        <sensor name='depth_camera' type='depth'>
          <visualize>1</visualize>
          <update_rate>10</update_rate>
          <plugin name='depth_camera_controller' filename='libgazebo_ros_camera.so'>
            <always_on>1</always_on>
            <update_rate>10.0</update_rate>
            <camera_name>depth_camera</camera_name>
            <frame_name>camera_link_optical</frame_name>
            <topic_name>camera/depth/image_raw</topic_name>
          </plugin>
          <plugin name='point_cloud_plugin' filename='libgazebo_ros_point_cloud.so'>
            <always_on>1</always_on>
            <update_rate>10.0</update_rate>
            <frame_name>camera_link_optical</frame_name>
            <topic_name>camera/depth/points</topic_name>
          </plugin>
          <pose>0.465 0 0.28 0 -0 0</pose>
          <camera>
            <horizontal_fov>1.047</horizontal_fov>
            <image>
              <width>320</width>
              <height>240</height>
            </image>
            <clip>
              <near>0.1</near>
              <far>100</far>
            </clip>
          </camera>
          <depth_camera>
            <horizontal_fov>1.089</horizontal_fov>
            <image>
              <format>FLOAT32</format>
              <width>640</width>
              <height>480</height>
            </image>
            <clip>
              <near>0.05</near>
              <far>8.0</far>
            </clip>
          </depth_camera>
        </sensor>
        <sensor name='front_laser_link' type='ray'>
          <visualize>0</visualize>
          <update_rate>12.5</update_rate>
          <ray>
            <scan>
              <horizontal>
                <samples>541</samples>
                <resolution>1</resolution>
                <min_angle>-2.35619</min_angle>
                <max_angle>2.35619</max_angle>
              </horizontal>
              <vertical>
                <samples>1</samples>
                <min_angle>0</min_angle>
                <max_angle>0</max_angle>
              </vertical>
            </scan>
            <range>
              <min>0.05</min>
              <max>29</max>
              <resolution>0.01</resolution>
            </range>
            <noise>
              <type>gaussian</type>
              <mean>0</mean>
              <stddev>0.01</stddev>
            </noise>
          </ray>
          <plugin name='gazebo_ros_front_laser_link_controller' filename='libgazebo_ros_ray_sensor.so'>
            <ros>
              <remapping>~/out:=f_scan</remapping>
            </ros>
            <output_type>sensor_msgs/LaserScan</output_type>
            <frame_name>front_laser_link</frame_name>
          </plugin>
          <pose>0.4288 0.2358 0.1914 0 -0 0.785398</pose>
        </sensor>
        <gravity>1</gravity>
        <sensor name='imu_sensor' type='imu'>
          <always_on>1</always_on>
          <update_rate>50</update_rate>
          <visualize>1</visualize>
          <imu>
            <angular_velocity>
              <x>
                <noise type='gaussian'>
                  <mean>0</mean>
                  <stddev>0.00017</stddev>
                  <bias_mean>7.5e-06</bias_mean>
                  <bias_stddev>8e-07</bias_stddev>
                </noise>
              </x>
              <y>
                <noise type='gaussian'>
                  <mean>0</mean>
                  <stddev>0.00017</stddev>
                  <bias_mean>7.5e-06</bias_mean>
                  <bias_stddev>8e-07</bias_stddev>
                </noise>
              </y>
              <z>
                <noise type='gaussian'>
                  <mean>0</mean>
                  <stddev>0.00017</stddev>
                  <bias_mean>7.5e-06</bias_mean>
                  <bias_stddev>8e-07</bias_stddev>
                </noise>
              </z>
            </angular_velocity>
            <linear_acceleration>
              <x>
                <noise type='gaussian'>
                  <mean>0</mean>
                  <stddev>0.00017</stddev>
                  <bias_mean>0.1</bias_mean>
                  <bias_stddev>0.001</bias_stddev>
                </noise>
              </x>
              <y>
                <noise type='gaussian'>
                  <mean>0</mean>
                  <stddev>0.00017</stddev>
                  <bias_mean>0.1</bias_mean>
                  <bias_stddev>0.001</bias_stddev>
                </noise>
              </y>
              <z>
                <noise type='gaussian'>
                  <mean>0</mean>
                  <stddev>0.00017</stddev>
                  <bias_mean>0.1</bias_mean>
                  <bias_stddev>0.001</bias_stddev>
                </noise>
              </z>
            </linear_acceleration>
          </imu>
          <plugin name='imu_plugin' filename='libgazebo_ros_imu_sensor.so'>
            <initial_orientation_as_reference>0</initial_orientation_as_reference>
            <ros>
              <namespace>imu_data</namespace>
              <remapping>~/out:=data</remapping>
              <frame_name>imu_frame</frame_name>
            </ros>
          </plugin>
          <pose>0 0 0.25 0 -0 0</pose>
        </sensor>
        <self_collide>0</self_collide>
        <enable_wind>0</enable_wind>
        <kinematic>0</kinematic>
      </link>
      <joint name='bl_caster_rotation_joint' type='revolute'>
        <pose relative_to='base_footprint'>-0.270154 0.203 0.1565 0 -0 0</pose>
        <parent>base_footprint</parent>
        <child>bl_caster_rotation_link</child>
        <axis>
          <xyz>0 0 1</xyz>
          <limit>
            <lower>-1e+16</lower>
            <upper>1e+16</upper>
          </limit>
          <dynamics>
            <damping>0</damping>
            <friction>0.5</friction>
            <spring_reference>0</spring_reference>
            <spring_stiffness>0</spring_stiffness>
          </dynamics>
        </axis>
      </joint>
      <link name='bl_caster_rotation_link'>
        <pose relative_to='bl_caster_rotation_joint'>0 0 0 0 -0 0</pose>
        <inertial>
          <pose>0 0 -0.0425 0.418879 0 1.5708</pose>
          <mass>0.309754</mass>
          <inertia>
            <ixx>0.000584452</ixx>
            <ixy>0</ixy>
            <ixz>0</ixz>
            <iyy>0.000528726</iyy>
            <iyz>0</iyz>
            <izz>0.000179236</izz>
          </inertia>
        </inertial>
        <collision name='bl_caster_rotation_link_collision'>
          <pose>0 0 0 0 -0 0</pose>
          <geometry>
            <mesh>
              <scale>1 1 1</scale>
              <uri>model://mir_description/meshes/collision/caster_wheel_base.stl</uri>
            </mesh>
          </geometry>
          <surface>
            <contact>
              <ode/>
            </contact>
            <friction>
              <ode/>
              <torsional>
                <ode/>
              </torsional>
            </friction>
            <bounce/>
          </surface>
          <max_contacts>10</max_contacts>
        </collision>
        <visual name='bl_caster_rotation_link_visual'>
          <pose>0 0 0 0 -0 0</pose>
          <geometry>
            <mesh>
              <scale>1 1 1</scale>
              <uri>model://mir_description/meshes/visual/caster_wheel_base.stl</uri>
            </mesh>
          </geometry>
          <material>
            <script>
              <name>Gazebo/Grey</name>
              <uri>file://media/materials/scripts/gazebo.material</uri>
            </script>
          </material>
        </visual>
        <self_collide>0</self_collide>
        <enable_wind>0</enable_wind>
        <kinematic>0</kinematic>
      </link>
      <joint name='bl_caster_wheel_joint' type='revolute'>
        <pose relative_to='bl_caster_rotation_link'>-0.0382 0 -0.094 0 -0 0</pose>
        <parent>bl_caster_rotation_link</parent>
        <child>bl_caster_wheel_link</child>
        <axis>
          <xyz>0 1 0</xyz>
          <limit>
            <lower>-1e+16</lower>
            <upper>1e+16</upper>
          </limit>
          <dynamics>
            <spring_reference>0</spring_reference>
            <spring_stiffness>0</spring_stiffness>
          </dynamics>
        </axis>
      </joint>
      <link name='bl_caster_wheel_link'>
        <pose relative_to='bl_caster_wheel_joint'>0 0 0 0 -0 0</pose>
        <inertial>
          <pose>0 0 0 1.5708 -0 0</pose>
          <mass>1</mass>
          <inertia>
            <ixx>0.0010619</ixx>
            <ixy>0</ixy>
            <ixz>0</ixz>
            <iyy>0.0010619</iyy>
            <iyz>0</iyz>
            <izz>0.00195312</izz>
          </inertia>
        </inertial>
        <collision name='bl_caster_wheel_link_collision'>
          <pose>0 0 0 1.5708 -0 0</pose>
          <geometry>
            <cylinder>
              <length>0.032</length>
              <radius>0.0625</radius>
            </cylinder>
          </geometry>
          <surface>
            <friction>
              <ode>
                <mu>1</mu>
                <mu2>1</mu2>
                <fdir1>0 0 1</fdir1>
                <slip1>0</slip1>
                <slip2>0.5</slip2>
              </ode>
              <torsional>
                <ode/>
              </torsional>
            </friction>
            <contact>
              <ode>
                <kp>1e+08</kp>
                <min_depth>0</min_depth>
              </ode>
            </contact>
            <bounce/>
          </surface>
          <max_contacts>10</max_contacts>
        </collision>
        <visual name='bl_caster_wheel_link_visual'>
          <pose>0 0 0 0 -0 0</pose>
          <geometry>
            <mesh>
              <scale>1 1 1</scale>
              <uri>model://mir_description/meshes/visual/wheel.stl</uri>
            </mesh>
          </geometry>
          <material>
            <script>
              <name>Gazebo/DarkGrey</name>
              <uri>file://media/materials/scripts/gazebo.material</uri>
            </script>
          </material>
        </visual>
        <self_collide>0</self_collide>
        <enable_wind>0</enable_wind>
        <kinematic>0</kinematic>
      </link>
      <joint name='br_caster_rotation_joint' type='revolute'>
        <pose relative_to='base_footprint'>-0.270154 -0.203 0.1565 0 -0 0</pose>
        <parent>base_footprint</parent>
        <child>br_caster_rotation_link</child>
        <axis>
          <xyz>0 0 1</xyz>
          <limit>
            <lower>-1e+16</lower>
            <upper>1e+16</upper>
          </limit>
          <dynamics>
            <damping>0</damping>
            <friction>0.5</friction>
            <spring_reference>0</spring_reference>
            <spring_stiffness>0</spring_stiffness>
          </dynamics>
        </axis>
      </joint>
      <link name='br_caster_rotation_link'>
        <pose relative_to='br_caster_rotation_joint'>0 0 0 0 -0 0</pose>
        <inertial>
          <pose>0 0 -0.0425 0.418879 0 1.5708</pose>
          <mass>0.309754</mass>
          <inertia>
            <ixx>0.000584452</ixx>
            <ixy>0</ixy>
            <ixz>0</ixz>
            <iyy>0.000528726</iyy>
            <iyz>0</iyz>
            <izz>0.000179236</izz>
          </inertia>
        </inertial>
        <collision name='br_caster_rotation_link_collision'>
          <pose>0 0 0 0 -0 0</pose>
          <geometry>
            <mesh>
              <scale>1 1 1</scale>
              <uri>model://mir_description/meshes/collision/caster_wheel_base.stl</uri>
            </mesh>
          </geometry>
          <surface>
            <contact>
              <ode/>
            </contact>
            <friction>
              <ode/>
              <torsional>
                <ode/>
              </torsional>
            </friction>
            <bounce/>
          </surface>
          <max_contacts>10</max_contacts>
        </collision>
        <visual name='br_caster_rotation_link_visual'>
          <pose>0 0 0 0 -0 0</pose>
          <geometry>
            <mesh>
              <scale>1 1 1</scale>
              <uri>model://mir_description/meshes/visual/caster_wheel_base.stl</uri>
            </mesh>
          </geometry>
          <material>
            <script>
              <name>Gazebo/Grey</name>
              <uri>file://media/materials/scripts/gazebo.material</uri>
            </script>
          </material>
        </visual>
        <self_collide>0</self_collide>
        <enable_wind>0</enable_wind>
        <kinematic>0</kinematic>
      </link>
      <joint name='br_caster_wheel_joint' type='revolute'>
        <pose relative_to='br_caster_rotation_link'>-0.0382 0 -0.094 0 -0 0</pose>
        <parent>br_caster_rotation_link</parent>
        <child>br_caster_wheel_link</child>
        <axis>
          <xyz>0 1 0</xyz>
          <limit>
            <lower>-1e+16</lower>
            <upper>1e+16</upper>
          </limit>
          <dynamics>
            <spring_reference>0</spring_reference>
            <spring_stiffness>0</spring_stiffness>
          </dynamics>
        </axis>
      </joint>
      <link name='br_caster_wheel_link'>
        <pose relative_to='br_caster_wheel_joint'>0 0 0 0 -0 0</pose>
        <inertial>
          <pose>0 0 0 1.5708 -0 0</pose>
          <mass>1</mass>
          <inertia>
            <ixx>0.0010619</ixx>
            <ixy>0</ixy>
            <ixz>0</ixz>
            <iyy>0.0010619</iyy>
            <iyz>0</iyz>
            <izz>0.00195312</izz>
          </inertia>
        </inertial>
        <collision name='br_caster_wheel_link_collision'>
          <pose>0 0 0 1.5708 -0 0</pose>
          <geometry>
            <cylinder>
              <length>0.032</length>
              <radius>0.0625</radius>
            </cylinder>
          </geometry>
          <surface>
            <friction>
              <ode>
                <mu>1</mu>
                <mu2>1</mu2>
                <fdir1>0 0 1</fdir1>
                <slip1>0</slip1>
                <slip2>0.5</slip2>
              </ode>
              <torsional>
                <ode/>
              </torsional>
            </friction>
            <contact>
              <ode>
                <kp>1e+08</kp>
                <min_depth>0</min_depth>
              </ode>
            </contact>
            <bounce/>
          </surface>
          <max_contacts>10</max_contacts>
        </collision>
        <visual name='br_caster_wheel_link_visual'>
          <pose>0 0 0 0 -0 0</pose>
          <geometry>
            <mesh>
              <scale>1 1 1</scale>
              <uri>model://mir_description/meshes/visual/wheel.stl</uri>
            </mesh>
          </geometry>
          <material>
            <script>
              <name>Gazebo/DarkGrey</name>
              <uri>file://media/materials/scripts/gazebo.material</uri>
            </script>
          </material>
        </visual>
        <self_collide>0</self_collide>
        <enable_wind>0</enable_wind>
        <kinematic>0</kinematic>
      </link>
      <joint name='fl_caster_rotation_joint' type='revolute'>
        <pose relative_to='base_footprint'>0.341346 0.203 0.1565 0 -0 0</pose>
        <parent>base_footprint</parent>
        <child>fl_caster_rotation_link</child>
        <axis>
          <xyz>0 0 1</xyz>
          <limit>
            <lower>-1e+16</lower>
            <upper>1e+16</upper>
          </limit>
          <dynamics>
            <damping>0</damping>
            <friction>0.5</friction>
            <spring_reference>0</spring_reference>
            <spring_stiffness>0</spring_stiffness>
          </dynamics>
        </axis>
      </joint>
      <link name='fl_caster_rotation_link'>
        <pose relative_to='fl_caster_rotation_joint'>0 0 0 0 -0 0</pose>
        <inertial>
          <pose>0 0 -0.0425 0.418879 0 1.5708</pose>
          <mass>0.309754</mass>
          <inertia>
            <ixx>0.000584452</ixx>
            <ixy>0</ixy>
            <ixz>0</ixz>
            <iyy>0.000528726</iyy>
            <iyz>0</iyz>
            <izz>0.000179236</izz>
          </inertia>
        </inertial>
        <collision name='fl_caster_rotation_link_collision'>
          <pose>0 0 0 0 -0 0</pose>
          <geometry>
            <mesh>
              <scale>1 1 1</scale>
              <uri>model://mir_description/meshes/collision/caster_wheel_base.stl</uri>
            </mesh>
          </geometry>
          <surface>
            <contact>
              <ode/>
            </contact>
            <friction>
              <ode/>
              <torsional>
                <ode/>
              </torsional>
            </friction>
            <bounce/>
          </surface>
          <max_contacts>10</max_contacts>
        </collision>
        <visual name='fl_caster_rotation_link_visual'>
          <pose>0 0 0 0 -0 0</pose>
          <geometry>
            <mesh>
              <scale>1 1 1</scale>
              <uri>model://mir_description/meshes/visual/caster_wheel_base.stl</uri>
            </mesh>
          </geometry>
          <material>
            <script>
              <name>Gazebo/Grey</name>
              <uri>file://media/materials/scripts/gazebo.material</uri>
            </script>
          </material>
        </visual>
        <self_collide>0</self_collide>
        <enable_wind>0</enable_wind>
        <kinematic>0</kinematic>
      </link>
      <joint name='fl_caster_wheel_joint' type='revolute'>
        <pose relative_to='fl_caster_rotation_link'>-0.0382 0 -0.094 0 -0 0</pose>
        <parent>fl_caster_rotation_link</parent>
        <child>fl_caster_wheel_link</child>
        <axis>
          <xyz>0 1 0</xyz>
          <limit>
            <lower>-1e+16</lower>
            <upper>1e+16</upper>
          </limit>
          <dynamics>
            <spring_reference>0</spring_reference>
            <spring_stiffness>0</spring_stiffness>
          </dynamics>
        </axis>
      </joint>
      <link name='fl_caster_wheel_link'>
        <pose relative_to='fl_caster_wheel_joint'>0 0 0 0 -0 0</pose>
        <inertial>
          <pose>0 0 0 1.5708 -0 0</pose>
          <mass>1</mass>
          <inertia>
            <ixx>0.0010619</ixx>
            <ixy>0</ixy>
            <ixz>0</ixz>
            <iyy>0.0010619</iyy>
            <iyz>0</iyz>
            <izz>0.00195312</izz>
          </inertia>
        </inertial>
        <collision name='fl_caster_wheel_link_collision'>
          <pose>0 0 0 1.5708 -0 0</pose>
          <geometry>
            <cylinder>
              <length>0.032</length>
              <radius>0.0625</radius>
            </cylinder>
          </geometry>
          <surface>
            <friction>
              <ode>
                <mu>1</mu>
                <mu2>1</mu2>
                <fdir1>0 0 1</fdir1>
                <slip1>0</slip1>
                <slip2>0.5</slip2>
              </ode>
              <torsional>
                <ode/>
              </torsional>
            </friction>
            <contact>
              <ode>
                <kp>1e+08</kp>
                <min_depth>0</min_depth>
              </ode>
            </contact>
            <bounce/>
          </surface>
          <max_contacts>10</max_contacts>
        </collision>
        <visual name='fl_caster_wheel_link_visual'>
          <pose>0 0 0 0 -0 0</pose>
          <geometry>
            <mesh>
              <scale>1 1 1</scale>
              <uri>model://mir_description/meshes/visual/wheel.stl</uri>
            </mesh>
          </geometry>
          <material>
            <script>
              <name>Gazebo/DarkGrey</name>
              <uri>file://media/materials/scripts/gazebo.material</uri>
            </script>
          </material>
        </visual>
        <self_collide>0</self_collide>
        <enable_wind>0</enable_wind>
        <kinematic>0</kinematic>
      </link>
      <joint name='fr_caster_rotation_joint' type='revolute'>
        <pose relative_to='base_footprint'>0.341346 -0.203 0.1565 0 -0 0</pose>
        <parent>base_footprint</parent>
        <child>fr_caster_rotation_link</child>
        <axis>
          <xyz>0 0 1</xyz>
          <limit>
            <lower>-1e+16</lower>
            <upper>1e+16</upper>
          </limit>
          <dynamics>
            <damping>0</damping>
            <friction>0.5</friction>
            <spring_reference>0</spring_reference>
            <spring_stiffness>0</spring_stiffness>
          </dynamics>
        </axis>
      </joint>
      <link name='fr_caster_rotation_link'>
        <pose relative_to='fr_caster_rotation_joint'>0 0 0 0 -0 0</pose>
        <inertial>
          <pose>0 0 -0.0425 0.418879 0 1.5708</pose>
          <mass>0.309754</mass>
          <inertia>
            <ixx>0.000584452</ixx>
            <ixy>0</ixy>
            <ixz>0</ixz>
            <iyy>0.000528726</iyy>
            <iyz>0</iyz>
            <izz>0.000179236</izz>
          </inertia>
        </inertial>
        <collision name='fr_caster_rotation_link_collision'>
          <pose>0 0 0 0 -0 0</pose>
          <geometry>
            <mesh>
              <scale>1 1 1</scale>
              <uri>model://mir_description/meshes/collision/caster_wheel_base.stl</uri>
            </mesh>
          </geometry>
          <surface>
            <contact>
              <ode/>
            </contact>
            <friction>
              <ode/>
              <torsional>
                <ode/>
              </torsional>
            </friction>
            <bounce/>
          </surface>
          <max_contacts>10</max_contacts>
        </collision>
        <visual name='fr_caster_rotation_link_visual'>
          <pose>0 0 0 0 -0 0</pose>
          <geometry>
            <mesh>
              <scale>1 1 1</scale>
              <uri>model://mir_description/meshes/visual/caster_wheel_base.stl</uri>
            </mesh>
          </geometry>
          <material>
            <script>
              <name>Gazebo/Grey</name>
              <uri>file://media/materials/scripts/gazebo.material</uri>
            </script>
          </material>
        </visual>
        <self_collide>0</self_collide>
        <enable_wind>0</enable_wind>
        <kinematic>0</kinematic>
      </link>
      <joint name='fr_caster_wheel_joint' type='revolute'>
        <pose relative_to='fr_caster_rotation_link'>-0.0382 0 -0.094 0 -0 0</pose>
        <parent>fr_caster_rotation_link</parent>
        <child>fr_caster_wheel_link</child>
        <axis>
          <xyz>0 1 0</xyz>
          <limit>
            <lower>-1e+16</lower>
            <upper>1e+16</upper>
          </limit>
          <dynamics>
            <spring_reference>0</spring_reference>
            <spring_stiffness>0</spring_stiffness>
          </dynamics>
        </axis>
      </joint>
      <link name='fr_caster_wheel_link'>
        <pose relative_to='fr_caster_wheel_joint'>0 0 0 0 -0 0</pose>
        <inertial>
          <pose>0 0 0 1.5708 -0 0</pose>
          <mass>1</mass>
          <inertia>
            <ixx>0.0010619</ixx>
            <ixy>0</ixy>
            <ixz>0</ixz>
            <iyy>0.0010619</iyy>
            <iyz>0</iyz>
            <izz>0.00195312</izz>
          </inertia>
        </inertial>
        <collision name='fr_caster_wheel_link_collision'>
          <pose>0 0 0 1.5708 -0 0</pose>
          <geometry>
            <cylinder>
              <length>0.032</length>
              <radius>0.0625</radius>
            </cylinder>
          </geometry>
          <surface>
            <friction>
              <ode>
                <mu>1</mu>
                <mu2>1</mu2>
                <fdir1>0 0 1</fdir1>
                <slip1>0</slip1>
                <slip2>0.5</slip2>
              </ode>
              <torsional>
                <ode/>
              </torsional>
            </friction>
            <contact>
              <ode>
                <kp>1e+08</kp>
                <min_depth>0</min_depth>
              </ode>
            </contact>
            <bounce/>
          </surface>
          <max_contacts>10</max_contacts>
        </collision>
        <visual name='fr_caster_wheel_link_visual'>
          <pose>0 0 0 0 -0 0</pose>
          <geometry>
            <mesh>
              <scale>1 1 1</scale>
              <uri>model://mir_description/meshes/visual/wheel.stl</uri>
            </mesh>
          </geometry>
          <material>
            <script>
              <name>Gazebo/DarkGrey</name>
              <uri>file://media/materials/scripts/gazebo.material</uri>
            </script>
          </material>
        </visual>
        <self_collide>0</self_collide>
        <enable_wind>0</enable_wind>
        <kinematic>0</kinematic>
      </link>
      <joint name='left_wheel_joint' type='revolute'>
        <pose relative_to='base_footprint'>0 0.222604 0.0625 0 -0 0</pose>
        <parent>base_footprint</parent>
        <child>left_wheel_link</child>
        <axis>
          <xyz>0 1 0</xyz>
          <limit>
            <effort>100</effort>
            <velocity>20</velocity>
            <lower>-1e+16</lower>
            <upper>1e+16</upper>
          </limit>
          <dynamics>
            <spring_reference>0</spring_reference>
            <spring_stiffness>0</spring_stiffness>
          </dynamics>
        </axis>
      </joint>
      <link name='left_wheel_link'>
        <pose relative_to='left_wheel_joint'>0 0 0 0 -0 0</pose>
        <inertial>
          <pose>0 0 0 1.5708 -0 0</pose>
          <mass>1</mass>
          <inertia>
            <ixx>0.0010619</ixx>
            <ixy>0</ixy>
            <ixz>0</ixz>
            <iyy>0.0010619</iyy>
            <iyz>0</iyz>
            <izz>0.00195312</izz>
          </inertia>
        </inertial>
        <collision name='left_wheel_link_collision'>
          <pose>0 0 0 1.5708 -0 0</pose>
          <geometry>
            <cylinder>
              <length>0.032</length>
              <radius>0.0625</radius>
            </cylinder>
          </geometry>
          <surface>
            <friction>
              <ode>
                <mu>300</mu>
                <mu2>300</mu2>
                <fdir1>0 0 1</fdir1>
              </ode>
              <torsional>
                <coefficient>300</coefficient>
                <use_patch_radius>0</use_patch_radius>
                <surface_radius>0.0625</surface_radius>
                <ode/>
              </torsional>
            </friction>
            <contact>
              <ode>
                <min_depth>0.001</min_depth>
              </ode>
            </contact>
            <bounce/>
          </surface>
          <max_contacts>10</max_contacts>
        </collision>
        <visual name='left_wheel_link_visual'>
          <pose>0 0 0 0 -0 0</pose>
          <geometry>
            <mesh>
              <scale>1 1 1</scale>
              <uri>model://mir_description/meshes/visual/wheel.stl</uri>
            </mesh>
          </geometry>
          <material>
            <script>
              <name>Gazebo/DarkGrey</name>
              <uri>file://media/materials/scripts/gazebo.material</uri>
            </script>
          </material>
        </visual>
        <self_collide>0</self_collide>
        <enable_wind>0</enable_wind>
        <kinematic>0</kinematic>
      </link>
      <joint name='right_wheel_joint' type='revolute'>
        <pose relative_to='base_footprint'>0 -0.222604 0.0625 0 -0 0</pose>
        <parent>base_footprint</parent>
        <child>right_wheel_link</child>
        <axis>
          <xyz>0 1 0</xyz>
          <limit>
            <effort>100</effort>
            <velocity>20</velocity>
            <lower>-1e+16</lower>
            <upper>1e+16</upper>
          </limit>
          <dynamics>
            <spring_reference>0</spring_reference>
            <spring_stiffness>0</spring_stiffness>
          </dynamics>
        </axis>
      </joint>
      <link name='right_wheel_link'>
        <pose relative_to='right_wheel_joint'>0 0 0 0 -0 0</pose>
        <inertial>
          <pose>0 0 0 1.5708 -0 0</pose>
          <mass>1</mass>
          <inertia>
            <ixx>0.0010619</ixx>
            <ixy>0</ixy>
            <ixz>0</ixz>
            <iyy>0.0010619</iyy>
            <iyz>0</iyz>
            <izz>0.00195312</izz>
          </inertia>
        </inertial>
        <collision name='right_wheel_link_collision'>
          <pose>0 0 0 1.5708 -0 0</pose>
          <geometry>
            <cylinder>
              <length>0.032</length>
              <radius>0.0625</radius>
            </cylinder>
          </geometry>
          <surface>
            <friction>
              <ode>
                <mu>300</mu>
                <mu2>300</mu2>
                <fdir1>0 0 1</fdir1>
              </ode>
              <torsional>
                <coefficient>300</coefficient>
                <use_patch_radius>0</use_patch_radius>
                <surface_radius>0.0625</surface_radius>
                <ode/>
              </torsional>
            </friction>
            <contact>
              <ode>
                <min_depth>0.001</min_depth>
              </ode>
            </contact>
            <bounce/>
          </surface>
          <max_contacts>10</max_contacts>
        </collision>
        <visual name='right_wheel_link_visual'>
          <pose>0 0 0 0 -0 0</pose>
          <geometry>
            <mesh>
              <scale>1 1 1</scale>
              <uri>model://mir_description/meshes/visual/wheel.stl</uri>
            </mesh>
          </geometry>
          <material>
            <script>
              <name>Gazebo/DarkGrey</name>
              <uri>file://media/materials/scripts/gazebo.material</uri>
            </script>
          </material>
        </visual>
        <self_collide>0</self_collide>
        <enable_wind>0</enable_wind>
        <kinematic>0</kinematic>
      </link>
      <plugin name='fl_caster_rotation_joint_states' filename='libgazebo_ros_joint_state_publisher.so'>
        <ros>
          <namespace/>
        </ros>
        <update_rate>200.0</update_rate>
        <joint_name>fl_caster_rotation_joint</joint_name>
      </plugin>
      <plugin name='fl_caster_wheel_joint_states' filename='libgazebo_ros_joint_state_publisher.so'>
        <ros>
          <namespace/>
        </ros>
        <update_rate>200.0</update_rate>
        <joint_name>fl_caster_wheel_joint</joint_name>
      </plugin>
      <plugin name='fr_caster_rotation_joint_states' filename='libgazebo_ros_joint_state_publisher.so'>
        <ros>
          <namespace/>
        </ros>
        <update_rate>200.0</update_rate>
        <joint_name>fr_caster_rotation_joint</joint_name>
      </plugin>
      <plugin name='fr_caster_wheel_joint_states' filename='libgazebo_ros_joint_state_publisher.so'>
        <ros>
          <namespace/>
        </ros>
        <update_rate>200.0</update_rate>
        <joint_name>fr_caster_wheel_joint</joint_name>
      </plugin>
      <plugin name='bl_caster_rotation_joint_states' filename='libgazebo_ros_joint_state_publisher.so'>
        <ros>
          <namespace/>
        </ros>
        <update_rate>200.0</update_rate>
        <joint_name>bl_caster_rotation_joint</joint_name>
      </plugin>
      <plugin name='bl_caster_wheel_joint_states' filename='libgazebo_ros_joint_state_publisher.so'>
        <ros>
          <namespace/>
        </ros>
        <update_rate>200.0</update_rate>
        <joint_name>bl_caster_wheel_joint</joint_name>
      </plugin>
      <plugin name='br_caster_rotation_joint_states' filename='libgazebo_ros_joint_state_publisher.so'>
        <ros>
          <namespace/>
        </ros>
        <update_rate>200.0</update_rate>
        <joint_name>br_caster_rotation_joint</joint_name>
      </plugin>
      <plugin name='br_caster_wheel_joint_states' filename='libgazebo_ros_joint_state_publisher.so'>
        <ros>
          <namespace/>
        </ros>
        <update_rate>200.0</update_rate>
        <joint_name>br_caster_wheel_joint</joint_name>
      </plugin>
      <plugin name='p3d_base_controller' filename='libgazebo_ros_p3d.so'>
        <ros>
          <remapping>odom:=base_pose_ground_truth</remapping>
        </ros>
        <always_on>1</always_on>
        <update_rate>50.0</update_rate>
        <body_name>base_footprint</body_name>
        <gaussian_noise>0.01</gaussian_noise>
        <frame_name>map</frame_name>
        <xyz_offset>0 0 0</xyz_offset>
        <rpy_offset>0 0 0</rpy_offset>
      </plugin>
      <static>0</static>
      <plugin name='joint_states' filename='libgazebo_ros_joint_state_publisher.so'>
        <ros>
          <namespace/>
        </ros>
        <update_rate>1000.0</update_rate>
        <joint_name>right_wheel_joint</joint_name>
        <joint_name>left_wheel_joint</joint_name>
      </plugin>
      <plugin name='diff_drive_controller' filename='libgazebo_ros_diff_drive.so'>
        <ros>
          <remapping>cmd_vel:=cmd_vel</remapping>
          <remapping>odom:=odom</remapping>
        </ros>
        <legacy_mode>0</legacy_mode>
        <always_on>1</always_on>
        <update_rate>1000.0</update_rate>
        <left_joint>left_wheel_joint</left_joint>
        <right_joint>right_wheel_joint</right_joint>
        <wheel_separation>0.445208</wheel_separation>
        <wheel_diameter>0.125</wheel_diameter>
        <odometry_frame>odom</odometry_frame>
        <robot_base_frame>base_footprint</robot_base_frame>
        <publish_odom>1</publish_odom>
        <publish_wheel_tf>0</publish_wheel_tf>
        <publish_odom_tf>1</publish_odom_tf>
        <max_wheel_torque>10</max_wheel_torque>
        <max_wheel_acceleration>2.8</max_wheel_acceleration>
      </plugin>
      <pose>0 0 0 0 -0 0</pose>
    </model>
    <model name='aruco_marker_0'>
      <static>1</static>
      <link name='link'>
        <visual name='visual'>
          <geometry>
            <box>
              <size>0.15 0.15 0.01</size>
            </box>
          </geometry>
          <material>
            <script>
              <uri>model://aruco_marker_0/materials/scripts</uri>
              <name>AruCo/Marker0</name>
            </script>
          </material>
        </visual>
        <self_collide>0</self_collide>
        <enable_wind>0</enable_wind>
        <kinematic>0</kinematic>
      </link>
      <pose>1.84354 -9.70764 0 0 -0 0</pose>
    </model>
    <state world_name='default'>
      <sim_time>2820 940000000</sim_time>
      <real_time>83 109065441</real_time>
      <wall_time>1747285288 15867059</wall_time>
      <iterations>82412</iterations>
      <model name='aruco_marker_0'>
        <pose>1.82 -10.312 0.3124 1.57079 -1.57079 3.14159</pose>
        <scale>1 1 1</scale>
        <link name='link'>
          <pose>1.82 -10.312 0.3124 1.57079 -1.57079 3.14159</pose>
          <velocity>0 0 0 0 -0 0</velocity>
          <acceleration>0 0 0 0 -0 0</acceleration>
          <wrench>0 0 0 0 -0 0</wrench>
        </link>
      </model>
      <model name='aruco_marker_1'>
        <pose>6.83309 -9.51828 0.3124 3.14159 -1.57079 3.14159</pose>
        <scale>1 1 1</scale>
        <link name='link'>
          <pose>6.83309 -9.51828 0.3124 3.14159 -1.57079 3.14159</pose>
          <velocity>0 0 0 0 -0 0</velocity>
          <acceleration>0 0 0 0 -0 0</acceleration>
          <wrench>0 0 0 0 -0 0</wrench>
        </link>
      </model>
      <model name='aruco_marker_2'>
        <pose>6.83405 -6.37807 0.3124 3.14159 -1.57079 3.14159</pose>
        <scale>1 1 1</scale>
        <link name='link'>
          <pose>6.83405 -6.37807 0.3124 3.14159 -1.57079 3.14159</pose>
          <velocity>0 0 0 0 -0 0</velocity>
          <acceleration>0 0 0 0 -0 0</acceleration>
          <wrench>0 0 0 0 -0 0</wrench>
        </link>
      </model>
      <model name='aruco_marker_3'>
        <pose>6.83371 -1.22608 0.312442 -3.00391 -1.57079 3.00392</pose>
        <scale>1 1 1</scale>
        <link name='link'>
          <pose>6.83371 -1.22608 0.312442 -3.00391 -1.57079 3.00392</pose>
          <velocity>0 0 0 0 -0 0</velocity>
          <acceleration>0 0 0 0 -0 0</acceleration>
          <wrench>0 0 0 0 -0 0</wrench>
        </link>
      </model>
      <model name='aruco_marker_4'>
        <pose>6.83452 2.20087 0.312473 -3.00391 -1.57079 3.00392</pose>
        <scale>1 1 1</scale>
        <link name='link'>
          <pose>6.83452 2.20087 0.312473 -3.00391 -1.57079 3.00392</pose>
          <velocity>0 0 0 0 -0 0</velocity>
          <acceleration>0 0 0 0 -0 0</acceleration>
          <wrench>0 0 0 0 -0 0</wrench>
        </link>
      </model>
      <model name='aruco_marker_5'>
        <pose>6.83424 6.35949 0.312487 -3.14159 -1.57079 -3.14159</pose>
        <scale>1 1 1</scale>
        <link name='link'>
          <pose>6.83424 6.35949 0.312487 -3.14159 -1.57079 -3.14159</pose>
          <velocity>0 0 0 0 -0 0</velocity>
          <acceleration>0 0 0 0 -0 0</acceleration>
          <wrench>0 0 0 0 -0 0</wrench>
        </link>
      </model>
      <model name='aruco_marker_6'>
        <pose>1.77748 10.3205 0.400646 -1.57079 -1.57079 3.14159</pose>
        <scale>1 1 1</scale>
        <link name='link'>
          <pose>1.77748 10.3205 0.400646 -1.57079 -1.57079 3.14159</pose>
          <velocity>0 0 0 0 -0 0</velocity>
          <acceleration>0 0 0 0 -0 0</acceleration>
          <wrench>0 0 0 0 -0 0</wrench>
        </link>
      </model>
      <model name='aruco_marker_7'>
        <pose>-3.77672 10.3199 0.39689 -1.57079 -1.57079 3.14159</pose>
        <scale>1 1 1</scale>
        <link name='link'>
          <pose>-3.77672 10.3199 0.39689 -1.57079 -1.57079 3.14159</pose>
          <velocity>0 0 0 0 -0 0</velocity>
          <acceleration>0 0 0 0 -0 0</acceleration>
          <wrench>0 0 0 0 -0 0</wrench>
        </link>
      </model>
      <model name='aruco_marker_8'>
        <pose>-6.86915 9.29036 0.303906 -3e-06 -1.57079 3.14159</pose>
        <scale>1 1 1</scale>
        <link name='link'>
          <pose>-6.86915 9.29036 0.303906 -3e-06 -1.57079 3.14159</pose>
          <velocity>0 0 0 0 -0 0</velocity>
          <acceleration>0 0 0 0 -0 0</acceleration>
          <wrench>0 0 0 0 -0 0</wrench>
        </link>
      </model>
      <model name='aws_robomaker_warehouse_Bucket_01_020'>
        <pose>0.433449 9.63171 0 0 0 -1.56316</pose>
        <scale>1 1 1</scale>
        <link name='aws_robomaker_warehouse_Bucket_01::body'>
          <pose>0.433449 9.63171 0 0 0 -1.56316</pose>
          <velocity>0 0 0 0 -0 0</velocity>
          <acceleration>0 0 0 0 -0 0</acceleration>
          <wrench>0 0 0 0 -0 0</wrench>
        </link>
      </model>
      <model name='aws_robomaker_warehouse_Bucket_01_020_clone'>
        <pose>-1.87113 3.23127 0 0 0 -1.56316</pose>
        <scale>1 1 1</scale>
        <link name='aws_robomaker_warehouse_Bucket_01::body'>
          <pose>-1.87113 3.23127 0 0 0 -1.56316</pose>
          <velocity>0 0 0 0 -0 0</velocity>
          <acceleration>0 0 0 0 -0 0</acceleration>
          <wrench>0 0 0 0 -0 0</wrench>
        </link>
      </model>
      <model name='aws_robomaker_warehouse_Bucket_01_021'>
        <pose>-1.8321 -6.3752 0 0 0 -1.56316</pose>
        <scale>1 1 1</scale>
        <link name='aws_robomaker_warehouse_Bucket_01::body'>
          <pose>-1.8321 -6.3752 0 0 0 -1.56316</pose>
          <velocity>0 0 0 0 -0 0</velocity>
          <acceleration>0 0 0 0 -0 0</acceleration>
          <wrench>0 0 0 0 -0 0</wrench>
        </link>
      </model>
      <model name='aws_robomaker_warehouse_Bucket_01_021_clone'>
        <pose>4.94933 -8.16306 0 0 0 -1.56316</pose>
        <scale>1 1 1</scale>
        <link name='aws_robomaker_warehouse_Bucket_01::body'>
          <pose>4.94933 -8.16306 0 0 0 -1.56316</pose>
          <velocity>0 0 0 0 -0 0</velocity>
          <acceleration>0 0 0 0 -0 0</acceleration>
          <wrench>0 0 0 0 -0 0</wrench>
        </link>
      </model>
      <model name='aws_robomaker_warehouse_ClutteringA_01_016'>
        <pose>5.70814 8.61684 -0.017477 0 -0 0</pose>
        <scale>1 1 1</scale>
        <link name='aws_robomaker_warehouse_ClutteringA_01::link'>
          <pose>5.70814 8.61684 -0.017477 0 -0 0</pose>
          <velocity>0 0 0 0 -0 0</velocity>
          <acceleration>0 0 0 0 -0 0</acceleration>
          <wrench>0 0 0 0 -0 0</wrench>
        </link>
      </model>
      <model name='aws_robomaker_warehouse_ClutteringA_01_017'>
        <pose>3.40864 8.61684 -0.017477 0 -0 0</pose>
        <scale>1 1 1</scale>
        <link name='aws_robomaker_warehouse_ClutteringA_01::link'>
          <pose>3.40864 8.61684 -0.017477 0 -0 0</pose>
          <velocity>0 0 0 0 -0 0</velocity>
          <acceleration>0 0 0 0 -0 0</acceleration>
          <wrench>0 0 0 0 -0 0</wrench>
        </link>
      </model>
      <model name='aws_robomaker_warehouse_ClutteringC_01_027'>
        <pose>3.32496 3.82245 -0.012064 0 -0 1.56387</pose>
        <scale>1 1 1</scale>
        <link name='aws_robomaker_warehouse_ClutteringC_01::link'>
          <pose>3.32496 3.82245 -0.012064 0 -0 1.56387</pose>
          <velocity>0 0 0 0 -0 0</velocity>
          <acceleration>0 0 0 0 -0 0</acceleration>
          <wrench>0 0 0 0 -0 0</wrench>
        </link>
      </model>
      <model name='aws_robomaker_warehouse_ClutteringC_01_028'>
        <pose>5.54171 3.81648 -0.015663 0 0 -1.58319</pose>
        <scale>1 1 1</scale>
        <link name='aws_robomaker_warehouse_ClutteringC_01::link'>
          <pose>5.54171 3.81648 -0.015663 0 0 -1.58319</pose>
          <velocity>0 0 0 0 -0 0</velocity>
          <acceleration>0 0 0 0 -0 0</acceleration>
          <wrench>0 0 0 0 -0 0</wrench>
        </link>
      </model>
      <model name='aws_robomaker_warehouse_ClutteringC_01_032'>
        <pose>-1.2196 9.407 -0.015663 0 -0 1.56387</pose>
        <scale>1 1 1</scale>
        <link name='aws_robomaker_warehouse_ClutteringC_01::link'>
          <pose>-1.2196 9.407 -0.015663 0 -0 1.56387</pose>
          <velocity>0 0 0 0 -0 0</velocity>
          <acceleration>0 0 0 0 -0 0</acceleration>
          <wrench>0 0 0 0 -0 0</wrench>
        </link>
      </model>
      <model name='aws_robomaker_warehouse_ClutteringD_01_005'>
        <pose>-1.63468 -7.81181 -0.319559 0 -0 0</pose>
        <scale>1 1 1</scale>
        <link name='aws_robomaker_warehouse_ClutteringD_01::link'>
          <pose>-1.63468 -7.81181 -0.319559 0 -0 0</pose>
          <velocity>0 0 0 0 -0 0</velocity>
          <acceleration>0 0 0 0 -0 0</acceleration>
          <wrench>0 0 0 0 -0 0</wrench>
        </link>
      </model>
      <model name='aws_robomaker_warehouse_GroundB_01_001'>
        <pose>0 0 -0.090092 0 -0 0</pose>
        <scale>1 1 1</scale>
        <link name='aws_robomaker_warehouse_GroundB_01::link'>
          <pose>0 0 -0.090092 0 -0 0</pose>
          <velocity>0 0 0 0 -0 0</velocity>
          <acceleration>0 0 0 0 -0 0</acceleration>
          <wrench>0 0 0 0 -0 0</wrench>
        </link>
      </model>
      <model name='aws_robomaker_warehouse_Lamp_01_005'>
        <pose>0 0 -4 0 -0 0</pose>
        <scale>1 1 1</scale>
        <link name='aws_robomaker_warehouse_Lamp_01::link'>
          <pose>0 0 -4 0 -0 0</pose>
          <velocity>0 0 0 0 -0 0</velocity>
          <acceleration>0 0 0 0 -0 0</acceleration>
          <wrench>0 0 0 0 -0 0</wrench>
        </link>
      </model>
      <model name='aws_robomaker_warehouse_ShelfD_01_002'>
        <pose>4.73156 -3.03855 0 0 -0 0</pose>
        <scale>1 1 1</scale>
        <link name='aws_robomaker_warehouse_ShelfD_01::link'>
          <pose>4.73156 -3.03855 0 0 -0 0</pose>
          <velocity>0 0 0 0 -0 0</velocity>
          <acceleration>0 0 0 0 -0 0</acceleration>
          <wrench>0 0 0 0 -0 0</wrench>
        </link>
      </model>
      <model name='aws_robomaker_warehouse_ShelfE_01_001'>
        <pose>4.73156 0.57943 0 0 -0 0</pose>
        <scale>1 1 1</scale>
        <link name='aws_robomaker_warehouse_ShelfE_01::link'>
          <pose>4.73156 0.57943 0 0 -0 0</pose>
          <velocity>0 0 0 0 -0 0</velocity>
          <acceleration>0 0 0 0 -0 0</acceleration>
          <wrench>0 0 0 0 -0 0</wrench>
        </link>
      </model>
      <model name='aws_robomaker_warehouse_ShelfE_01_002'>
        <pose>4.73156 -4.82705 0 0 -0 0</pose>
        <scale>1 1 1</scale>
        <link name='aws_robomaker_warehouse_ShelfE_01::link'>
          <pose>4.73156 -4.82705 0 0 -0 0</pose>
          <velocity>0 0 0 0 -0 0</velocity>
          <acceleration>0 0 0 0 -0 0</acceleration>
          <wrench>0 0 0 0 -0 0</wrench>
        </link>
      </model>
      <model name='aws_robomaker_warehouse_ShelfF_01_001'>
        <pose>-5.79514 -0.956635 0 0 -0 0</pose>
        <scale>1 1 1</scale>
        <link name='aws_robomaker_warehouse_ShelfF_01::link'>
          <pose>-5.79514 -0.956635 0 0 -0 0</pose>
          <velocity>0 0 0 0 -0 0</velocity>
          <acceleration>0 0 0 0 -0 0</acceleration>
          <wrench>0 0 0 0 -0 0</wrench>
        </link>
      </model>
      <model name='aws_robomaker_warehouse_WallB_01_001'>
        <pose>-0.01238 0.004524 0 0 -0 0</pose>
        <scale>1 1 1</scale>
        <link name='aws_robomaker_warehouse_WallB_01::link'>
          <pose>-0.01238 0.004524 0 0 -0 0</pose>
          <velocity>0 0 0 0 -0 0</velocity>
          <acceleration>0 0 0 0 -0 0</acceleration>
          <wrench>0 0 0 0 -0 0</wrench>
        </link>
      </model>
      <model name='cart'>
        <pose>-106.77 -75.7986 -1.67841e+07 -0.785282 1.08088 -0.30677</pose>
        <scale>1 1 1</scale>
        <link name='base_footprint'>
          <pose>-106.77 -75.7986 -1.67841e+07 -0.785282 1.08088 -0.30677</pose>
          <velocity>-0.362267 0.315705 -18139.4 0.097693 -1.41824 -0.836803</velocity>
          <acceleration>-0.986968 -0.208807 -9.20534 -1.83593 -0.872741 -2.22777</acceleration>
          <wrench>-29.7699 -6.29824 -277.661 0 -0 0</wrench>
        </link>
        <link name='rev1_link'>
          <pose>-106.625 -75.5059 -1.67841e+07 -0.690982 -1.12428 -1.85864</pose>
          <velocity>0.575787 0.242606 -18139.1 2.51726 1.21718 -1.69296</velocity>
          <acceleration>-2.47085 -0.326981 -5.64455 -2.12406 -0.458187 -1.55559</acceleration>
          <wrench>-3.4494 -0.456479 -7.88002 0 -0 0</wrench>
        </link>
        <link name='rev2_link'>
          <pose>-107.034 -75.3766 -1.67841e+07 1.01811 0.884367 1.66647</pose>
          <velocity>-0.454798 0.502961 -18139.7 2.17482 -1.40832 1.47714</velocity>
          <acceleration>1.71636 2.57025 -9.36317 -0.157811 0.782119 -0.352658</acceleration>
          <wrench>2.39611 3.58817 -13.0714 0 -0 0</wrench>
        </link>
        <link name='rev3_link'>
          <pose>-106.351 -76.127 -1.67841e+07 -1.21931 0.259339 -0.93607</pose>
          <velocity>-0.28423 -0.009758 -18138.8 -2.41433 -0.830594 -2.60075</velocity>
          <acceleration>-0.694658 -0.594082 -10.2379 -0.223617 0.984784 1.76007</acceleration>
          <wrench>-0.96977 -0.829363 -14.2925 0 -0 0</wrench>
        </link>
        <link name='rev4_link'>
          <pose>-106.759 -75.9977 -1.67841e+07 -1.11755 0.707496 -0.723249</pose>
          <velocity>-1.31517 0.252519 -18139.4 2.30852 -1.36078 1.19121</velocity>
          <acceleration>3.61415 -0.795351 -10.243 0.420879 1.104 0.436159</acceleration>
          <wrench>5.04549 -1.11034 -14.2997 0 -0 0</wrench>
        </link>
        <link name='wheel_link1'>
          <pose>-106.658 -75.5404 -1.67841e+07 -2.14679 -1.04104 -1.98873</pose>
          <velocity>0.533392 0.46683 -18139.3 1.25077 -0.479195 -1.09269</velocity>
          <acceleration>-1.37516 -2.09521 -5.51565 2.07423 0.359678 1.43204</acceleration>
          <wrench>-4.37213 -6.66139 -17.5362 0 -0 0</wrench>
        </link>
        <link name='wheel_link2'>
          <pose>-107.092 -75.4083 -1.67841e+07 -0.945121 -0.399531 0.494597</pose>
          <velocity>-0.083887 -0.186507 -18139.7 -0.17294 1.04899 -2.68237</velocity>
          <acceleration>1.87427 8.43011 -17.535 2.91901 1.14144 2.22986</acceleration>
          <wrench>5.95895 26.8023 -55.75 0 -0 0</wrench>
        </link>
        <link name='wheel_link3'>
          <pose>-106.416 -76.1445 -1.67841e+07 2.73835 -0.164794 2.44818</pose>
          <velocity>-0.437886 0.432576 -18139.2 -0.564797 -0.053062 -3.00452</velocity>
          <acceleration>2.18369 -3.3004 -10.9623 -1.16714 1.31578 -2.06222</acceleration>
          <wrench>6.94272 -10.4931 -34.8531 0 -0 0</wrench>
        </link>
        <link name='wheel_link4'>
          <pose>-106.818 -76.0287 -1.67841e+07 2.98629 0.807159 -1.57992</pose>
          <velocity>-1.55885 0.665374 -18139.5 -0.430648 0.113305 -0.160558</velocity>
          <acceleration>5.73008 -1.42844 -12.4582 2.07658 1.47188 -0.148476</acceleration>
          <wrench>18.2179 -4.5415 -39.609 0 -0 0</wrench>
        </link>
      </model>
      <model name='mir_robot'>
        <pose>0.001526 0.003191 0.03422 1e-06 -6e-06 -0.014077</pose>
        <scale>1 1 1</scale>
        <link name='base_footprint'>
          <pose>0.001526 0.003191 0.03422 1e-06 -6e-06 -0.014077</pose>
          <velocity>0.000255 0.001318 0.000316 0.00031 -1e-05 -0.002243</velocity>
          <acceleration>-0.007884 -0.113894 0.106215 -0.658664 -0.060234 -0.015377</acceleration>
          <wrench>-0.55946 -8.08191 7.53701 0 -0 0</wrench>
        </link>
        <link name='bl_caster_rotation_link'>
          <pose>-0.265746 0.209975 0.190722 8e-06 7.8e-05 -1.67383</pose>
          <velocity>0.00055 0.001909 0.000139 -0.004286 0.000877 0.004323</velocity>
          <acceleration>0.003179 -0.084956 0.006697 0.281376 0.049012 0.161007</acceleration>
          <wrench>0.000985 -0.026315 0.002074 0 -0 0</wrench>
        </link>
        <link name='bl_caster_wheel_link'>
          <pose>-0.261816 0.247974 0.096724 3.14159 -0.123597 1.46776</pose>
          <velocity>0.000304 0.001847 2.7e-05 -0.002634 0.00208 0.004211</velocity>
          <acceleration>-0.008594 -0.133504 0.012754 -0.047019 0.166934 0.445462</acceleration>
          <wrench>-0.008594 -0.133504 0.012754 0 -0 0</wrench>
        </link>
        <link name='br_caster_rotation_link'>
          <pose>-0.27146 -0.195985 0.190722 5e-06 7.9e-05 -1.49604</pose>
          <velocity>-0.000225 0.001939 6.5e-05 -0.002981 -0.000519 -0.001698</velocity>
          <acceleration>0.005299 -0.208358 0.080525 0.509339 -1.49377 -0.124919</acceleration>
          <wrench>0.001641 -0.06454 0.024943 0 -0 0</wrench>
        </link>
        <link name='br_caster_wheel_link'>
          <pose>-0.274313 -0.15789 0.096724 6e-06 -0.101211 -1.49604</pose>
          <velocity>-0.00015 0.001894 -8e-06 -0.00264 -0.000326 -0.001673</velocity>
          <acceleration>-0.011264 -0.199337 -0.013375 -0.017503 -0.777493 0.477675</acceleration>
          <wrench>-0.011264 -0.199337 -0.013375 0 -0 0</wrench>
        </link>
        <link name='fl_caster_rotation_link'>
          <pose>0.345695 0.201366 0.190723 1.2e-05 2.9e-05 -2.73164</pose>
          <velocity>0.00073 0.000393 0.000149 -0.000966 0.004984 -0.003872</velocity>
          <acceleration>-0.032933 -0.053935 0.006455 0.912535 0.241089 -1.1103</acceleration>
          <wrench>-0.010201 -0.016706 0.001999 0 -0 0</wrench>
        </link>
        <link name='fl_caster_wheel_link'>
          <pose>0.380732 0.216591 0.096724 3.1e-05 1.13781 -2.73161</pose>
          <velocity>0.000611 0.000245 1.3e-05 -0.000261 0.001353 -0.003857</velocity>
          <acceleration>-0.018444 -0.076573 0.010339 0.975498 0.643807 -0.356017</acceleration>
          <wrench>-0.018444 -0.076573 0.010339 0 -0 0</wrench>
        </link>
        <link name='fr_caster_rotation_link'>
          <pose>0.33998 -0.204594 0.190724 1e-06 2.7e-05 1.44889</pose>
          <velocity>-7.8e-05 0.000492 9e-05 0.003649 0.000103 0.002536</velocity>
          <acceleration>-0.013618 0.030374 0.069282 2.58001 0.27615 -0.317321</acceleration>
          <wrench>-0.004218 0.009408 0.02146 0 -0 0</wrench>
        </link>
        <link name='fr_caster_wheel_link'>
          <pose>0.335335 -0.242511 0.096724 -1e-06 -0.355059 1.4489</pose>
          <velocity>4.8e-05 0.000597 -1.2e-05 0.002052 -0.000649 0.00253</velocity>
          <acceleration>0.036677 -0.071512 -0.019312 0.095793 1.32149 1.34743</acceleration>
          <wrench>0.036677 -0.071512 -0.019312 0 -0 0</wrench>
        </link>
        <link name='left_wheel_link'>
          <pose>0.004658 0.22577 0.096724 -0.000214 0.527303 -0.014197</pose>
          <velocity>0.000615 0.001003 0.000563 -0.015279 0.009233 -0.002502</velocity>
          <acceleration>0.005163 -0.191948 -0.081885 -3.13658 0.641337 1.46324</acceleration>
          <wrench>0.005163 -0.191948 -0.081885 0 -0 0</wrench>
        </link>
        <link name='right_wheel_link'>
          <pose>-0.001608 -0.219392 0.096723 -3.14148 0.408078 3.12758</pose>
          <velocity>-0.000162 0.001051 0.000386 -0.016382 -0.004051 -0.006083</velocity>
          <acceleration>0.147875 -0.197219 0.393593 2.877 1.35898 -2.92168</acceleration>
          <wrench>0.147875 -0.197219 0.393593 0 -0 0</wrench>
        </link>
      </model>
      <light name='Warehouse_CeilingLight_003'>
        <pose>0 0 9 0 -0 0</pose>
      </light>
    </state>
    <model name='aruco_marker_1'>
      <static>1</static>
      <link name='link'>
        <visual name='visual'>
          <geometry>
            <box>
              <size>0.15 0.15 0.01</size>
            </box>
          </geometry>
          <material>
            <script>
              <uri>model://aruco_marker_1/materials/scripts</uri>
              <name>AruCo/Marker1</name>
            </script>
          </material>
        </visual>
        <self_collide>0</self_collide>
        <enable_wind>0</enable_wind>
        <kinematic>0</kinematic>
      </link>
      <pose>6.68568 -9.99923 0 0 -0 0</pose>
    </model>
    <model name='aruco_marker_2'>
      <static>1</static>
      <link name='link'>
        <visual name='visual'>
          <geometry>
            <box>
              <size>0.15 0.15 0.01</size>
            </box>
          </geometry>
          <material>
            <script>
              <uri>model://aruco_marker_2/materials/scripts</uri>
              <name>AruCo/Marker2</name>
            </script>
          </material>
        </visual>
        <self_collide>0</self_collide>
        <enable_wind>0</enable_wind>
        <kinematic>0</kinematic>
      </link>
      <pose>7.83095 2.31895 0 0 -0 0</pose>
    </model>
    <model name='aruco_marker_3'>
      <static>1</static>
      <link name='link'>
        <visual name='visual'>
          <geometry>
            <box>
              <size>0.15 0.15 0.01</size>
            </box>
          </geometry>
          <material>
            <script>
              <uri>model://aruco_marker_3/materials/scripts</uri>
              <name>AruCo/Marker3</name>
            </script>
          </material>
        </visual>
        <self_collide>0</self_collide>
        <enable_wind>0</enable_wind>
        <kinematic>0</kinematic>
      </link>
      <pose>1.58684 10.8851 0 0 -0 0</pose>
    </model>
    <model name='aruco_marker_4'>
      <static>1</static>
      <link name='link'>
        <visual name='visual'>
          <geometry>
            <box>
              <size>0.15 0.15 0.01</size>
            </box>
          </geometry>
          <material>
            <script>
              <uri>model://aruco_marker_4/materials/scripts</uri>
              <name>AruCo/Marker4</name>
            </script>
          </material>
        </visual>
        <self_collide>0</self_collide>
        <enable_wind>0</enable_wind>
        <kinematic>0</kinematic>
      </link>
      <pose>-3.85436 10.7375 0 0 -0 0</pose>
    </model>
    <model name='aruco_marker_5'>
      <static>1</static>
      <link name='link'>
        <visual name='visual'>
          <geometry>
            <box>
              <size>0.15 0.15 0.01</size>
            </box>
          </geometry>
          <material>
            <script>
              <uri>model://aruco_marker_5/materials/scripts</uri>
              <name>AruCo/Marker5</name>
            </script>
          </material>
        </visual>
        <self_collide>0</self_collide>
        <enable_wind>0</enable_wind>
        <kinematic>0</kinematic>
      </link>
      <pose>-6.14092 9.19602 0 0 -0 0</pose>
    </model>
    <model name='aws_robomaker_warehouse_Bucket_01_020_clone'>
      <frame name='aws_robomaker_warehouse_Bucket_01::__model__' attached_to='aws_robomaker_warehouse_Bucket_01::body'>
        <pose relative_to='__model__'>0 0 0 0 -0 0</pose>
      </frame>
      <link name='aws_robomaker_warehouse_Bucket_01::body'>
        <inertial>
          <mass>2</mass>
          <pose>0 0 0 0 -0 0</pose>
          <inertia>
            <ixx>0.57</ixx>
            <ixy>0</ixy>
            <ixz>0</ixz>
            <iyy>0.474</iyy>
            <iyz>0</iyz>
            <izz>0.391</izz>
          </inertia>
        </inertial>
        <pose relative_to='aws_robomaker_warehouse_Bucket_01::__model__'>0 0 0 0 -0 0</pose>
        <self_collide>0</self_collide>
        <kinematic>0</kinematic>
        <gravity>1</gravity>
        <visual name='visual'>
          <geometry>
            <mesh>
              <uri>file://models/aws_robomaker_warehouse_Bucket_01/meshes/aws_robomaker_warehouse_Bucket_01_visual.DAE</uri>
            </mesh>
          </geometry>
          <meta>
            <layer>1</layer>
          </meta>
        </visual>
        <collision name='collision_0'>
          <laser_retro>0</laser_retro>
          <max_contacts>10</max_contacts>
          <pose>0 0 0 0 -0 0</pose>
          <geometry>
            <mesh>
              <uri>file://models/aws_robomaker_warehouse_Bucket_01/meshes/aws_robomaker_warehouse_Bucket_01_collision.DAE</uri>
              <scale>1 1 1</scale>
            </mesh>
          </geometry>
          <surface>
            <friction>
              <ode>
                <mu>0.4</mu>
                <mu2>0.4</mu2>
                <fdir1>0 0 0</fdir1>
                <slip1>0</slip1>
                <slip2>0</slip2>
              </ode>
              <torsional>
                <coefficient>1</coefficient>
                <patch_radius>0</patch_radius>
                <surface_radius>0</surface_radius>
                <use_patch_radius>1</use_patch_radius>
                <ode>
                  <slip>0</slip>
                </ode>
              </torsional>
            </friction>
            <contact>
              <ode/>
            </contact>
            <bounce/>
          </surface>
        </collision>
        <enable_wind>0</enable_wind>
      </link>
      <static>1</static>
      <pose>-1.87113 3.23127 0 0 0 -1.56316</pose>
    </model>
    <model name='aws_robomaker_warehouse_Bucket_01_021_clone'>
      <frame name='aws_robomaker_warehouse_Bucket_01::__model__' attached_to='aws_robomaker_warehouse_Bucket_01::body'>
        <pose relative_to='__model__'>0 0 0 0 -0 0</pose>
      </frame>
      <link name='aws_robomaker_warehouse_Bucket_01::body'>
        <inertial>
          <mass>2</mass>
          <pose>0 0 0 0 -0 0</pose>
          <inertia>
            <ixx>0.57</ixx>
            <ixy>0</ixy>
            <ixz>0</ixz>
            <iyy>0.474</iyy>
            <iyz>0</iyz>
            <izz>0.391</izz>
          </inertia>
        </inertial>
        <pose relative_to='aws_robomaker_warehouse_Bucket_01::__model__'>0 0 0 0 -0 0</pose>
        <self_collide>0</self_collide>
        <kinematic>0</kinematic>
        <gravity>1</gravity>
        <visual name='visual'>
          <geometry>
            <mesh>
              <uri>file://models/aws_robomaker_warehouse_Bucket_01/meshes/aws_robomaker_warehouse_Bucket_01_visual.DAE</uri>
            </mesh>
          </geometry>
          <meta>
            <layer>1</layer>
          </meta>
        </visual>
        <collision name='collision_0'>
          <laser_retro>0</laser_retro>
          <max_contacts>10</max_contacts>
          <pose>0 0 0 0 -0 0</pose>
          <geometry>
            <mesh>
              <uri>file://models/aws_robomaker_warehouse_Bucket_01/meshes/aws_robomaker_warehouse_Bucket_01_collision.DAE</uri>
              <scale>1 1 1</scale>
            </mesh>
          </geometry>
          <surface>
            <friction>
              <ode>
                <mu>0.4</mu>
                <mu2>0.4</mu2>
                <fdir1>0 0 0</fdir1>
                <slip1>0</slip1>
                <slip2>0</slip2>
              </ode>
              <torsional>
                <coefficient>1</coefficient>
                <patch_radius>0</patch_radius>
                <surface_radius>0</surface_radius>
                <use_patch_radius>1</use_patch_radius>
                <ode>
                  <slip>0</slip>
                </ode>
              </torsional>
            </friction>
            <contact>
              <ode/>
            </contact>
            <bounce/>
          </surface>
        </collision>
        <enable_wind>0</enable_wind>
      </link>
      <static>1</static>
      <pose>4.94933 -8.16306 0 0 0 -1.56316</pose>
    </model>
    <model name='cart'>
      <link name='base_footprint'>
        <inertial>
          <pose>-0 0 0.76506 0 -0 0</pose>
          <mass>30.163</mass>
          <inertia>
            <ixx>1.0132</ixx>
            <ixy>-2.3419e-15</ixy>
            <ixz>7.6733e-10</ixz>
            <iyy>1.6281</iyy>
            <iyz>-3.803e-10</iyz>
            <izz>2.1018</izz>
          </inertia>
        </inertial>
        <collision name='base_footprint_fixed_joint_lump__base_link_collision'>
          <pose>0 0 1.371 0 -0 0</pose>
          <geometry>
            <mesh>
              <scale>1 1 1</scale>
              <uri>file:////home/kraiwich/OpenTopic_ws/install/cart_description/share/cart_description/meshes/base_link.STL</uri>
            </mesh>
          </geometry>
          <surface>
            <contact>
              <ode/>
            </contact>
            <friction>
              <ode/>
              <torsional>
                <ode/>
              </torsional>
            </friction>
            <bounce/>
          </surface>
          <max_contacts>10</max_contacts>
        </collision>
        <visual name='base_footprint_fixed_joint_lump__base_link_visual'>
          <pose>0 0 1.371 0 -0 0</pose>
          <geometry>
            <mesh>
              <scale>1 1 1</scale>
              <uri>file:////home/kraiwich/OpenTopic_ws/install/cart_description/share/cart_description/meshes/base_link.STL</uri>
            </mesh>
          </geometry>
          <material>
            <script>
              <name>Gazebo/White</name>
              <uri>file://media/materials/scripts/gazebo.material</uri>
            </script>
          </material>
        </visual>
        <self_collide>0</self_collide>
        <enable_wind>0</enable_wind>
        <kinematic>0</kinematic>
      </link>
      <joint name='rev1_joint' type='revolute'>
        <pose relative_to='base_footprint'>0.455 0.359999 0.0965 0 -0 0</pose>
        <parent>base_footprint</parent>
        <child>rev1_link</child>
        <axis>
          <xyz>0 0 -1</xyz>
          <limit>
            <lower>-1e+16</lower>
            <upper>1e+16</upper>
          </limit>
          <dynamics>
            <spring_reference>0</spring_reference>
            <spring_stiffness>0</spring_stiffness>
          </dynamics>
        </axis>
      </joint>
      <link name='rev1_link'>
        <pose relative_to='rev1_joint'>0 0 0 0 -0 0</pose>
        <inertial>
          <pose>-0.008873 -6.6e-05 -0.024908 0 -0 0</pose>
          <mass>1.39604</mass>
          <inertia>
            <ixx>0.00039872</ixx>
            <ixy>-4.2724e-07</ixy>
            <ixz>-6.7183e-05</ixz>
            <iyy>0.00033801</iyy>
            <iyz>-8.9725e-07</iyz>
            <izz>0.00036573</izz>
          </inertia>
        </inertial>
        <collision name='rev1_link_collision'>
          <pose>0 0 0 0 -0 0</pose>
          <geometry>
            <mesh>
              <scale>1 1 1</scale>
              <uri>file:////home/kraiwich/OpenTopic_ws/install/cart_description/share/cart_description/meshes/rev1_link.STL</uri>
            </mesh>
          </geometry>
          <surface>
            <contact>
              <ode/>
            </contact>
            <friction>
              <ode>
                <mu>1000</mu>
                <mu2>1000</mu2>
              </ode>
              <torsional>
                <ode/>
              </torsional>
            </friction>
            <bounce/>
          </surface>
          <max_contacts>10</max_contacts>
        </collision>
        <visual name='rev1_link_visual'>
          <pose>0 0 0 0 -0 0</pose>
          <geometry>
            <mesh>
              <scale>1 1 1</scale>
              <uri>file:////home/kraiwich/OpenTopic_ws/install/cart_description/share/cart_description/meshes/rev1_link.STL</uri>
            </mesh>
          </geometry>
          <material>
            <script>
              <name>Gazebo/White</name>
              <uri>file://media/materials/scripts/gazebo.material</uri>
            </script>
          </material>
        </visual>
        <self_collide>0</self_collide>
        <enable_wind>0</enable_wind>
        <kinematic>0</kinematic>
      </link>
      <joint name='wheel_joint1' type='revolute'>
        <pose relative_to='rev1_link'>-0.025 0.021001 -0.059 -1.5708 0 0</pose>
        <parent>rev1_link</parent>
        <child>wheel_link1</child>
        <axis>
          <xyz>0 0 -1</xyz>
          <limit>
            <lower>-1e+16</lower>
            <upper>1e+16</upper>
          </limit>
          <dynamics>
            <spring_reference>0</spring_reference>
            <spring_stiffness>0</spring_stiffness>
          </dynamics>
        </axis>
      </joint>
      <link name='wheel_link1'>
        <pose relative_to='wheel_joint1'>0 0 0 0 -0 0</pose>
        <inertial>
          <pose>-0 -0 -0.021 0 -0 0</pose>
          <mass>3.17935</mass>
          <inertia>
            <ixx>8.2728e-05</ixx>
            <ixy>-9.2883e-10</ixy>
            <ixz>-2.5882e-10</ixz>
            <iyy>8.2727e-05</iyy>
            <iyz>-4.0977e-11</iyz>
            <izz>0.00012509</izz>
          </inertia>
        </inertial>
        <collision name='wheel_link1_collision'>
          <pose>0 0 0 0 -0 0</pose>
          <geometry>
            <mesh>
              <scale>1 1 1</scale>
              <uri>file:////home/kraiwich/OpenTopic_ws/install/cart_description/share/cart_description/meshes/wheel_link1.STL</uri>
            </mesh>
          </geometry>
          <surface>
            <contact>
              <ode/>
            </contact>
            <friction>
              <ode>
                <mu>1000</mu>
                <mu2>1000</mu2>
              </ode>
              <torsional>
                <ode/>
              </torsional>
            </friction>
            <bounce/>
          </surface>
          <max_contacts>10</max_contacts>
        </collision>
        <visual name='wheel_link1_visual'>
          <pose>0 0 0 0 -0 0</pose>
          <geometry>
            <mesh>
              <scale>1 1 1</scale>
              <uri>file:////home/kraiwich/OpenTopic_ws/install/cart_description/share/cart_description/meshes/wheel_link1.STL</uri>
            </mesh>
          </geometry>
          <material>
            <script>
              <name>Gazebo/Black</name>
              <uri>file://media/materials/scripts/gazebo.material</uri>
            </script>
          </material>
        </visual>
        <self_collide>0</self_collide>
        <enable_wind>0</enable_wind>
        <kinematic>0</kinematic>
      </link>
      <joint name='rev2_joint' type='revolute'>
        <pose relative_to='base_footprint'>-0.455 0.359999 0.0965 0 -0 0</pose>
        <parent>base_footprint</parent>
        <child>rev2_link</child>
        <axis>
          <xyz>0 0 -1</xyz>
          <limit>
            <lower>-1e+16</lower>
            <upper>1e+16</upper>
          </limit>
          <dynamics>
            <spring_reference>0</spring_reference>
            <spring_stiffness>0</spring_stiffness>
          </dynamics>
        </axis>
      </joint>
      <link name='rev2_link'>
        <pose relative_to='rev2_joint'>0 0 0 0 -0 0</pose>
        <inertial>
          <pose>-0.008873 -6.6e-05 -0.024908 0 -0 0</pose>
          <mass>1.39604</mass>
          <inertia>
            <ixx>0.000398723</ixx>
            <ixy>-4.27245e-07</ixy>
            <ixz>-6.71828e-05</ixz>
            <iyy>0.000338006</iyy>
            <iyz>-8.97252e-07</iyz>
            <izz>0.000365728</izz>
          </inertia>
        </inertial>
        <collision name='rev2_link_collision'>
          <pose>0 0 0 0 -0 0</pose>
          <geometry>
            <mesh>
              <scale>1 1 1</scale>
              <uri>file:////home/kraiwich/OpenTopic_ws/install/cart_description/share/cart_description/meshes/rev2_link.STL</uri>
            </mesh>
          </geometry>
          <surface>
            <contact>
              <ode/>
            </contact>
            <friction>
              <ode>
                <mu>1000</mu>
                <mu2>1000</mu2>
              </ode>
              <torsional>
                <ode/>
              </torsional>
            </friction>
            <bounce/>
          </surface>
          <max_contacts>10</max_contacts>
        </collision>
        <visual name='rev2_link_visual'>
          <pose>0 0 0 0 -0 0</pose>
          <geometry>
            <mesh>
              <scale>1 1 1</scale>
              <uri>file:////home/kraiwich/OpenTopic_ws/install/cart_description/share/cart_description/meshes/rev2_link.STL</uri>
            </mesh>
          </geometry>
          <material>
            <script>
              <name>Gazebo/White</name>
              <uri>file://media/materials/scripts/gazebo.material</uri>
            </script>
          </material>
        </visual>
        <self_collide>0</self_collide>
        <enable_wind>0</enable_wind>
        <kinematic>0</kinematic>
      </link>
      <joint name='wheel_joint2' type='revolute'>
        <pose relative_to='rev2_link'>-0.025001 0.021001 -0.059 -1.5708 0 0</pose>
        <parent>rev2_link</parent>
        <child>wheel_link2</child>
        <axis>
          <xyz>0 0 -1</xyz>
          <limit>
            <lower>-1e+16</lower>
            <upper>1e+16</upper>
          </limit>
          <dynamics>
            <spring_reference>0</spring_reference>
            <spring_stiffness>0</spring_stiffness>
          </dynamics>
        </axis>
      </joint>
      <link name='wheel_link2'>
        <pose relative_to='wheel_joint2'>0 0 0 0 -0 0</pose>
        <inertial>
          <pose>0 0 -0.021 0 -0 0</pose>
          <mass>3.17935</mass>
          <inertia>
            <ixx>8.27284e-05</ixx>
            <ixy>4.23195e-11</ixy>
            <ixz>3.01176e-10</ixz>
            <iyy>8.27261e-05</iyy>
            <iyz>2.65006e-10</iyz>
            <izz>0.00012509</izz>
          </inertia>
        </inertial>
        <collision name='wheel_link2_collision'>
          <pose>0 0 0 0 -0 0</pose>
          <geometry>
            <mesh>
              <scale>1 1 1</scale>
              <uri>file:////home/kraiwich/OpenTopic_ws/install/cart_description/share/cart_description/meshes/wheel_link2.STL</uri>
            </mesh>
          </geometry>
          <surface>
            <contact>
              <ode/>
            </contact>
            <friction>
              <ode>
                <mu>1000</mu>
                <mu2>1000</mu2>
              </ode>
              <torsional>
                <ode/>
              </torsional>
            </friction>
            <bounce/>
          </surface>
          <max_contacts>10</max_contacts>
        </collision>
        <visual name='wheel_link2_visual'>
          <pose>0 0 0 0 -0 0</pose>
          <geometry>
            <mesh>
              <scale>1 1 1</scale>
              <uri>file:////home/kraiwich/OpenTopic_ws/install/cart_description/share/cart_description/meshes/wheel_link2.STL</uri>
            </mesh>
          </geometry>
          <material>
            <script>
              <name>Gazebo/Black</name>
              <uri>file://media/materials/scripts/gazebo.material</uri>
            </script>
          </material>
        </visual>
        <self_collide>0</self_collide>
        <enable_wind>0</enable_wind>
        <kinematic>0</kinematic>
      </link>
      <joint name='rev3_joint' type='revolute'>
        <pose relative_to='base_footprint'>0.455 -0.360001 0.0965 0 -0 0</pose>
        <parent>base_footprint</parent>
        <child>rev3_link</child>
        <axis>
          <xyz>0 0 -1</xyz>
          <limit>
            <lower>-1e+16</lower>
            <upper>1e+16</upper>
          </limit>
          <dynamics>
            <spring_reference>0</spring_reference>
            <spring_stiffness>0</spring_stiffness>
          </dynamics>
        </axis>
      </joint>
      <link name='rev3_link'>
        <pose relative_to='rev3_joint'>0 0 0 0 -0 0</pose>
        <inertial>
          <pose>-0.008873 -6.6e-05 -0.024908 0 -0 0</pose>
          <mass>1.39604</mass>
          <inertia>
            <ixx>0.000398723</ixx>
            <ixy>-4.27245e-07</ixy>
            <ixz>-6.71828e-05</ixz>
            <iyy>0.000338006</iyy>
            <iyz>-8.97252e-07</iyz>
            <izz>0.000365728</izz>
          </inertia>
        </inertial>
        <collision name='rev3_link_collision'>
          <pose>0 0 0 0 -0 0</pose>
          <geometry>
            <mesh>
              <scale>1 1 1</scale>
              <uri>file:////home/kraiwich/OpenTopic_ws/install/cart_description/share/cart_description/meshes/rev3_link.STL</uri>
            </mesh>
          </geometry>
          <surface>
            <contact>
              <ode/>
            </contact>
            <friction>
              <ode>
                <mu>1000</mu>
                <mu2>1000</mu2>
              </ode>
              <torsional>
                <ode/>
              </torsional>
            </friction>
            <bounce/>
          </surface>
          <max_contacts>10</max_contacts>
        </collision>
        <visual name='rev3_link_visual'>
          <pose>0 0 0 0 -0 0</pose>
          <geometry>
            <mesh>
              <scale>1 1 1</scale>
              <uri>file:////home/kraiwich/OpenTopic_ws/install/cart_description/share/cart_description/meshes/rev3_link.STL</uri>
            </mesh>
          </geometry>
          <material>
            <script>
              <name>Gazebo/White</name>
              <uri>file://media/materials/scripts/gazebo.material</uri>
            </script>
          </material>
        </visual>
        <self_collide>0</self_collide>
        <enable_wind>0</enable_wind>
        <kinematic>0</kinematic>
      </link>
      <joint name='wheel_joint3' type='revolute'>
        <pose relative_to='rev3_link'>-0.025007 -0.020999 -0.058998 -1.5708 0 0</pose>
        <parent>rev3_link</parent>
        <child>wheel_link3</child>
        <axis>
          <xyz>0 0 -1</xyz>
          <limit>
            <lower>-1e+16</lower>
            <upper>1e+16</upper>
          </limit>
          <dynamics>
            <spring_reference>0</spring_reference>
            <spring_stiffness>0</spring_stiffness>
          </dynamics>
        </axis>
      </joint>
      <link name='wheel_link3'>
        <pose relative_to='wheel_joint3'>0 0 0 0 -0 0</pose>
        <inertial>
          <pose>7e-06 2e-06 0.021 0 -0 0</pose>
          <mass>3.17935</mass>
          <inertia>
            <ixx>8.2728e-05</ixx>
            <ixy>-9.2883e-10</ixy>
            <ixz>-2.5882e-10</ixz>
            <iyy>8.2727e-05</iyy>
            <iyz>-4.0977e-11</iyz>
            <izz>0.00012509</izz>
          </inertia>
        </inertial>
        <collision name='wheel_link3_collision'>
          <pose>0 0 0 0 -0 0</pose>
          <geometry>
            <mesh>
              <scale>1 1 1</scale>
              <uri>file:////home/kraiwich/OpenTopic_ws/install/cart_description/share/cart_description/meshes/wheel_link3.STL</uri>
            </mesh>
          </geometry>
          <surface>
            <contact>
              <ode/>
            </contact>
            <friction>
              <ode>
                <mu>1000</mu>
                <mu2>1000</mu2>
              </ode>
              <torsional>
                <ode/>
              </torsional>
            </friction>
            <bounce/>
          </surface>
          <max_contacts>10</max_contacts>
        </collision>
        <visual name='wheel_link3_visual'>
          <pose>0 0 0 0 -0 0</pose>
          <geometry>
            <mesh>
              <scale>1 1 1</scale>
              <uri>file:////home/kraiwich/OpenTopic_ws/install/cart_description/share/cart_description/meshes/wheel_link3.STL</uri>
            </mesh>
          </geometry>
          <material>
            <script>
              <name>Gazebo/Black</name>
              <uri>file://media/materials/scripts/gazebo.material</uri>
            </script>
          </material>
        </visual>
        <self_collide>0</self_collide>
        <enable_wind>0</enable_wind>
        <kinematic>0</kinematic>
      </link>
      <joint name='rev4_joint' type='revolute'>
        <pose relative_to='base_footprint'>-0.455 -0.360001 0.0965 0 -0 0</pose>
        <parent>base_footprint</parent>
        <child>rev4_link</child>
        <axis>
          <xyz>0 0 -1</xyz>
          <limit>
            <lower>-1e+16</lower>
            <upper>1e+16</upper>
          </limit>
          <dynamics>
            <spring_reference>0</spring_reference>
            <spring_stiffness>0</spring_stiffness>
          </dynamics>
        </axis>
      </joint>
      <link name='rev4_link'>
        <pose relative_to='rev4_joint'>0 0 0 0 -0 0</pose>
        <inertial>
          <pose>-0.008873 -6.6e-05 -0.024908 0 -0 0</pose>
          <mass>1.39604</mass>
          <inertia>
            <ixx>0.000398723</ixx>
            <ixy>-4.27245e-07</ixy>
            <ixz>-6.71828e-05</ixz>
            <iyy>0.000338006</iyy>
            <iyz>-8.97252e-07</iyz>
            <izz>0.000365728</izz>
          </inertia>
        </inertial>
        <collision name='rev4_link_collision'>
          <pose>0 0 0 0 -0 0</pose>
          <geometry>
            <mesh>
              <scale>1 1 1</scale>
              <uri>file:////home/kraiwich/OpenTopic_ws/install/cart_description/share/cart_description/meshes/rev4_link.STL</uri>
            </mesh>
          </geometry>
          <surface>
            <contact>
              <ode/>
            </contact>
            <friction>
              <ode>
                <mu>1000</mu>
                <mu2>1000</mu2>
              </ode>
              <torsional>
                <ode/>
              </torsional>
            </friction>
            <bounce/>
          </surface>
          <max_contacts>10</max_contacts>
        </collision>
        <visual name='rev4_link_visual'>
          <pose>0 0 0 0 -0 0</pose>
          <geometry>
            <mesh>
              <scale>1 1 1</scale>
              <uri>file:////home/kraiwich/OpenTopic_ws/install/cart_description/share/cart_description/meshes/rev4_link.STL</uri>
            </mesh>
          </geometry>
          <material>
            <script>
              <name>Gazebo/White</name>
              <uri>file://media/materials/scripts/gazebo.material</uri>
            </script>
          </material>
        </visual>
        <self_collide>0</self_collide>
        <enable_wind>0</enable_wind>
        <kinematic>0</kinematic>
      </link>
      <joint name='wheel_joint4' type='revolute'>
        <pose relative_to='rev4_link'>-0.025007 -0.020999 -0.058998 -1.5708 0 0</pose>
        <parent>rev4_link</parent>
        <child>wheel_link4</child>
        <axis>
          <xyz>0 0 -1</xyz>
          <limit>
            <lower>-1e+16</lower>
            <upper>1e+16</upper>
          </limit>
          <dynamics>
            <spring_reference>0</spring_reference>
            <spring_stiffness>0</spring_stiffness>
          </dynamics>
        </axis>
      </joint>
      <link name='wheel_link4'>
        <pose relative_to='wheel_joint4'>0 0 0 0 -0 0</pose>
        <inertial>
          <pose>7e-06 2e-06 0.021 0 -0 0</pose>
          <mass>3.17935</mass>
          <inertia>
            <ixx>8.27278e-05</ixx>
            <ixy>-9.28827e-10</ixy>
            <ixz>-2.58823e-10</ixz>
            <iyy>8.27267e-05</iyy>
            <iyz>-4.09773e-11</iyz>
            <izz>0.00012509</izz>
          </inertia>
        </inertial>
        <collision name='wheel_link4_collision'>
          <pose>0 0 0 0 -0 0</pose>
          <geometry>
            <mesh>
              <scale>1 1 1</scale>
              <uri>file:////home/kraiwich/OpenTopic_ws/install/cart_description/share/cart_description/meshes/wheel_link4.STL</uri>
            </mesh>
          </geometry>
          <surface>
            <contact>
              <ode/>
            </contact>
            <friction>
              <ode>
                <mu>1000</mu>
                <mu2>1000</mu2>
              </ode>
              <torsional>
                <ode/>
              </torsional>
            </friction>
            <bounce/>
          </surface>
          <max_contacts>10</max_contacts>
        </collision>
        <visual name='wheel_link4_visual'>
          <pose>0 0 0 0 -0 0</pose>
          <geometry>
            <mesh>
              <scale>1 1 1</scale>
              <uri>file:////home/kraiwich/OpenTopic_ws/install/cart_description/share/cart_description/meshes/wheel_link4.STL</uri>
            </mesh>
          </geometry>
          <material>
            <script>
              <name>Gazebo/Black</name>
              <uri>file://media/materials/scripts/gazebo.material</uri>
            </script>
          </material>
        </visual>
        <self_collide>0</self_collide>
        <enable_wind>0</enable_wind>
        <kinematic>0</kinematic>
      </link>
      <pose>-2 -2 0 0 -0 0</pose>
    </model>
    <model name='aruco_marker_6'>
      <static>1</static>
      <link name='link'>
        <visual name='visual'>
          <geometry>
            <box>
              <size>0.15 0.15 0.01</size>
            </box>
          </geometry>
          <material>
            <script>
              <uri>model://aruco_marker_6/materials/scripts</uri>
              <name>AruCo/Marker6</name>
            </script>
          </material>
        </visual>
        <self_collide>0</self_collide>
        <enable_wind>0</enable_wind>
        <kinematic>0</kinematic>
      </link>
      <pose>1.88299 9.52681 0 0 -0 0</pose>
    </model>
    <model name='aruco_marker_7'>
      <static>1</static>
      <link name='link'>
        <visual name='visual'>
          <geometry>
            <box>
              <size>0.15 0.15 0.01</size>
            </box>
          </geometry>
          <material>
            <script>
              <uri>model://aruco_marker_7/materials/scripts</uri>
              <name>AruCo/Marker7</name>
            </script>
          </material>
        </visual>
        <self_collide>0</self_collide>
        <enable_wind>0</enable_wind>
        <kinematic>0</kinematic>
      </link>
      <pose>-3.77954 10.6832 0 0 -0 0</pose>
    </model>
    <model name='aruco_marker_8'>
      <static>1</static>
      <link name='link'>
        <visual name='visual'>
          <geometry>
            <box>
              <size>0.15 0.15 0.01</size>
            </box>
          </geometry>
          <material>
            <script>
              <uri>model://aruco_marker_8/materials/scripts</uri>
              <name>AruCo/Marker8</name>
            </script>
          </material>
        </visual>
        <self_collide>0</self_collide>
        <enable_wind>0</enable_wind>
        <kinematic>0</kinematic>
      </link>
      <pose>-7.29572 9.287 0 0 -0 0</pose>
    </model>
  </world>
</sdf>
